Workbook
Name ARMCXDOC: 'MC IMB RJ'!$D$12
Name ARMCXMID: 'MC IMB RJ'!$D$15
Name ARMMA: 'MC IMB RJ'!$D$21
Name ARMMIC: 'MC IMB RJ'!$D$24
Name ARMMID: 'MC IMB RJ'!$D$27
Name ARMTB: 'MC IMB RJ'!$D$18
Name BaseKM: #REF!

Sheet MC IMB RJ
B2: P E T R O L E O B R A S I L E I R O S. A. P E T R O B R A S
B3: M E M Ó R I A D E C Á L C U L O D E M E D I Ç Ã O
B4: Razão Social: | D4: IRON MOUNTAIN DO BRASIL LTDA | I4: CNPJ: | J4: 04.120.966/0001-13 | L4: Item 1 PPU | M4: IAPEFARQ: | N4: 0.93
B5: Contrato SAP: | D5: 4600686987 | I5: Área contrato: | J5: Lote 1 | M5: FDM: | N5: 0.98
B6: Objeto: | D6: Serviços de Guarda e Gerenciamento de Documentos e Informações do Acervo da PETROBRAS | I6: Instr. contratual: | J6: 5900.0133210.25.2 | L6: Item 2 PPU | M6: IAPEFARQ: | N6: 1
I7: Período: | J7: 26/07/2026 à 25/08/2026 | M7: FDM: | N7: 1
C10: Item | D10: Descrição da atividade | I10: Unidade | J10: QExec | K10: QFinal | L10: Valor unitário | M10: Valor total a pagar | N10: Observações
C11: 1 | D11: Guarda de Documentos e Informações
D12: ARM-CX-DOC | E12: Armazenamento de caixas para documentos
C13: 1.1 | D13: QUAm-1 | E13: QBm | F13: QDm | G13: QNm | H13: QUAm | I13: UA | J13: =SUMIF(Consolidado!S:S,D12,Consolidado!O:O) -> 233913.67 | K13: =J13*N5 -> 229235.4 | L13: =IFERROR(VLOOKUP(ARMCXDOC,TabelaIRON[[Linha de Serviço PPU]:[PREÇO UNITÁRIO ]],3,FALSE),"N/A") -> 0.6 | M13: =J13*L13 -> 140348.2
D14: =SUMIF(ConsolidadoRJ[Contrato], D12, ConsolidadoRJ[QUAm-1]) -> 206009 | E14: =SUMIF(ConsolidadoRJ[Contrato], D12, ConsolidadoRJ[QBm]) -> 128 | F14: =SUMIF(ConsolidadoRJ[Contrato], D12, ConsolidadoRJ[QDm]) -> 0 | G14: =SUMIF(ConsolidadoRJ[Contrato], D12, ConsolidadoRJ[QNm] ) -> 34683 | H14: =(D14-E14-F14)+G14 -> 240564
D15: ARM-CX-MID | E15: Armazenamento de caixas para mídias
C16: 1.2 | D16: QUAm-1 | E16: QBm | F16: QDm | G16: QNm | H16: QUAm | I16: UA | J16: =SUMIF(Consolidado!S:S,D15,Consolidado!O:O) -> 6904 | K16: =J16*N5 -> 6765.92 | L16: =IFERROR(VLOOKUP(ARMCXMID,TabelaIRON[[Linha de Serviço PPU]:[PREÇO UNITÁRIO ]],3,FALSE),"N/A") -> 3.55 | M16: =J16*L16 -> 24509.2
D17: =SUMIF(ConsolidadoRJ[Contrato], D15, ConsolidadoRJ[QUAm-1]) -> 992 | E17: =SUMIF(ConsolidadoRJ[Contrato], D15, ConsolidadoRJ[QBm]) -> 0 | F17: =SUMIF(ConsolidadoRJ[Contrato], D15, ConsolidadoRJ[QDm]) -> 0 | G17: =SUMIF(ConsolidadoRJ[Contrato], D15, ConsolidadoRJ[QNm] ) -> 5912 | H17: =(D17-E17-F17)+G17 -> 6904
D18: ARM-TB | E18: Armazenamento de tubos
C19: 1.3 | D19: QUAm-1 | E19: QBm | F19: QDm | G19: QNm | H19: QUAm | I19: UA | J19: =SUMIF(Consolidado!S:S,D18,Consolidado!O:O) -> 11415.25 | K19: =J19*N5 -> 11186.945 | L19: =IFERROR(VLOOKUP(ARMTB,TabelaIRON[[Linha de Serviço PPU]:[PREÇO UNITÁRIO ]],3,FALSE),"N/A") -> 0.74 | M19: =J19*L19 -> 8447.285
D20: =SUMIF(ConsolidadoRJ[Contrato], D18, ConsolidadoRJ[QUAm-1]) -> 14647 | E20: =SUMIF(ConsolidadoRJ[Contrato], D18, ConsolidadoRJ[QBm]) -> 0 | F20: =SUMIF(ConsolidadoRJ[Contrato], D18, ConsolidadoRJ[QDm]) -> 0 | G20: =SUMIF(ConsolidadoRJ[Contrato], D18, ConsolidadoRJ[QNm] ) -> 0 | H20: =(D20-E20-F20)+G20 -> 14647
D21: ARM-MA | E21: Armazenamento de mapotecas e arquivos de aço
C22: 1.4 | D22: QUAm-1 | E22: QBm | F22: QDm | G22: QNm | H22: QUAm | I22: UA | J22: =SUMIF(Consolidado!S:S,D21,Consolidado!O:O) -> 17 | K22: =J22*N5 -> 16.66 | L22: =IFERROR(VLOOKUP(ARMMA,TabelaIRON[[Linha de Serviço PPU]:[PREÇO UNITÁRIO ]],3,FALSE),"N/A") -> 56.11 | M22: =J22*L22 -> 953.87
D23: =SUMIF(ConsolidadoRJ[Contrato], D21, ConsolidadoRJ[QUAm-1]) -> 17 | E23: =SUMIF(ConsolidadoRJ[Contrato], D21, ConsolidadoRJ[QBm]) -> 0 | F23: =SUMIF(ConsolidadoRJ[Contrato], D21, ConsolidadoRJ[QDm]) -> 0 | G23: =SUMIF(ConsolidadoRJ[Contrato], D21, ConsolidadoRJ[QNm] ) -> 0 | H23: =(D23-E23-F23)+G23 -> 17
D24: ARM-MIC | E24: Armazenamento de microformas
C25: 1.5 | D25: QUAm-1 | E25: QBm | F25: QDm | G25: QNm | H25: QUAm | I25: UA | J25: =SUMIF(Consolidado!S:S,D24,Consolidado!O:O) -> 0 | K25: =J25*N5 -> 0 | L25: =IFERROR(VLOOKUP(ARMMIC,TabelaIRON[[Linha de Serviço PPU]:[PREÇO UNITÁRIO ]],3,FALSE),"N/A") -> 0.08 | M25: =J25*L25 -> 0
D26: =SUMIF(ConsolidadoRJ[Contrato], D24, ConsolidadoRJ[QUAm-1]) -> 0 | E26: =SUMIF(ConsolidadoRJ[Contrato], D24, ConsolidadoRJ[QBm]) -> 0 | F26: =SUMIF(ConsolidadoRJ[Contrato], D24, ConsolidadoRJ[QDm]) -> 0 | G26: =SUMIF(ConsolidadoRJ[Contrato], D24, ConsolidadoRJ[QNm] ) -> 0 | H26: =(D26-E26-F26)+G26 -> 0
D27: ARM-MID | E27: Armazenamento de midias
C28: 1.6 | D28: QUAm-1 | E28: QBm | F28: QDm | G28: QNm | H28: QUAm | I28: UA | J28: =SUMIF(Consolidado!S:S,D27,Consolidado!O:O) -> 14650 | K28: =J28*N5 -> 14357 | L28: =IFERROR(VLOOKUP(ARMMID,TabelaIRON[[Linha de Serviço PPU]:[PREÇO UNITÁRIO ]],3,FALSE),"N/A") -> 0.08 | M28: =J28*L28 -> 1172
D29: =SUMIF(ConsolidadoRJ[Contrato], D27, ConsolidadoRJ[QUAm-1]) -> 5193 | E29: =SUMIF(ConsolidadoRJ[Contrato], D27, ConsolidadoRJ[QBm]) -> 0 | F29: =SUMIF(ConsolidadoRJ[Contrato], D27, ConsolidadoRJ[QDm]) -> 0 | G29: =SUMIF(ConsolidadoRJ[Contrato], D27, ConsolidadoRJ[QNm] ) -> 9457 | H29: =(D29-E29-F29)+G29 -> 14650
C30: 1.7 | D30: FRE-NRM | E30: Frete normal | I30: Frete | J30: 44 | K30: 43.12 | L30: =IFERROR(VLOOKUP(D30,TabelaIRON[[Linha de Serviço PPU]:[PREÇO UNITÁRIO ]],3,FALSE),"N/A") -> 125.89 | M30: =L30*J30 -> 5539.16
C31: 1.8 | D31: FRE-EXP | E31: Frete expresso | I31: Frete | J31: 4 | K31: 3.92 | L31: =IFERROR(VLOOKUP(D31,TabelaIRON[[Linha de Serviço PPU]:[PREÇO UNITÁRIO ]],3,FALSE),"N/A") -> 200 | M31: =L31*J31 -> 800
C32: 1.9 | D32: KM-AD | E32: Quilometragem adicional | I32: KM | J32: 500 | K32: 490 | L32: =IFERROR(VLOOKUP(D32,TabelaIRON[[Linha de Serviço PPU]:[PREÇO UNITÁRIO ]],3,FALSE),"N/A") -> 0.5 | M32: =L32*J32 -> 250
C33: 1.10 | D33: PES-ITEM | E33: Pesquisa de itens avulsos | I33: Item Avulso | J33: 8502 | K33: 8331.96 | L33: =IFERROR(VLOOKUP(D33,TabelaIRON[[Linha de Serviço PPU]:[PREÇO UNITÁRIO ]],3,FALSE),"N/A") -> 1.96 | M33: =L33*J33 -> 16663.92
C34: 1.11 | D34: DES-EMB | E34: Destruição segura de documentos | I34: Item Avulso | J34: 0 | K34: 0 | L34: =IFERROR(VLOOKUP(D34,TabelaIRON[[Linha de Serviço PPU]:[PREÇO UNITÁRIO ]],3,FALSE),"N/A") -> 1.35 | M34: =L34*J34 -> 0
C35: 1.12 | D35: TRANSF | E35: Transferência inicial de acervo documental | I35: Transferência | J35: 0 | K35: 0 | L35: =IFERROR(VLOOKUP(D35,TabelaIRON[[Linha de Serviço PPU]:[PREÇO UNITÁRIO ]],3,FALSE),"N/A") -> 594488.34 | M35: =L35*J35 -> 0
C36: 1.13 | D36: MIGR-UA | E36: Migração de acervo documental para digitalização | I36: UA | J36: 0 | K36: 0 | L36: =IFERROR(VLOOKUP(D36,TabelaIRON[[Linha de Serviço PPU]:[PREÇO UNITÁRIO ]],3,FALSE),"N/A") -> 1.01 | M36: =L36*J36 -> 0
C37: 2 | D37: Gerenciamento de Documentos e Informações
C38: 2.1 | D38: CAT-ITEM | E38: Catalogação de documentos digitalizados | I38: Documento | J38: 8502 | K38: 8502 | L38: =IFERROR(VLOOKUP(D38,TabelaIRON[[Linha de Serviço PPU]:[PREÇO UNITÁRIO ]],3,FALSE),"N/A") -> 0.44 | M38: =J38*L38 -> 3740.88
C39: 2.2 | D39: ORG-DOC | E39: Organização de documentos para digitalização | I39: UA | J39: 0 | K39: 0 | L39: =IFERROR(VLOOKUP(D39,TabelaIRON[[Linha de Serviço PPU]:[PREÇO UNITÁRIO ]],3,FALSE),"N/A") -> 1.44 | M39: =J39*L39 -> 0
C40: 2.3 | D40: DIG-MI | E40: Digitalização de microfilmes | I40: UD | J40: 0 | K40: 0 | L40: =IFERROR(VLOOKUP(D40,TabelaIRON[[Linha de Serviço PPU]:[PREÇO UNITÁRIO ]],3,FALSE),"N/A") -> 0.05 | M40: =J40*L40 -> 0
C41: 2.4 | D41: DIG-MF | E41: Digitalização de microfichas | I41: UD | J41: 7 | K41: 7 | L41: =IFERROR(VLOOKUP(D41,TabelaIRON[[Linha de Serviço PPU]:[PREÇO UNITÁRIO ]],3,FALSE),"N/A") -> 0.06 | M41: =J41*L41 -> 0.42
C42: 2.5 | D42: DIG-DOC | E42: Digitalização de documentos | I42: UD | J42: 197507 | K42: 197507 | L42: =IFERROR(VLOOKUP(D42,TabelaIRON[[Linha de Serviço PPU]:[PREÇO UNITÁRIO ]],3,FALSE),"N/A") -> 0.1 | M42: =J42*L42 -> 19750.7
C43: 2.6 | D43: IND-DOC | E43: Indexação de documentos | I43: UD | J43: 8502 | K43: 8502 | L43: =IFERROR(VLOOKUP(D43,TabelaIRON[[Linha de Serviço PPU]:[PREÇO UNITÁRIO ]],3,FALSE),"N/A") -> 0.23 | M43: =J43*L43 -> 1955.46
...

Sheet Consolidado
A1: Consolidado RJ | J1: mês anterior | K1: Saída/mês | L1: Exp./Mês | M1: Novas/mês | N1: QUAm = QUAm-1 + QNm - QBm - QDm
C2: Formula | D2: Formula | E2: Formula | F2: Formula | G2: Formula | H2: Formula | J2: Editar | K2: Editar | L2: Editar | M2: Editar | N2: Formula | O2: Formula | P2: Formula | Q2: Formula
A3: MEDIDAS CONTRATO | B3: Padrão | C3: Ø | D3: A | E3: L | F3: P | G3: cm³ = V1 | H3: cm³ = V2 | I3: FC = V1/V2 | J3: QUAm-1 | K3: QBm | L3: QDm | M3: QNm | N3: QUAm | O3: UA | P3: $ Unitário | Q3: $ Total | R3: Tabela | S3: Contrato
A4: A 29,0 X L 41,0 X P 37,0 | B4: Caixa 20 kg - Tipo 1 | C4: =IF( ConsolidadoRJ[[#This Row],[MEDIDAS CONTRATO]] = "", "", IFERROR( VLOOKUP(ConsolidadoRJ[[#This Row],[MEDIDAS CONTRATO]],MedidasContrato[[MEDIDAS CONTRATO]:[Ø]],2,0),"N/A")) -> 0 | D4: =IF( ConsolidadoRJ[[#This Row],[MEDIDAS CONTRATO]] = "", "", IFERROR( VLOOKUP(ConsolidadoRJ[[#This Row],[MEDIDAS CONTRATO]],MedidasContrato[],3,0),"N/A")) -> 29 | E4: =IF( ConsolidadoRJ[[#This Row],[MEDIDAS CONTRATO]] = "", "", IFERROR( VLOOKUP(ConsolidadoRJ[[#This Row],[MEDIDAS CONTRATO]],MedidasContrato[],4,0),"N/A")) -> 41 | F4: =IF( ConsolidadoRJ[[#This Row],[MEDIDAS CONTRATO]] = "", "", IFERROR( VLOOKUP(ConsolidadoRJ[[#This Row],[MEDIDAS CONTRATO]],MedidasContrato[],5,0),"N/A")) -> 37 | G4: =IFERROR( Consolidado!$D4*Consolidado!$E4*Consolidado!$F4, "") -> 43993 | H4: =IFERROR( IF(ConsolidadoRJ[[#This Row],[cm³ = V1]]="","",ConsolidadoRJ[[#This Row],[cm³ = V1]]/ConsolidadoRJ[[#This Row],[FC = V1/V2]]), "") -> 43993 | I4: 1 | J4: 199223 | K4: 128 | L4: 0 | M4: 28034 | N4: =IF(ConsolidadoRJ[[#This Row],[QUAm-1]]="","",ConsolidadoRJ[[#This Row],[QUAm-1]]+ConsolidadoRJ[[#This Row],[QNm]]-ConsolidadoRJ[[#This Row],[QBm]]-ConsolidadoRJ[[#This Row],[QDm]]) -> 227129 | O4: =IF(ConsolidadoRJ[[#This Row],[FC = V1/V2]]="","",ConsolidadoRJ[[#This Row],[FC = V1/V2]]*ConsolidadoRJ[[#This Row],[QUAm]]) -> 227129 | P4: =IF( ConsolidadoRJ[[#This Row],[Contrato]] = "", "", IFERROR( VLOOKUP(ConsolidadoRJ[[#This Row],[Contrato]],TabelaIRON[[Linha de Serviço PPU]:[PREÇO UNITÁRIO ]],3,0),"Nao Encontrado")) -> 0.6 | Q4: =IF(ConsolidadoRJ[[#This Row],[UA]]="","",ConsolidadoRJ[[#This Row],[UA]]*ConsolidadoRJ[[#This Row],[$ Unitário]]) -> 136277.4 | R4: FC1 | S4: ARM-CX-DOC
A5: A 34,0 X L 37,0 X P 12,0 | B5: Caixa para mídias - Tipo 1 | C5: =IF( ConsolidadoRJ[[#This Row],[MEDIDAS CONTRATO]] = "", "", IFERROR( VLOOKUP(ConsolidadoRJ[[#This Row],[MEDIDAS CONTRATO]],MedidasContrato[[MEDIDAS CONTRATO]:[Ø]],2,0),"N/A")) -> 0 | D5: =IF( ConsolidadoRJ[[#This Row],[MEDIDAS CONTRATO]] = "", "", IFERROR( VLOOKUP(ConsolidadoRJ[[#This Row],[MEDIDAS CONTRATO]],MedidasContrato[],3,0),"N/A")) -> 34 | E5: =IF( ConsolidadoRJ[[#This Row],[MEDIDAS CONTRATO]] = "", "", IFERROR( VLOOKUP(ConsolidadoRJ[[#This Row],[MEDIDAS CONTRATO]],MedidasContrato[],4,0),"N/A")) -> 37 | F5: =IF( ConsolidadoRJ[[#This Row],[MEDIDAS CONTRATO]] = "", "", IFERROR( VLOOKUP(ConsolidadoRJ[[#This Row],[MEDIDAS CONTRATO]],MedidasContrato[],5,0),"N/A")) -> 12 | G5: =IFERROR( Consolidado!$D5*Consolidado!$E5*Consolidado!$F5, "") -> 15096 | H5: =IFERROR( IF(ConsolidadoRJ[[#This Row],[cm³ = V1]]="","",ConsolidadoRJ[[#This Row],[cm³ = V1]]/ConsolidadoRJ[[#This Row],[FC = V1/V2]]), "") -> 15096 | I5: 1 | J5: 992 | K5: 0 | L5: 0 | M5: 5912 | N5: =IF(ConsolidadoRJ[[#This Row],[QUAm-1]]="","",ConsolidadoRJ[[#This Row],[QUAm-1]]+ConsolidadoRJ[[#This Row],[QNm]]-ConsolidadoRJ[[#This Row],[QBm]]-ConsolidadoRJ[[#This Row],[QDm]]) -> 6904 | O5: =IF(ConsolidadoRJ[[#This Row],[FC = V1/V2]]="","",ConsolidadoRJ[[#This Row],[FC = V1/V2]]*ConsolidadoRJ[[#This Row],[QUAm]]) -> 6904 | P5: =IF( ConsolidadoRJ[[#This Row],[Contrato]] = "", "", IFERROR( VLOOKUP(ConsolidadoRJ[[#This Row],[Contrato]],TabelaIRON[[Linha de Serviço PPU]:[PREÇO UNITÁRIO ]],3,0),"Nao Encontrado")) -> 3.55 | Q5: =IF(ConsolidadoRJ[[#This Row],[UA]]="","",ConsolidadoRJ[[#This Row],[UA]]*ConsolidadoRJ[[#This Row],[$ Unitário]]) -> 24509.2 | R5: FC2 | S5: ARM-CX-MID
A6: A 40,5 X L 41,5 X P 10,0 | B6: Caixa para mídias - Tipo 2 | C6: =IF( ConsolidadoRJ[[#This Row],[MEDIDAS CONTRATO]] = "", "", IFERROR( VLOOKUP(ConsolidadoRJ[[#This Row],[MEDIDAS CONTRATO]],MedidasContrato[[MEDIDAS CONTRATO]:[Ø]],2,0),"N/A")) -> 0 | D6: =IF( ConsolidadoRJ[[#This Row],[MEDIDAS CONTRATO]] = "", "", IFERROR( VLOOKUP(ConsolidadoRJ[[#This Row],[MEDIDAS CONTRATO]],MedidasContrato[],3,0),"N/A")) -> 40.5 | E6: =IF( ConsolidadoRJ[[#This Row],[MEDIDAS CONTRATO]] = "", "", IFERROR( VLOOKUP(ConsolidadoRJ[[#This Row],[MEDIDAS CONTRATO]],MedidasContrato[],4,0),"N/A")) -> 41.5 | F6: =IF( ConsolidadoRJ[[#This Row],[MEDIDAS CONTRATO]] = "", "", IFERROR( VLOOKUP(ConsolidadoRJ[[#This Row],[MEDIDAS CONTRATO]],MedidasContrato[],5,0),"N/A")) -> 10 | G6: =IFERROR( Consolidado!$D6*Consolidado!$E6*Consolidado!$F6, "") -> 16807.5 | H6: =IFERROR( IF(ConsolidadoRJ[[#This Row],[cm³ = V1]]="","",ConsolidadoRJ[[#This Row],[cm³ = V1]]/ConsolidadoRJ[[#This Row],[FC = V1/V2]]), "") -> 15101.078 | I6: 1.113 | J6: 0 | K6: 0 | L6: 0 | M6: 0 | N6: =IF(ConsolidadoRJ[[#This Row],[QUAm-1]]="","",ConsolidadoRJ[[#This Row],[QUAm-1]]+ConsolidadoRJ[[#This Row],[QNm]]-ConsolidadoRJ[[#This Row],[QBm]]-ConsolidadoRJ[[#This Row],[QDm]]) -> 0 | O6: =IF(ConsolidadoRJ[[#This Row],[FC = V1/V2]]="","",ConsolidadoRJ[[#This Row],[FC = V1/V2]]*ConsolidadoRJ[[#This Row],[QUAm]]) -> 0 | P6: =IF( ConsolidadoRJ[[#This Row],[Contrato]] = "", "", IFERROR( VLOOKUP(ConsolidadoRJ[[#This Row],[Contrato]],TabelaIRON[[Linha de Serviço PPU]:[PREÇO UNITÁRIO ]],3,0),"Nao Encontrado")) -> 3.55 | Q6: =IF(ConsolidadoRJ[[#This Row],[UA]]="","",ConsolidadoRJ[[#This Row],[UA]]*ConsolidadoRJ[[#This Row],[$ Unitário]]) -> 0 | R6: FC2 | S6: ARM-CX-MID
A7: A 30,0 X L 19,0 X P 39,0 | B7: Caixa 10 kg (Jumbo) | C7: =IF( ConsolidadoRJ[[#This Row],[MEDIDAS CONTRATO]] = "", "", IFERROR( VLOOKUP(ConsolidadoRJ[[#This Row],[MEDIDAS CONTRATO]],MedidasContrato[[MEDIDAS CONTRATO]:[Ø]],2,0),"N/A")) -> 0 | D7: =IF( ConsolidadoRJ[[#This Row],[MEDIDAS CONTRATO]] = "", "", IFERROR( VLOOKUP(ConsolidadoRJ[[#This Row],[MEDIDAS CONTRATO]],MedidasContrato[],3,0),"N/A")) -> 30 | E7: =IF( ConsolidadoRJ[[#This Row],[MEDIDAS CONTRATO]] = "", "", IFERROR( VLOOKUP(ConsolidadoRJ[[#This Row],[MEDIDAS CONTRATO]],MedidasContrato[],4,0),"N/A")) -> 19 | F7: =IF( ConsolidadoRJ[[#This Row],[MEDIDAS CONTRATO]] = "", "", IFERROR( VLOOKUP(ConsolidadoRJ[[#This Row],[MEDIDAS CONTRATO]],MedidasContrato[],5,0),"N/A")) -> 39 | G7: =IFERROR( Consolidado!$D7*Consolidado!$E7*Consolidado!$F7, "") -> 22230 | H7: =IFERROR( IF(ConsolidadoRJ[[#This Row],[cm³ = V1]]="","",ConsolidadoRJ[[#This Row],[cm³ = V1]]/ConsolidadoRJ[[#This Row],[FC = V1/V2]]), "") -> 44019.802 | I7: 0.505 | J7: 6786 | K7: 0 | L7: 0 | M7: 6649 | N7: =IF(ConsolidadoRJ[[#This Row],[QUAm-1]]="","",ConsolidadoRJ[[#This Row],[QUAm-1]]+ConsolidadoRJ[[#This Row],[QNm]]-ConsolidadoRJ[[#This Row],[QBm]]-ConsolidadoRJ[[#This Row],[QDm]]) -> 13435 | O7: =IF(ConsolidadoRJ[[#This Row],[FC = V1/V2]]="","",ConsolidadoRJ[[#This Row],[FC = V1/V2]]*ConsolidadoRJ[[#This Row],[QUAm]]) -> 6784.675 | P7: =IF( ConsolidadoRJ[[#This Row],[Contrato]] = "", "", IFERROR( VLOOKUP(ConsolidadoRJ[[#This Row],[Contrato]],TabelaIRON[[Linha de Serviço PPU]:[PREÇO UNITÁRIO ]],3,0),"Nao Encontrado")) -> 0.6 | Q7: =IF(ConsolidadoRJ[[#This Row],[UA]]="","",ConsolidadoRJ[[#This Row],[UA]]*ConsolidadoRJ[[#This Row],[$ Unitário]]) -> 4070.805 | R7: FC1 | S7: ARM-CX-DOC
A8: Ø10,0 P 120,0 | B8: Tubo de engenharia | C8: =IF( ConsolidadoRJ[[#This Row],[MEDIDAS CONTRATO]] = "", "", IFERROR( VLOOKUP(ConsolidadoRJ[[#This Row],[MEDIDAS CONTRATO]],MedidasContrato[[MEDIDAS CONTRATO]:[Ø]],2,0),"N/A")) -> 10 | D8: =IF( ConsolidadoRJ[[#This Row],[MEDIDAS CONTRATO]] = "", "", IFERROR( VLOOKUP(ConsolidadoRJ[[#This Row],[MEDIDAS CONTRATO]],MedidasContrato[],3,0),"N/A")) -> 0 | E8: =IF( ConsolidadoRJ[[#This Row],[MEDIDAS CONTRATO]] = "", "", IFERROR( VLOOKUP(ConsolidadoRJ[[#This Row],[MEDIDAS CONTRATO]],MedidasContrato[],4,0),"N/A")) -> 0 | F8: =IF( ConsolidadoRJ[[#This Row],[MEDIDAS CONTRATO]] = "", "", IFERROR( VLOOKUP(ConsolidadoRJ[[#This Row],[MEDIDAS CONTRATO]],MedidasContrato[],5,0),"N/A")) -> 120 | G8: =IFERROR( Consolidado!$D8*Consolidado!$E8*Consolidado!$F8, "") -> 0 | H8: =IFERROR( IF(ConsolidadoRJ[[#This Row],[cm³ = V1]]="","",ConsolidadoRJ[[#This Row],[cm³ = V1]]/ConsolidadoRJ[[#This Row],[FC = V1/V2]]), "") -> 0 | I8: 1 | J8: 10338 | K8: 0 | L8: 0 | M8: 0 | N8: =IF(ConsolidadoRJ[[#This Row],[QUAm-1]]="","",ConsolidadoRJ[[#This Row],[QUAm-1]]+ConsolidadoRJ[[#This Row],[QNm]]-ConsolidadoRJ[[#This Row],[QBm]]-ConsolidadoRJ[[#This Row],[QDm]]) -> 10338 | O8: =IF(ConsolidadoRJ[[#This Row],[FC = V1/V2]]="","",ConsolidadoRJ[[#This Row],[FC = V1/V2]]*ConsolidadoRJ[[#This Row],[QUAm]]) -> 10338 | P8: =IF( ConsolidadoRJ[[#This Row],[Contrato]] = "", "", IFERROR( VLOOKUP(ConsolidadoRJ[[#This Row],[Contrato]],TabelaIRON[[Linha de Serviço PPU]:[PREÇO UNITÁRIO ]],3,0),"Nao Encontrado")) -> 0.74 | Q8: =IF(ConsolidadoRJ[[#This Row],[UA]]="","",ConsolidadoRJ[[#This Row],[UA]]*ConsolidadoRJ[[#This Row],[$ Unitário]]) -> 7650.12 | R8: FC3 | S8: ARM-TB
A9: A 135,0 X L 51,0 X P 105,0 | B9: Mapoteca | C9: =IF( ConsolidadoRJ[[#This Row],[MEDIDAS CONTRATO]] = "", "", IFERROR( VLOOKUP(ConsolidadoRJ[[#This Row],[MEDIDAS CONTRATO]],MedidasContrato[[MEDIDAS CONTRATO]:[Ø]],2,0),"N/A")) -> 0 | D9: =IF( ConsolidadoRJ[[#This Row],[MEDIDAS CONTRATO]] = "", "", IFERROR( VLOOKUP(ConsolidadoRJ[[#This Row],[MEDIDAS CONTRATO]],MedidasContrato[],3,0),"N/A")) -> 135 | E9: =IF( ConsolidadoRJ[[#This Row],[MEDIDAS CONTRATO]] = "", "", IFERROR( VLOOKUP(ConsolidadoRJ[[#This Row],[MEDIDAS CONTRATO]],MedidasContrato[],4,0),"N/A")) -> 51 | F9: =IF( ConsolidadoRJ[[#This Row],[MEDIDAS CONTRATO]] = "", "", IFERROR( VLOOKUP(ConsolidadoRJ[[#This Row],[MEDIDAS CONTRATO]],MedidasContrato[],5,0),"N/A")) -> 105 | G9: =IFERROR( Consolidado!$D9*Consolidado!$E9*Consolidado!$F9, "") -> 722925 | H9: =IFERROR( IF(ConsolidadoRJ[[#This Row],[cm³ = V1]]="","",ConsolidadoRJ[[#This Row],[cm³ = V1]]/ConsolidadoRJ[[#This Row],[FC = V1/V2]]), "") -> 722925 | I9: 1 | J9: 17 | K9: 0 | L9: 0 | M9: 0 | N9: =IF(ConsolidadoRJ[[#This Row],[QUAm-1]]="","",ConsolidadoRJ[[#This Row],[QUAm-1]]+ConsolidadoRJ[[#This Row],[QNm]]-ConsolidadoRJ[[#This Row],[QBm]]-ConsolidadoRJ[[#This Row],[QDm]]) -> 17 | O9: =IF(ConsolidadoRJ[[#This Row],[FC = V1/V2]]="","",ConsolidadoRJ[[#This Row],[FC = V1/V2]]*ConsolidadoRJ[[#This Row],[QUAm]]) -> 17 | P9: =IF( ConsolidadoRJ[[#This Row],[Contrato]] = "", "", IFERROR( VLOOKUP(ConsolidadoRJ[[#This Row],[Contrato]],TabelaIRON[[Linha de Serviço PPU]:[PREÇO UNITÁRIO ]],3,0),"Nao Encontrado")) -> 56.11 | Q9: =IF(ConsolidadoRJ[[#This Row],[UA]]="","",ConsolidadoRJ[[#This Row],[UA]]*ConsolidadoRJ[[#This Row],[$ Unitário]]) -> 953.87 | R9: FC4 | S9: ARM-MA
A10: A 10,0 X L 10,0 X P 2,5 | B10: Microfilme | C10: =IF( ConsolidadoRJ[[#This Row],[MEDIDAS CONTRATO]] = "", "", IFERROR( VLOOKUP(ConsolidadoRJ[[#This Row],[MEDIDAS CONTRATO]],MedidasContrato[[MEDIDAS CONTRATO]:[Ø]],2,0),"N/A")) -> 0 | D10: =IF( ConsolidadoRJ[[#This Row],[MEDIDAS CONTRATO]] = "", "", IFERROR( VLOOKUP(ConsolidadoRJ[[#This Row],[MEDIDAS CONTRATO]],MedidasContrato[],3,0),"N/A")) -> 10 | E10: =IF( ConsolidadoRJ[[#This Row],[MEDIDAS CONTRATO]] = "", "", IFERROR( VLOOKUP(ConsolidadoRJ[[#This Row],[MEDIDAS CONTRATO]],MedidasContrato[],4,0),"N/A")) -> 10 | F10: =IF( ConsolidadoRJ[[#This Row],[MEDIDAS CONTRATO]] = "", "", IFERROR( VLOOKUP(ConsolidadoRJ[[#This Row],[MEDIDAS CONTRATO]],MedidasContrato[],5,0),"N/A")) -> 2.5 | G10: =IFERROR( Consolidado!$D10*Consolidado!$E10*Consolidado!$F10, "") -> 250 | H10: =IFERROR( IF(ConsolidadoRJ[[#This Row],[cm³ = V1]]="","",ConsolidadoRJ[[#This Row],[cm³ = V1]]/ConsolidadoRJ[[#This Row],[FC = V1/V2]]), "") -> 250 | I10: 1 | J10: 0 | K10: 0 | L10: 0 | M10: 6123 | N10: =IF(ConsolidadoRJ[[#This Row],[QUAm-1]]="","",ConsolidadoRJ[[#This Row],[QUAm-1]]+ConsolidadoRJ[[#This Row],[QNm]]-ConsolidadoRJ[[#This Row],[QBm]]-ConsolidadoRJ[[#This Row],[QDm]]) -> 6123 | O10: =IF(ConsolidadoRJ[[#This Row],[FC = V1/V2]]="","",ConsolidadoRJ[[#This Row],[FC = V1/V2]]*ConsolidadoRJ[[#This Row],[QUAm]]) -> 6123 | P10: =IF( ConsolidadoRJ[[#This Row],[Contrato]] = "", "", IFERROR( VLOOKUP(ConsolidadoRJ[[#This Row],[Contrato]],TabelaIRON[[Linha de Serviço PPU]:[PREÇO UNITÁRIO ]],3,0),"Nao Encontrado")) -> 0.08 | Q10: =IF(ConsolidadoRJ[[#This Row],[UA]]="","",ConsolidadoRJ[[#This Row],[UA]]*ConsolidadoRJ[[#This Row],[$ Unitário]]) -> 489.84 | R10: FC5 | S10: ARM-MID
A11: A 12,5 X L 14 X P 0,5 | B11: Mídia óptica | C11: =IF( ConsolidadoRJ[[#This Row],[MEDIDAS CONTRATO]] = "", "", IFERROR( VLOOKUP(ConsolidadoRJ[[#This Row],[MEDIDAS CONTRATO]],MedidasContrato[[MEDIDAS CONTRATO]:[Ø]],2,0),"N/A")) -> 0 | D11: =IF( ConsolidadoRJ[[#This Row],[MEDIDAS CONTRATO]] = "", "", IFERROR( VLOOKUP(ConsolidadoRJ[[#This Row],[MEDIDAS CONTRATO]],MedidasContrato[],3,0),"N/A")) -> 12.5 | E11: =IF( ConsolidadoRJ[[#This Row],[MEDIDAS CONTRATO]] = "", "", IFERROR( VLOOKUP(ConsolidadoRJ[[#This Row],[MEDIDAS CONTRATO]],MedidasContrato[],4,0),"N/A")) -> 14 | F11: =IF( ConsolidadoRJ[[#This Row],[MEDIDAS CONTRATO]] = "", "", IFERROR( VLOOKUP(ConsolidadoRJ[[#This Row],[MEDIDAS CONTRATO]],MedidasContrato[],5,0),"N/A")) -> 0.5 | G11: =IFERROR( Consolidado!$D11*Consolidado!$E11*Consolidado!$F11, "") -> 87.5 | H11: =IFERROR( IF(ConsolidadoRJ[[#This Row],[cm³ = V1]]="","",ConsolidadoRJ[[#This Row],[cm³ = V1]]/ConsolidadoRJ[[#This Row],[FC = V1/V2]]), "") -> 87.5 | I11: 1 | J11: 5193 | K11: 0 | L11: 0 | M11: 3334 | N11: =IF(ConsolidadoRJ[[#This Row],[QUAm-1]]="","",ConsolidadoRJ[[#This Row],[QUAm-1]]+ConsolidadoRJ[[#This Row],[QNm]]-ConsolidadoRJ[[#This Row],[QBm]]-ConsolidadoRJ[[#This Row],[QDm]]) -> 8527 | O11: =IF(ConsolidadoRJ[[#This Row],[FC = V1/V2]]="","",ConsolidadoRJ[[#This Row],[FC = V1/V2]]*ConsolidadoRJ[[#This Row],[QUAm]]) -> 8527 | P11: =IF( ConsolidadoRJ[[#This Row],[Contrato]] = "", "", IFERROR( VLOOKUP(ConsolidadoRJ[[#This Row],[Contrato]],TabelaIRON[[Linha de Serviço PPU]:[PREÇO UNITÁRIO ]],3,0),"Nao Encontrado")) -> 0.08 | Q11: =IF(ConsolidadoRJ[[#This Row],[UA]]="","",ConsolidadoRJ[[#This Row],[UA]]*ConsolidadoRJ[[#This Row],[$ Unitário]]) -> 682.16 | R11: FC6 | S11: ARM-MID
A12: L 10 X P 30 | B12: Tubo para perfil de poço | C12: =IF( ConsolidadoRJ[[#This Row],[MEDIDAS CONTRATO]] = "", "", IFERROR( VLOOKUP(ConsolidadoRJ[[#This Row],[MEDIDAS CONTRATO]],MedidasContrato[[MEDIDAS CONTRATO]:[Ø]],2,0),"N/A")) -> 0 | D12: =IF( ConsolidadoRJ[[#This Row],[MEDIDAS CONTRATO]] = "", "", IFERROR( VLOOKUP(ConsolidadoRJ[[#This Row],[MEDIDAS CONTRATO]],MedidasContrato[],3,0),"N/A")) -> 104 | E12: =IF( ConsolidadoRJ[[#This Row],[MEDIDAS CONTRATO]] = "", "", IFERROR( VLOOKUP(ConsolidadoRJ[[#This Row],[MEDIDAS CONTRATO]],MedidasContrato[],4,0),"N/A")) -> 10 | F12: =IF( ConsolidadoRJ[[#This Row],[MEDIDAS CONTRATO]] = "", "", IFERROR( VLOOKUP(ConsolidadoRJ[[#This Row],[MEDIDAS CONTRATO]],MedidasContrato[],5,0),"N/A")) -> 30 | G12: =IFERROR( Consolidado!$D12*Consolidado!$E12*Consolidado!$F12, "") -> 31200 | H12: =IFERROR( IF(ConsolidadoRJ[[#This Row],[cm³ = V1]]="","",ConsolidadoRJ[[#This Row],[cm³ = V1]]/ConsolidadoRJ[[#This Row],[FC = V1/V2]]), "") -> 124800 | I12: 0.25 | J12: 4309 | K12: 0 | L12: 0 | M12: 0 | N12: =IF(ConsolidadoRJ[[#This Row],[QUAm-1]]="","",ConsolidadoRJ[[#This Row],[QUAm-1]]+ConsolidadoRJ[[#This Row],[QNm]]-ConsolidadoRJ[[#This Row],[QBm]]-ConsolidadoRJ[[#This Row],[QDm]]) -> 4309 | O12: =IF(ConsolidadoRJ[[#This Row],[FC = V1/V2]]="","",ConsolidadoRJ[[#This Row],[FC = V1/V2]]*ConsolidadoRJ[[#This Row],[QUAm]]) -> 1077.25 | P12: =IF( ConsolidadoRJ[[#This Row],[Contrato]] = "", "", IFERROR( VLOOKUP(ConsolidadoRJ[[#This Row],[Contrato]],TabelaIRON[[Linha de Serviço PPU]:[PREÇO UNITÁRIO ]],3,0),"Nao Encontrado")) -> 0.74 | Q12: =IF(ConsolidadoRJ[[#This Row],[UA]]="","",ConsolidadoRJ[[#This Row],[UA]]*ConsolidadoRJ[[#This Row],[$ Unitário]]) -> 797.165 | R12: FC3 | S12: ARM-TB

Sheet Tabela
A1: Padrão | C1: Tabela | E1: Linha de serviço PPU | G1: ITEM | H1: DESCRIÇÃO | I1: Linha de Serviço PPU | J1: UNID. | K1: PREÇO UNITÁRIO | L1: Descrição da Linha de Serviço | N1: MEDIDAS CONTRATO | O1: Ø | P1: A | Q1: L | R1: P
A2: Arquivo de aço 1 | C2: FC1 | E2: ARM-CX-DOC | G2: 1.1 | H2: ARM-CX-DOC: Armazenamento de caixas para documentos | I2: ARM-CX-DOC | J2: UA | K2: 0.6 | L2: Armazenamento de caixas para documentos | N2: A 0,5 X L 12,5 X P14,0 | P2: 0.5 | Q2: 12.5 | R2: 14
A3: Arquivo de aço 2 | C3: FC2 | E3: ARM-CX-MID | G3: 1.2 | H3: ARM-CX-MID: Armazenamento de caixas para mídias | I3: ARM-CX-MID | J3: UA | K3: 3.55 | L3: Armazenamento de caixas para mídias | N3: A 0,5 X L 13,0 X P13,0 | P3: 0.5 | Q3: 13 | R3: 13
A4: Arquivo de aço 3 | C4: FC3 | E4: ARM-TB | G4: 1.3 | H4: ARM-TB: Armazenamento de tubos | I4: ARM-TB | J4: UA | K4: 0.74 | L4: Armazenamento de tubos | N4: A 0,5 X L 14,0 X P 12,5 | P4: 0.5 | Q4: 14 | R4: 12.5
A5: Arquivo de aço 4 | C5: FC4 | E5: ARM-MA | G5: 1.4 | H5: ARM-MA: Armazenamento de mapotecas e arquivos de aço | I5: ARM-MA | J5: UA | K5: 56.11 | L5: Armazenamento de mapotecas e arquivos de aço | N5: A 0,5 X L 14,0 X P 13,0 | P5: 0.5 | Q5: 14 | R5: 13
A6: Arquivo de aço 5 | C6: FC5 | E6: ARM-MIC | G6: 1.5 | H6: ARM-MIC: Armazenamento de microformas | I6: ARM-MIC | J6: UA | K6: 0.08 | L6: Armazenamento de microformas | N6: A 0,5 X L 14,0 X P 14,0 | P6: 0.5 | Q6: 14 | R6: 14
A7: Caixa 10 kg (Jumbo) | C7: FC6 | E7: ARM-MID | G7: 1.6 | H7: ARM-MID: Armazenamento de midias | I7: ARM-MID | J7: UA | K7: 0.08 | L7: Armazenamento de midias | N7: A 08,0 X L 41,0 X P 41,0 | P7: 8 | Q7: 41 | R7: 41
A8: Caixa 20 Kg | C8: FC7 | E8: FRE-NRM | G8: 1.7 | H8: FRE-NRM: Frete normal | I8: FRE-NRM | J8: Frete | K8: 125.89 | L8: Frete normal | N8: A 1,0 X L 12,5 X P14,0 | P8: 1 | Q8: 12.5 | R8: 14
A9: Caixa 20 kg - Tipo 1 | C9: FC8 | E9: FRE-EXP | G9: 1.8 | H9: FRE-EXP: Frete expresso | I9: FRE-EXP | J9: Frete | K9: 200 | L9: Frete expresso | N9: A 1,0 X L 14,0 X P 13,0 | P9: 1 | Q9: 14 | R9: 13
A10: Caixa 20 kg - Tipo 2 | C10: FC9 | E10: INS-ITEM | G10: 1.9 | H10: KM-AD: Quilometragem adicional | I10: KM-AD | J10: KM | K10: 0.5 | L10: Quilometragem adicional | N10: A 1,0 X L 14,0 X P 19,0 | P10: 1 | Q10: 14 | R10: 19
A11: Caixa 20 kg (contendo Mídias e Microfilmes) | E11: PES-ITEM | G11: 1.10 | H11: PES-ITEM: Pesquisa de itens avulsos | I11: PES-ITEM | J11: Item Avulso | K11: 1.96 | L11: Pesquisa de itens avulsos | N11: A 10,0 X L 10,0 X P 2,5 | P11: 10 | Q11: 10 | R11: 2.5
A12: Caixa 5 kg | E12: DES-EMB | G12: 1.11 | H12: DES-EMB: Destruição segura de documentos | I12: DES-EMB | J12: Embalagem | K12: 1.35 | L12: Destruição segura de documentos | N12: A 10,0 X L 10,5 X P 4,0 | P12: 10 | Q12: 10.5 | R12: 4
A13: Caixa 5kg | E13: TRANSF | G13: 1.12 | H13: TRANSF: Transferência inicial de acervo documental | I13: TRANSF | J13: Transferência | K13: 594488.34 | L13: Transferência inicial de acervo documental | N13: A 10,0 X L 15,5 X P 0,3 | P13: 10 | Q13: 15.5 | R13: 0.3
A14: Caixa 7 kg | E14: MIGR-UA | G14: 1.13 | H14: MIGR-UA: Migração de acervo documental para digitalização | I14: MIGR-UA | J14: UA | K14: 1.01 | L14: Migração de acervo documental para digitalização | N14: A 10,0 X L 19,0 X P 26,5 | P14: 10 | Q14: 19 | R14: 26.5
A15: Caixa para mídias - Tipo 1 | E15: CAT-EMB | G15: 2.1 | H15: CAT-ITEM: Catalogação de documentos digitalizados | I15: CAT-ITEM | J15: Documento | K15: 0.44 | L15: Catalogação de documentos digitalizados | N15: A 10,0 X L 3,0 X P 10,0 | P15: 10 | Q15: 3 | R15: 10
A16: Caixa para mídias - Tipo 2 | E16: CAT-ITEM | G16: 2.2 | H16: ORG-DOC: Organização de documentos para digitalização | I16: ORG-DOC | J16: UA | K16: 1.44 | L16: Organização de documentos para digitalização | N16: A 10,0 X L 4,5 X P 10,0 | P16: 10 | Q16: 4.5 | R16: 10
A17: Documentação administrativa | E17: ORG-DOC | G17: 2.3 | H17: DIG-MI: Digitalização de microfilmes | I17: DIG-MI | J17: UD | K17: 0.05 | L17: Digitalização de microfilmes | N17: A 10,5 X L 15,0 X P 0,3 | P17: 10.5 | Q17: 15 | R17: 0.3
A18: Documentação bibliográfica | E18: HIG-MI | G18: 2.4 | H18: DIG-MF: Digitalização de microfichas | I18: DIG-MF | J18: UD | K18: 0.06 | L18: Digitalização de microfichas | N18: A 10,5 X L 19,0 X P2,5 | P18: 10.5 | Q18: 19 | R18: 2.5
A19: Documentação contábil e financeira | E19: HIG-MF | G19: 2.5 | H19: DIG-DOC: Digitalização de documentos | I19: DIG-DOC | J19: UD | K19: 0.1 | L19: Digitalização de documentos | N19: A 10,5 X L 41,0 X P 41,0 | P19: 10.5 | Q19: 41 | R19: 41
A20: Documentação contratual | E20: HIG-PER | G20: 2.6 | H20: IND-DOC: Indexação de documentos | I20: IND-DOC | J20: UD | K20: 0.23 | L20: Indexação de documentos | N20: A 100,0 X L 140,0 X P 51,0 | P20: 100 | Q20: 140 | R20: 51
A21: Documentação técnica | E21: DIG-MI | G21: 2.7 | H21: CONV-MID: Conversão de mídias | I21: CONV-MID | J21: Mídia | K21: 68.27 | L21: Conversão de mídias | N21: A 11,0 X L 15,5 X P 0,3 | P21: 11 | Q21: 15.5 | R21: 0.3
A22: Documento - Formato A0 | E22: DIG-MF | G22: 2.8 | H22: GRV-MID: Gravação de mídias | I22: GRV-MID | J22: Mídia | K22: 39 | L22: Gravação de mídias | N22: A 11,0 X L 33,0 X P 37,0 | P22: 11 | Q22: 33 | R22: 37
... A24: Documento - Formato A2 | E24: IND-DOC | G24: 2.10 | H24: COP-VID: Cópia de vídeos | I24: COP-VID | J24: Mídia | K24: 2.44 | L24: Cópia de vídeos | N24: A 11,5 X L 37,0 X P 33,0 | P24: 11.5 | Q24: 37 | R24: 33
A25: Documento - Formato A3 | E25: CONV-MID | N25: A 12,0 X L 34,0 X P 37,0 | P25: 12 | Q25: 34 | R25: 37
A26: Documento - Formato A4 | E26: GRV-MID | N26: A 12,0 X L 34,0 X P 37,0 | P26: 12 | Q26: 34 | R26: 37
A27: Documento - Superior ao Formato A0 | E27: COP-MID | N27: A 12,5 X L 14 X P 0,5 | P27: 12.5 | Q27: 14 | R27: 0.5
A28: Embalagem | E28: COP-VID | N28: A 12,5 X L 14,5 X P0,5 | P28: 12.5 | Q28: 14.5 | R28: 0.5
A29: Fita VHS | E29: N/A | N29: A 130,0 X L 060,0 X P 72,0 | P29: 130 | Q29: 60 | R29: 72
A30: Item avulso | N30: A 130,0 X L 060,0 X P 73,0 | P30: 130 | Q30: 60 | R30: 73
A31: Item documental | N31: A 135,0 X L 51,0 X P 105,0 | P31: 135 | Q31: 51 | R31: 105
A32: Item documental em caixa | N32: A 140,0 X L 067,0 X P 72,0 | P32: 140 | Q32: 67 | R32: 72
A33: Item documental em mapoteca | N33: A 15,0 X L 40,0 X P 35,0 | P33: 15 | Q33: 40 | R33: 35
A34: Item documental em Tubo | N34: A 150,0 X L 090,0 X P 76,0 | P34: 150 | Q34: 90 | R34: 76
A35: Kit de material | N35: A 16,5 X L 11,5 X P 0,3 | P35: 16.5 | Q35: 11.5 | R35: 0.3
A36: Mapoteca | N36: A 17,0 X L 20,5 X P 111,5 | P36: 17 | Q36: 20.5 | R36: 111.5
A37: Microficha | N37: A 170,0 X L 061,0 X P 72,0 | P37: 170 | Q37: 61 | R37: 72
A38: Microfilme | N38: A 180,0 X L 068,0 X P 72,0 | P38: 180 | Q38: 68 | R38: 72
A39: Microfilme 16 mm | N39: A 21,0 X L 31,0 X P 46,0 | P39: 21 | Q39: 31 | R39: 46
A40: Microfilme 35 mm | N40: A 21,0 X L 41,0 X P 55,0 | P40: 21 | Q40: 41 | R40: 55
A41: Microforma em arquivo de aço | N41: A 21,5 X L 41,0 X P 51,0 | P41: 21.5 | Q41: 41 | R41: 51
...
