Workbook
Name ARMCXDOC: 'MC IMB SP'!$D$12
Name ARMCXMID: 'MC IMB SP'!$D$15
Name ARMMID: 'MC IMB SP'!$D$27
Name ARMTB: 'MC IMB SP'!$D$18
Name FDM: 'MC IMB SP'!$N$5

Sheet MC IMB SP
B2: P E T R O L E O B R A S I L E I R O S. A. P E T R O B R A S
B3: M E M Ó R I A D E C Á L C U L O D E M E D I Ç Ã O
B4: Razão Social: | D4: IRON MOUNTAIN DO BRASIL LTDA | I4: CNPJ: | J4: 04.120.966/0001-13 | L4: Item 1 PPU | M4: IAPEFARQ: | N4: =(21/22)*100 -> 95.454545
B5: Contrato SAP: | D5: 4600686987 | I5: Área contrato: | J5: Lote 1 | M5: FDM: | N5: 0.99
B6: Objeto: | D6: Serviços de Guarda e Gerenciamento de Documentos e Informações do Acervo da PETROBRAS | I6: Instr. contratual: | J6: 5900.0133210.25.2 | L6: Item 2 PPU | M6: IAPEFARQ: | N6: =(3/13)*100 -> 23.076923
I7: Período: | J7: 26/06/2026 à 25/07/2026 | M7: FDM: | N7: 0.97
C10: Item | D10: Descrição da atividade | I10: Unidade | J10: QExec | K10: QFinal | L10: Valor unitário | M10: Valor total a pagar | N10: Observações
C11: 1 | D11: Guarda de Documentos e Informações
D12: ARM-CX-DOC | E12: Armazenamento de caixas para documentos
C13: 1.1 | D13: QUAm-1 | E13: QBm | F13: QDm | G13: QNm | H13: QUAm | I13: UA | J13: =SUMIF(Consolidado!S:S,D12,Consolidado!O:O) -> 52663.624 | K13: =J13*N5 -> 52136.988 | L13: =IFERROR(VLOOKUP(D12,TabelaIRON[[Linha de Serviço PPU]:[PREÇO UNITÁRIO ]],3,FALSE),"N/A") -> 0.6 | M13: =J13*L13 -> 31598.174
D14: =SUMIF(ConsolidadoSP[Contrato], D12, ConsolidadoSP[QUAm-1]) -> 64179 | E14: =SUMIF(ConsolidadoSP[Contrato], D12, ConsolidadoSP[QBm]) -> 0 | F14: =SUMIF(ConsolidadoSP[Contrato], D12, ConsolidadoSP[QDm]) -> 0 | G14: =SUMIF(ConsolidadoSP[Contrato], D12, ConsolidadoSP[QNm] ) -> 316 | H14: =(D14-E14-F14)+G14 -> 64495
D15: ARM-CX-MID | E15: Armazenamento de caixas para mídias
C16: 1.2 | D16: QUAm-1 | E16: QBm | F16: QDm | G16: QNm | H16: QUAm | I16: UA | J16: =SUMIF(Consolidado!S:S,D15,Consolidado!O:O) -> 1870 | K16: =J16*N5 -> 1851.3 | L16: =IFERROR(VLOOKUP(D15,TabelaIRON[[Linha de Serviço PPU]:[PREÇO UNITÁRIO ]],3,FALSE),"N/A") -> 3.55 | M16: =J16*L16 -> 6638.5
D17: =SUMIF(ConsolidadoSP[Contrato], D15, ConsolidadoSP[QUAm-1]) -> 1870 | E17: =SUMIF(ConsolidadoSP[Contrato], D15, ConsolidadoSP[QBm]) -> 0 | F17: =SUMIF(ConsolidadoSP[Contrato], D15, ConsolidadoSP[QDm]) -> 0 | G17: =SUMIF(ConsolidadoSP[Contrato], D15, ConsolidadoSP[QNm] ) -> 0 | H17: =(D17-E17-F17)+G17 -> 1870
D18: ARM-TB | E18: Armazenamento de tubos
C19: 1.3 | D19: QUAm-1 | E19: QBm | F19: QDm | G19: QNm | H19: QUAm | I19: UA | J19: =SUMIF(Consolidado!S:S,D18,Consolidado!O:O) -> 4951 | K19: =J19*N5 -> 4901.49 | L19: =IFERROR(VLOOKUP(D18,TabelaIRON[[Linha de Serviço PPU]:[PREÇO UNITÁRIO ]],3,FALSE),"N/A") -> 0.74 | M19: =J19*L19 -> 3663.74
D20: =SUMIF(ConsolidadoSP[Contrato], D18, ConsolidadoSP[QUAm-1]) -> 4822 | E20: =SUMIF(ConsolidadoSP[Contrato], D18, ConsolidadoSP[QBm]) -> 0 | F20: =SUMIF(ConsolidadoSP[Contrato], D18, ConsolidadoSP[QDm]) -> 0 | G20: =SUMIF(ConsolidadoSP[Contrato], D18, ConsolidadoSP[QNm] ) -> 129 | H20: =(D20-E20-F20)+G20 -> 4951
D21: ARM-MA | E21: Armazenamento de mapotecas e arquivos de aço
C22: 1.4 | D22: QUAm-1 | E22: QBm | F22: QDm | G22: QNm | H22: QUAm | I22: UA | J22: =SUMIF(Consolidado!S:S,D21,Consolidado!O:O) -> 0 | K22: =J22*N5 -> 0 | L22: =IFERROR(VLOOKUP(D21,TabelaIRON[[Linha de Serviço PPU]:[PREÇO UNITÁRIO ]],3,FALSE),"N/A") -> 56.11 | M22: =J22*L22 -> 0
D23: =SUMIF(ConsolidadoSP[Contrato], D21, ConsolidadoSP[QUAm-1]) -> 0 | E23: =SUMIF(ConsolidadoSP[Contrato], D21, ConsolidadoSP[QBm]) -> 0 | F23: =SUMIF(ConsolidadoSP[Contrato], D21, ConsolidadoSP[QDm]) -> 0 | G23: =SUMIF(ConsolidadoSP[Contrato], D21, ConsolidadoSP[QNm] ) -> 0 | H23: =(D23-E23-F23)+G23 -> 0
D24: ARM-MIC | E24: Armazenamento de microformas
C25: 1.5 | D25: QUAm-1 | E25: QBm | F25: QDm | G25: QNm | H25: QUAm | I25: UA | J25: =SUMIF(Consolidado!S:S,D24,Consolidado!O:O) -> 0 | K25: =J25*N5 -> 0 | L25: =IFERROR(VLOOKUP(D24,TabelaIRON[[Linha de Serviço PPU]:[PREÇO UNITÁRIO ]],3,FALSE),"N/A") -> 0.08 | M25: =J25*L25 -> 0
D26: =SUMIF(ConsolidadoSP[Contrato], D24, ConsolidadoSP[QUAm-1]) -> 0 | E26: =SUMIF(ConsolidadoSP[Contrato], D24, ConsolidadoSP[QBm]) -> 0 | F26: =SUMIF(ConsolidadoSP[Contrato], D24, ConsolidadoSP[QDm]) -> 0 | G26: =SUMIF(ConsolidadoSP[Contrato], D24, ConsolidadoSP[QNm] ) -> 0 | H26: =(D26-E26-F26)+G26 -> 0
D27: ARM-MID | E27: Armazenamento de midias
C28: 1.6 | D28: QUAm-1 | E28: QBm | F28: QDm | G28: QNm | H28: QUAm | I28: UA | J28: =SUMIF(Consolidado!S:S,D27,Consolidado!O:O) -> 0 | K28: =J28*N5 -> 0 | L28: =IFERROR(VLOOKUP(D27,TabelaIRON[[Linha de Serviço PPU]:[PREÇO UNITÁRIO ]],3,FALSE),"N/A") -> 0.08 | M28: =J28*L28 -> 0
D29: =SUMIF(ConsolidadoSP[Contrato], D27, ConsolidadoSP[QUAm-1]) -> 0 | E29: =SUMIF(ConsolidadoSP[Contrato], D27, ConsolidadoSP[QBm]) -> 0 | F29: =SUMIF(ConsolidadoSP[Contrato], D27, ConsolidadoSP[QDm]) -> 0 | G29: =SUMIF(ConsolidadoSP[Contrato], D27, ConsolidadoSP[QNm] ) -> 0 | H29: =(D29-E29-F29)+G29 -> 0
C30: 1.7 | D30: FRE-NRM | E30: Frete normal | I30: Frete | J30: 10 | K30: 10 | L30: =IFERROR(VLOOKUP(D30,TabelaIRON[[Linha de Serviço PPU]:[PREÇO UNITÁRIO ]],3,FALSE),"N/A") -> 125.89 | M30: =J30*L30 -> 1258.9
C31: 1.8 | D31: FRE-EXP | E31: Frete expresso | I31: Frete | J31: 1 | K31: 1 | L31: =IFERROR(VLOOKUP(D31,TabelaIRON[[Linha de Serviço PPU]:[PREÇO UNITÁRIO ]],3,FALSE),"N/A") -> 200 | M31: =J31*L31 -> 200
C32: 1.9 | D32: KM-AD | E32: Quilometragem adicional | I32: KM | J32: 250 | K32: 250 | L32: =IFERROR(VLOOKUP(D32,TabelaIRON[[Linha de Serviço PPU]:[PREÇO UNITÁRIO ]],3,FALSE),"N/A") -> 0.5 | M32: =J32*L32 -> 125
C33: 1.10 | D33: PES-ITEM | E33: Pesquisa de itens avulsos | I33: Item Avulso | J33: 30 | K33: 30 | L33: =IFERROR(VLOOKUP(D33,TabelaIRON[[Linha de Serviço PPU]:[PREÇO UNITÁRIO ]],3,FALSE),"N/A") -> 1.96 | M33: =J33*L33 -> 58.8
C34: 1.11 | D34: DES-EMB | E34: Destruição segura de documentos | I34: Item Avulso | J34: 0 | K34: 0 | L34: =IFERROR(VLOOKUP(D34,TabelaIRON[[Linha de Serviço PPU]:[PREÇO UNITÁRIO ]],3,FALSE),"N/A") -> 1.35 | M34: =J34*L34 -> 0
C35: 1.12 | D35: TRANSF | E35: Transferência inicial de acervo documental | I35: Transferência | J35: 0 | K35: 0 | L35: =IFERROR(VLOOKUP(D35,TabelaIRON[[Linha de Serviço PPU]:[PREÇO UNITÁRIO ]],3,FALSE),"N/A") -> 594488.34 | M35: =J35*L35 -> 0
C36: 1.13 | D36: MIGR-UA | E36: Migração de acervo documental para digitalização | I36: UA | J36: 0 | K36: 0 | L36: =IFERROR(VLOOKUP(D36,TabelaIRON[[Linha de Serviço PPU]:[PREÇO UNITÁRIO ]],3,FALSE),"N/A") -> 1.01 | M36: =J36*L36 -> 0
C37: 2 | D37: Gerenciamento de Documentos e Informações
C38: 2.1 | D38: CAT-ITEM | E38: Catalogação de documentos digitalizados | I38: Documento | J38: 28 | K38: 28 | L38: =IFERROR(VLOOKUP(D38,TabelaIRON[[Linha de Serviço PPU]:[PREÇO UNITÁRIO ]],3,FALSE),"N/A") -> 0.44 | M38: =J38*L38 -> 12.32
C39: 2.2 | D39: ORG-DOC | E39: Organização de documentos para digitalização | I39: UA | J39: 0 | K39: 0 | L39: =IFERROR(VLOOKUP(D39,TabelaIRON[[Linha de Serviço PPU]:[PREÇO UNITÁRIO ]],3,FALSE),"N/A") -> 1.44 | M39: =J39*L39 -> 0
C40: 2.3 | D40: DIG-MI | E40: Digitalização de microfilmes | I40: UD | J40: 0 | K40: 0 | L40: =IFERROR(VLOOKUP(D40,TabelaIRON[[Linha de Serviço PPU]:[PREÇO UNITÁRIO ]],3,FALSE),"N/A") -> 0.05 | M40: =J40*L40 -> 0
C41: 2.4 | D41: DIG-MF | E41: Digitalização de microfichas | I41: UD | J41: 0 | K41: 0 | L41: =IFERROR(VLOOKUP(D41,TabelaIRON[[Linha de Serviço PPU]:[PREÇO UNITÁRIO ]],3,FALSE),"N/A") -> 0.06 | M41: =J41*L41 -> 0
C42: 2.5 | D42: DIG-DOC | E42: Digitalização de documentos | I42: UD | J42: 1858.5 | K42: 1858.5 | L42: =IFERROR(VLOOKUP(D42,TabelaIRON[[Linha de Serviço PPU]:[PREÇO UNITÁRIO ]],3,FALSE),"N/A") -> 0.1 | M42: =J42*L42 -> 185.85
C43: 2.6 | D43: IND-DOC | E43: Indexação de documentos | I43: UD | J43: 28 | K43: 28 | L43: =IFERROR(VLOOKUP(D43,TabelaIRON[[Linha de Serviço PPU]:[PREÇO UNITÁRIO ]],3,FALSE),"N/A") -> 0.23 | M43: =J43*L43 -> 6.44
...

Sheet Consolidado
A1: Consolidado SP | J1: mês anterior | K1: Saída/mês | L1: Exp./Mês | M1: Novas/mês | N1: QUAm = QUAm-1 + QNm - QBm - QDm
C2: Formula | D2: Formula | E2: Formula | F2: Formula | G2: Formula | H2: Formula | J2: Editar | K2: Editar | L2: Editar | M2: Editar | N2: Formula | O2: Formula | P2: Formula | Q2: Formula
A3: MEDIDAS CONTRATO | B3: Padrão | C3: Ø | D3: A | E3: L | F3: P | G3: cm³ = V1 | H3: cm³ = V2 | I3: FC = V1/V2 | J3: QUAm-1 | K3: QBm | L3: QDm | M3: QNm | N3: QUAm | O3: UA | P3: $ Unitário | Q3: $ Total | R3: Tabela | S3: Contrato
A4: A 25,0 X L 14,0 X P 37,0 | B4: Caixa 5 kg | C4: =IFERROR( VLOOKUP(ConsolidadoSP[[#This Row],[MEDIDAS CONTRATO]],MedidasContrato[[MEDIDAS CONTRATO]:[Ø]],2,0),"") -> 0 | D4: =IFERROR( VLOOKUP(ConsolidadoSP[[#This Row],[MEDIDAS CONTRATO]],MedidasContrato[],3,0),"") -> 25 | E4: =IFERROR( VLOOKUP(ConsolidadoSP[[#This Row],[MEDIDAS CONTRATO]],MedidasContrato[],4,0),"") -> 14 | F4: =IFERROR( VLOOKUP(ConsolidadoSP[[#This Row],[MEDIDAS CONTRATO]],MedidasContrato[],5,0),"") -> 37 | G4: =Consolidado!$D4*Consolidado!$E4*Consolidado!$F4 -> 12950 | H4: =G4/I4 -> 44047.619 | I4: 0.294 | J4: 0 | K4: 0 | L4: 0 | M4: 0 | N4: =IF( ConsolidadoSP[[#This Row],[QUAm-1]] = "", "", ConsolidadoSP[[#This Row],[QUAm-1]] +ConsolidadoSP[[#This Row],[QNm]] -ConsolidadoSP[[#This Row],[QBm]] -ConsolidadoSP[[#This Row],[QDm]]) -> 0 | O4: =IF( ConsolidadoSP[[#This Row],[FC = V1/V2]] = "", "", ConsolidadoSP[[#This Row],[FC = V1/V2]] * ConsolidadoSP[[#This Row],[QUAm]]) -> 0 | P4: =IF( ConsolidadoSP[[#This Row],[Contrato]] = "", "", IFERROR( VLOOKUP(ConsolidadoSP[[#This Row],[Contrato]],TabelaIRON[[Linha de Serviço PPU]:[PREÇO UNITÁRIO ]],3,0),"Nao Encontrado")) -> 0.6 | Q4: =IF(ConsolidadoSP[[#This Row],[FC = V1/V2]]="","", ConsolidadoSP[[#This Row],[UA]] * ConsolidadoSP[[#This Row],[$ Unitário]]) -> 0 | R4: FC1 | S4: ARM-CX-DOC
A5: A 29,0 X L 18,0 X P 41,0 | B5: Caixa 7 kg | C5: =IFERROR( VLOOKUP(ConsolidadoSP[[#This Row],[MEDIDAS CONTRATO]],MedidasContrato[[MEDIDAS CONTRATO]:[Ø]],2,0),"") -> 0 | D5: =IFERROR( VLOOKUP(ConsolidadoSP[[#This Row],[MEDIDAS CONTRATO]],MedidasContrato[],3,0),"") -> 29 | E5: =IFERROR( VLOOKUP(ConsolidadoSP[[#This Row],[MEDIDAS CONTRATO]],MedidasContrato[],4,0),"") -> 18 | F5: =IFERROR( VLOOKUP(ConsolidadoSP[[#This Row],[MEDIDAS CONTRATO]],MedidasContrato[],5,0),"") -> 41 | G5: =Consolidado!$D5*Consolidado!$E5*Consolidado!$F5 -> 21402 | H5: =G5/I5 -> 44037.037 | I5: 0.486 | J5: 17224 | K5: 0 | L5: 0 | M5: 95 | N5: =IF( ConsolidadoSP[[#This Row],[QUAm-1]] = "", "", ConsolidadoSP[[#This Row],[QUAm-1]] +ConsolidadoSP[[#This Row],[QNm]] -ConsolidadoSP[[#This Row],[QBm]] -ConsolidadoSP[[#This Row],[QDm]]) -> 17319 | O5: =IF( ConsolidadoSP[[#This Row],[FC = V1/V2]] = "", "", ConsolidadoSP[[#This Row],[FC = V1/V2]] * ConsolidadoSP[[#This Row],[QUAm]]) -> 8417.034 | P5: =IF( ConsolidadoSP[[#This Row],[Contrato]] = "", "", IFERROR( VLOOKUP(ConsolidadoSP[[#This Row],[Contrato]],TabelaIRON[[Linha de Serviço PPU]:[PREÇO UNITÁRIO ]],3,0),"Nao Encontrado")) -> 0.6 | Q5: =IF(ConsolidadoSP[[#This Row],[FC = V1/V2]]="","", ConsolidadoSP[[#This Row],[UA]] * ConsolidadoSP[[#This Row],[$ Unitário]]) -> 5050.2204 | R5: FC1 | S5: ARM-CX-DOC
A6: A 30,0 X L 19,0 X P 39,0 | B6: Caixa 10 kg (Jumbo) | C6: =IFERROR( VLOOKUP(ConsolidadoSP[[#This Row],[MEDIDAS CONTRATO]],MedidasContrato[[MEDIDAS CONTRATO]:[Ø]],2,0),"") -> 0 | D6: =IFERROR( VLOOKUP(ConsolidadoSP[[#This Row],[MEDIDAS CONTRATO]],MedidasContrato[],3,0),"") -> 30 | E6: =IFERROR( VLOOKUP(ConsolidadoSP[[#This Row],[MEDIDAS CONTRATO]],MedidasContrato[],4,0),"") -> 19 | F6: =IFERROR( VLOOKUP(ConsolidadoSP[[#This Row],[MEDIDAS CONTRATO]],MedidasContrato[],5,0),"") -> 39 | G6: =Consolidado!$D6*Consolidado!$E6*Consolidado!$F6 -> 22230 | H6: =G6/I6 -> 44019.802 | I6: 0.505 | J6: 5883 | K6: 0 | L6: 0 | M6: 35 | N6: =IF( ConsolidadoSP[[#This Row],[QUAm-1]] = "", "", ConsolidadoSP[[#This Row],[QUAm-1]] +ConsolidadoSP[[#This Row],[QNm]] -ConsolidadoSP[[#This Row],[QBm]] -ConsolidadoSP[[#This Row],[QDm]]) -> 5918 | O6: =IF( ConsolidadoSP[[#This Row],[FC = V1/V2]] = "", "", ConsolidadoSP[[#This Row],[FC = V1/V2]] * ConsolidadoSP[[#This Row],[QUAm]]) -> 2988.59 | P6: =IF( ConsolidadoSP[[#This Row],[Contrato]] = "", "", IFERROR( VLOOKUP(ConsolidadoSP[[#This Row],[Contrato]],TabelaIRON[[Linha de Serviço PPU]:[PREÇO UNITÁRIO ]],3,0),"Nao Encontrado")) -> 0.6 | Q6: =IF(ConsolidadoSP[[#This Row],[FC = V1/V2]]="","", ConsolidadoSP[[#This Row],[UA]] * ConsolidadoSP[[#This Row],[$ Unitário]]) -> 1793.154 | R6: FC1 | S6: ARM-CX-DOC
A7: A 29 X L 41 X P 37 | B7: Caixa 20 kg - Tipo 1 | C7: =IFERROR( VLOOKUP(ConsolidadoSP[[#This Row],[MEDIDAS CONTRATO]],MedidasContrato[[MEDIDAS CONTRATO]:[Ø]],2,0),"") -> 0 | D7: =IFERROR( VLOOKUP(ConsolidadoSP[[#This Row],[MEDIDAS CONTRATO]],MedidasContrato[],3,0),"") -> 29 | E7: =IFERROR( VLOOKUP(ConsolidadoSP[[#This Row],[MEDIDAS CONTRATO]],MedidasContrato[],4,0),"") -> 41 | F7: =IFERROR( VLOOKUP(ConsolidadoSP[[#This Row],[MEDIDAS CONTRATO]],MedidasContrato[],5,0),"") -> 37 | G7: =Consolidado!$D7*Consolidado!$E7*Consolidado!$F7 -> 43993 | H7: =G7/I7 -> 43993 | I7: 1 | J7: 41072 | K7: 0 | L7: 0 | M7: 186 | N7: =IF( ConsolidadoSP[[#This Row],[QUAm-1]] = "", "", ConsolidadoSP[[#This Row],[QUAm-1]] +ConsolidadoSP[[#This Row],[QNm]] -ConsolidadoSP[[#This Row],[QBm]] -ConsolidadoSP[[#This Row],[QDm]]) -> 41258 | O7: =IF( ConsolidadoSP[[#This Row],[FC = V1/V2]] = "", "", ConsolidadoSP[[#This Row],[FC = V1/V2]] * ConsolidadoSP[[#This Row],[QUAm]]) -> 41258 | P7: =IF( ConsolidadoSP[[#This Row],[Contrato]] = "", "", IFERROR( VLOOKUP(ConsolidadoSP[[#This Row],[Contrato]],TabelaIRON[[Linha de Serviço PPU]:[PREÇO UNITÁRIO ]],3,0),"Nao Encontrado")) -> 0.6 | Q7: =IF(ConsolidadoSP[[#This Row],[FC = V1/V2]]="","", ConsolidadoSP[[#This Row],[UA]] * ConsolidadoSP[[#This Row],[$ Unitário]]) -> 24754.8 | R7: FC1 | S7: ARM-CX-DOC
A8: A 29 X L 40 X P 50 | B8: Caixa 20 kg - Tipo 2 | C8: =IFERROR( VLOOKUP(ConsolidadoSP[[#This Row],[MEDIDAS CONTRATO]],MedidasContrato[[MEDIDAS CONTRATO]:[Ø]],2,0),"") -> 0 | D8: =IFERROR( VLOOKUP(ConsolidadoSP[[#This Row],[MEDIDAS CONTRATO]],MedidasContrato[],3,0),"") -> 29 | E8: =IFERROR( VLOOKUP(ConsolidadoSP[[#This Row],[MEDIDAS CONTRATO]],MedidasContrato[],4,0),"") -> 40 | F8: =IFERROR( VLOOKUP(ConsolidadoSP[[#This Row],[MEDIDAS CONTRATO]],MedidasContrato[],5,0),"") -> 50 | G8: =Consolidado!$D8*Consolidado!$E8*Consolidado!$F8 -> 58000 | H8: =G8/I8 -> 44006.07 | I8: 1.318 | J8: 0 | K8: 0 | L8: 0 | M8: 0 | N8: =IF( ConsolidadoSP[[#This Row],[QUAm-1]] = "", "", ConsolidadoSP[[#This Row],[QUAm-1]] +ConsolidadoSP[[#This Row],[QNm]] -ConsolidadoSP[[#This Row],[QBm]] -ConsolidadoSP[[#This Row],[QDm]]) -> 0 | O8: =IF( ConsolidadoSP[[#This Row],[FC = V1/V2]] = "", "", ConsolidadoSP[[#This Row],[FC = V1/V2]] * ConsolidadoSP[[#This Row],[QUAm]]) -> 0 | P8: =IF( ConsolidadoSP[[#This Row],[Contrato]] = "", "", IFERROR( VLOOKUP(ConsolidadoSP[[#This Row],[Contrato]],TabelaIRON[[Linha de Serviço PPU]:[PREÇO UNITÁRIO ]],3,0),"Nao Encontrado")) -> 0.6 | Q8: =IF(ConsolidadoSP[[#This Row],[FC = V1/V2]]="","", ConsolidadoSP[[#This Row],[UA]] * ConsolidadoSP[[#This Row],[$ Unitário]]) -> 0 | R8: FC1 | S8: ARM-CX-DOC
A9: A 29 X L 41 X P 37 | B9: Caixa 20 kg (contendo Mídias e Microfilmes) | C9: =IFERROR( VLOOKUP(ConsolidadoSP[[#This Row],[MEDIDAS CONTRATO]],MedidasContrato[[MEDIDAS CONTRATO]:[Ø]],2,0),"") -> 0 | D9: =IFERROR( VLOOKUP(ConsolidadoSP[[#This Row],[MEDIDAS CONTRATO]],MedidasContrato[],3,0),"") -> 29 | E9: =IFERROR( VLOOKUP(ConsolidadoSP[[#This Row],[MEDIDAS CONTRATO]],MedidasContrato[],4,0),"") -> 41 | F9: =IFERROR( VLOOKUP(ConsolidadoSP[[#This Row],[MEDIDAS CONTRATO]],MedidasContrato[],5,0),"") -> 37 | G9: =Consolidado!$D9*Consolidado!$E9*Consolidado!$F9 -> 43993 | H9: =G9/I9 -> 43993 | I9: 1 | J9: 0 | K9: 0 | L9: 0 | M9: 0 | N9: =IF( ConsolidadoSP[[#This Row],[QUAm-1]] = "", "", ConsolidadoSP[[#This Row],[QUAm-1]] +ConsolidadoSP[[#This Row],[QNm]] -ConsolidadoSP[[#This Row],[QBm]] -ConsolidadoSP[[#This Row],[QDm]]) -> 0 | O9: =IF( ConsolidadoSP[[#This Row],[FC = V1/V2]] = "", "", ConsolidadoSP[[#This Row],[FC = V1/V2]] * ConsolidadoSP[[#This Row],[QUAm]]) -> 0 | P9: =IF( ConsolidadoSP[[#This Row],[Contrato]] = "", "", IFERROR( VLOOKUP(ConsolidadoSP[[#This Row],[Contrato]],TabelaIRON[[Linha de Serviço PPU]:[PREÇO UNITÁRIO ]],3,0),"Nao Encontrado")) -> 3.55 | Q9: =IF(ConsolidadoSP[[#This Row],[FC = V1/V2]]="","", ConsolidadoSP[[#This Row],[UA]] * ConsolidadoSP[[#This Row],[$ Unitário]]) -> 0 | R9: FC2 | S9: ARM-CX-MID
A10: Ø10,0 P 120,0 | B10: Tubo de Engenharia | C10: =IFERROR( VLOOKUP(ConsolidadoSP[[#This Row],[MEDIDAS CONTRATO]],MedidasContrato[[MEDIDAS CONTRATO]:[Ø]],2,0),"") -> 10 | D10: =IFERROR( VLOOKUP(ConsolidadoSP[[#This Row],[MEDIDAS CONTRATO]],MedidasContrato[],3,0),"") -> 0 | E10: =IFERROR( VLOOKUP(ConsolidadoSP[[#This Row],[MEDIDAS CONTRATO]],MedidasContrato[],4,0),"") -> 0 | F10: =IFERROR( VLOOKUP(ConsolidadoSP[[#This Row],[MEDIDAS CONTRATO]],MedidasContrato[],5,0),"") -> 120 | G10: =(((Consolidado!$C10/2)^2*PI())*Consolidado!$F10) -> 9424.778 | H10: =G10/I10 -> 9424.778 | I10: 1 | J10: 4822 | K10: 0 | L10: 0 | M10: 129 | N10: =IF( ConsolidadoSP[[#This Row],[QUAm-1]] = "", "", ConsolidadoSP[[#This Row],[QUAm-1]] +ConsolidadoSP[[#This Row],[QNm]] -ConsolidadoSP[[#This Row],[QBm]] -ConsolidadoSP[[#This Row],[QDm]]) -> 4951 | O10: =IF( ConsolidadoSP[[#This Row],[FC = V1/V2]] = "", "", ConsolidadoSP[[#This Row],[FC = V1/V2]] * ConsolidadoSP[[#This Row],[QUAm]]) -> 4951 | P10: =IF( ConsolidadoSP[[#This Row],[Contrato]] = "", "", IFERROR( VLOOKUP(ConsolidadoSP[[#This Row],[Contrato]],TabelaIRON[[Linha de Serviço PPU]:[PREÇO UNITÁRIO ]],3,0),"Nao Encontrado")) -> 0.74 | Q10: =IF(ConsolidadoSP[[#This Row],[FC = V1/V2]]="","", ConsolidadoSP[[#This Row],[UA]] * ConsolidadoSP[[#This Row],[$ Unitário]]) -> 3663.74 | R10: FC3 | S10: ARM-TB
A11: A 34,0 X L 37,0 X P 12,0 | B11: Caixa para mídias - Tipo 1 | C11: =IFERROR( VLOOKUP(ConsolidadoSP[[#This Row],[MEDIDAS CONTRATO]],MedidasContrato[[MEDIDAS CONTRATO]:[Ø]],2,0),"") -> 0 | D11: =IFERROR( VLOOKUP(ConsolidadoSP[[#This Row],[MEDIDAS CONTRATO]],MedidasContrato[],3,0),"") -> 34 | E11: =IFERROR( VLOOKUP(ConsolidadoSP[[#This Row],[MEDIDAS CONTRATO]],MedidasContrato[],4,0),"") -> 37 | F11: =IFERROR( VLOOKUP(ConsolidadoSP[[#This Row],[MEDIDAS CONTRATO]],MedidasContrato[],5,0),"") -> 12 | G11: =Consolidado!$D11*Consolidado!$E11*Consolidado!$F11 -> 15096 | H11: =G11/I11 -> 15096 | I11: 1 | J11: 1870 | K11: 0 | L11: 0 | M11: 0 | N11: =IF( ConsolidadoSP[[#This Row],[QUAm-1]] = "", "", ConsolidadoSP[[#This Row],[QUAm-1]] +ConsolidadoSP[[#This Row],[QNm]] -ConsolidadoSP[[#This Row],[QBm]] -ConsolidadoSP[[#This Row],[QDm]]) -> 1870 | O11: =IF( ConsolidadoSP[[#This Row],[FC = V1/V2]] = "", "", ConsolidadoSP[[#This Row],[FC = V1/V2]] * ConsolidadoSP[[#This Row],[QUAm]]) -> 1870 | P11: =IF( ConsolidadoSP[[#This Row],[Contrato]] = "", "", IFERROR( VLOOKUP(ConsolidadoSP[[#This Row],[Contrato]],TabelaIRON[[Linha de Serviço PPU]:[PREÇO UNITÁRIO ]],3,0),"Nao Encontrado")) -> 3.55 | Q11: =IF(ConsolidadoSP[[#This Row],[FC = V1/V2]]="","", ConsolidadoSP[[#This Row],[UA]] * ConsolidadoSP[[#This Row],[$ Unitário]]) -> 6638.5 | R11: FC2 | S11: ARM-CX-MID
A12: A 10,0 X L 10,0 X P 2,5 | B12: Microfilme | C12: =IFERROR( VLOOKUP(ConsolidadoSP[[#This Row],[MEDIDAS CONTRATO]],MedidasContrato[[MEDIDAS CONTRATO]:[Ø]],2,0),"") -> 0 | D12: =IFERROR( VLOOKUP(ConsolidadoSP[[#This Row],[MEDIDAS CONTRATO]],MedidasContrato[],3,0),"") -> 10 | E12: =IFERROR( VLOOKUP(ConsolidadoSP[[#This Row],[MEDIDAS CONTRATO]],MedidasContrato[],4,0),"") -> 10 | F12: =IFERROR( VLOOKUP(ConsolidadoSP[[#This Row],[MEDIDAS CONTRATO]],MedidasContrato[],5,0),"") -> 2.5 | G12: =Consolidado!$D12*Consolidado!$E12*Consolidado!$F12 -> 250 | H12: =G12/I12 -> 250 | I12: 1 | J12: 0 | K12: 0 | L12: 0 | M12: 0 | N12: =IF( ConsolidadoSP[[#This Row],[QUAm-1]] = "", "", ConsolidadoSP[[#This Row],[QUAm-1]] +ConsolidadoSP[[#This Row],[QNm]] -ConsolidadoSP[[#This Row],[QBm]] -ConsolidadoSP[[#This Row],[QDm]]) -> 0 | O12: =IF( ConsolidadoSP[[#This Row],[FC = V1/V2]] = "", "", ConsolidadoSP[[#This Row],[FC = V1/V2]] * ConsolidadoSP[[#This Row],[QUAm]]) -> 0 | P12: =IF( ConsolidadoSP[[#This Row],[Contrato]] = "", "", IFERROR( VLOOKUP(ConsolidadoSP[[#This Row],[Contrato]],TabelaIRON[[Linha de Serviço PPU]:[PREÇO UNITÁRIO ]],3,0),"Nao Encontrado")) -> 0.08 | Q12: =IF(ConsolidadoSP[[#This Row],[FC = V1/V2]]="","", ConsolidadoSP[[#This Row],[UA]] * ConsolidadoSP[[#This Row],[$ Unitário]]) -> 0 | R12: FC5 | S12: ARM-MIC
A13: A 11,0 X L 15,5 X P 0,3 | B13: Microficha | C13: =IFERROR( VLOOKUP(ConsolidadoSP[[#This Row],[MEDIDAS CONTRATO]],MedidasContrato[[MEDIDAS CONTRATO]:[Ø]],2,0),"") -> 0 | D13: =IFERROR( VLOOKUP(ConsolidadoSP[[#This Row],[MEDIDAS CONTRATO]],MedidasContrato[],3,0),"") -> 11 | E13: =IFERROR( VLOOKUP(ConsolidadoSP[[#This Row],[MEDIDAS CONTRATO]],MedidasContrato[],4,0),"") -> 15.5 | F13: =IFERROR( VLOOKUP(ConsolidadoSP[[#This Row],[MEDIDAS CONTRATO]],MedidasContrato[],5,0),"") -> 0.3 | G13: =Consolidado!$D13*Consolidado!$E13*Consolidado!$F13 -> 51.15 | H13: =G13/I13 -> 275 | I13: 0.186 | J13: 0 | K13: 0 | L13: 0 | M13: 0 | N13: =IF( ConsolidadoSP[[#This Row],[QUAm-1]] = "", "", ConsolidadoSP[[#This Row],[QUAm-1]] +ConsolidadoSP[[#This Row],[QNm]] -ConsolidadoSP[[#This Row],[QBm]] -ConsolidadoSP[[#This Row],[QDm]]) -> 0 | O13: =IF( ConsolidadoSP[[#This Row],[FC = V1/V2]] = "", "", ConsolidadoSP[[#This Row],[FC = V1/V2]] * ConsolidadoSP[[#This Row],[QUAm]]) -> 0 | P13: =IF( ConsolidadoSP[[#This Row],[Contrato]] = "", "", IFERROR( VLOOKUP(ConsolidadoSP[[#This Row],[Contrato]],TabelaIRON[[Linha de Serviço PPU]:[PREÇO UNITÁRIO ]],3,0),"Nao Encontrado")) -> 0.08 | Q13: =IF(ConsolidadoSP[[#This Row],[FC = V1/V2]]="","", ConsolidadoSP[[#This Row],[UA]] * ConsolidadoSP[[#This Row],[$ Unitário]]) -> 0 | R13: FC5 | S13: ARM-MIC
A14: A 12,5 X L 14 X P 0,5 | B14: Mídia óptica | C14: =IFERROR( VLOOKUP(ConsolidadoSP[[#This Row],[MEDIDAS CONTRATO]],MedidasContrato[[MEDIDAS CONTRATO]:[Ø]],2,0),"") -> 0 | D14: =IFERROR( VLOOKUP(ConsolidadoSP[[#This Row],[MEDIDAS CONTRATO]],MedidasContrato[],3,0),"") -> 12.5 | E14: =IFERROR( VLOOKUP(ConsolidadoSP[[#This Row],[MEDIDAS CONTRATO]],MedidasContrato[],4,0),"") -> 14 | F14: =IFERROR( VLOOKUP(ConsolidadoSP[[#This Row],[MEDIDAS CONTRATO]],MedidasContrato[],5,0),"") -> 0.5 | G14: =Consolidado!$D14*Consolidado!$E14*Consolidado!$F14 -> 87.5 | H14: =G14/I14 -> 87.5 | I14: 1 | J14: 0 | K14: 0 | L14: 0 | M14: 0 | N14: =IF( ConsolidadoSP[[#This Row],[QUAm-1]] = "", "", ConsolidadoSP[[#This Row],[QUAm-1]] +ConsolidadoSP[[#This Row],[QNm]] -ConsolidadoSP[[#This Row],[QBm]] -ConsolidadoSP[[#This Row],[QDm]]) -> 0 | O14: =IF( ConsolidadoSP[[#This Row],[FC = V1/V2]] = "", "", ConsolidadoSP[[#This Row],[FC = V1/V2]] * ConsolidadoSP[[#This Row],[QUAm]]) -> 0 | P14: =IF( ConsolidadoSP[[#This Row],[Contrato]] = "", "", IFERROR( VLOOKUP(ConsolidadoSP[[#This Row],[Contrato]],TabelaIRON[[Linha de Serviço PPU]:[PREÇO UNITÁRIO ]],3,0),"Nao Encontrado")) -> 0.08 | Q14: =IF(ConsolidadoSP[[#This Row],[FC = V1/V2]]="","", ConsolidadoSP[[#This Row],[UA]] * ConsolidadoSP[[#This Row],[$ Unitário]]) -> 0 | R14: FC6 | S14: ARM-MID
A15: A 10,0 X L 10,0 X P 2,5 | B15: Microfilme | C15: =IFERROR( VLOOKUP(ConsolidadoSP[[#This Row],[MEDIDAS CONTRATO]],MedidasContrato[[MEDIDAS CONTRATO]:[Ø]],2,0),"") -> 0 | D15: =IFERROR( VLOOKUP(ConsolidadoSP[[#This Row],[MEDIDAS CONTRATO]],MedidasContrato[],3,0),"") -> 10 | E15: =IFERROR( VLOOKUP(ConsolidadoSP[[#This Row],[MEDIDAS CONTRATO]],MedidasContrato[],4,0),"") -> 10 | F15: =IFERROR( VLOOKUP(ConsolidadoSP[[#This Row],[MEDIDAS CONTRATO]],MedidasContrato[],5,0),"") -> 2.5 | G15: =Consolidado!$D15*Consolidado!$E15*Consolidado!$F15 -> 250 | H15: =G15/I15 -> 250 | I15: 1 | J15: 0 | K15: 0 | L15: 0 | M15: 0 | N15: =IF( ConsolidadoSP[[#This Row],[QUAm-1]] = "", "", ConsolidadoSP[[#This Row],[QUAm-1]] +ConsolidadoSP[[#This Row],[QNm]] -ConsolidadoSP[[#This Row],[QBm]] -ConsolidadoSP[[#This Row],[QDm]]) -> 0 | O15: =IF( ConsolidadoSP[[#This Row],[FC = V1/V2]] = "", "", ConsolidadoSP[[#This Row],[FC = V1/V2]] * ConsolidadoSP[[#This Row],[QUAm]]) -> 0 | P15: =IF( ConsolidadoSP[[#This Row],[Contrato]] = "", "", IFERROR( VLOOKUP(ConsolidadoSP[[#This Row],[Contrato]],TabelaIRON[[Linha de Serviço PPU]:[PREÇO UNITÁRIO ]],3,0),"Nao Encontrado")) -> 0.08 | Q15: =IF(ConsolidadoSP[[#This Row],[FC = V1/V2]]="","", ConsolidadoSP[[#This Row],[UA]] * ConsolidadoSP[[#This Row],[$ Unitário]]) -> 0 | R15: FC5 | S15: ARM-MIC
A16: A 11,0 X L 15,5 X P 0,3 | B16: Microficha | C16: =IFERROR( VLOOKUP(ConsolidadoSP[[#This Row],[MEDIDAS CONTRATO]],MedidasContrato[[MEDIDAS CONTRATO]:[Ø]],2,0),"") -> 0 | D16: =IFERROR( VLOOKUP(ConsolidadoSP[[#This Row],[MEDIDAS CONTRATO]],MedidasContrato[],3,0),"") -> 11 | E16: =IFERROR( VLOOKUP(ConsolidadoSP[[#This Row],[MEDIDAS CONTRATO]],MedidasContrato[],4,0),"") -> 15.5 | F16: =IFERROR( VLOOKUP(ConsolidadoSP[[#This Row],[MEDIDAS CONTRATO]],MedidasContrato[],5,0),"") -> 0.3 | G16: =Consolidado!$D16*Consolidado!$E16*Consolidado!$F16 -> 51.15 | H16: =G16/I16 -> 275 | I16: 0.186 | J16: 0 | K16: 0 | L16: 0 | M16: 0 | N16: =IF( ConsolidadoSP[[#This Row],[QUAm-1]] = "", "", ConsolidadoSP[[#This Row],[QUAm-1]] +ConsolidadoSP[[#This Row],[QNm]] -ConsolidadoSP[[#This Row],[QBm]] -ConsolidadoSP[[#This Row],[QDm]]) -> 0 | O16: =IF( ConsolidadoSP[[#This Row],[FC = V1/V2]] = "", "", ConsolidadoSP[[#This Row],[FC = V1/V2]] * ConsolidadoSP[[#This Row],[QUAm]]) -> 0 | P16: =IF( ConsolidadoSP[[#This Row],[Contrato]] = "", "", IFERROR( VLOOKUP(ConsolidadoSP[[#This Row],[Contrato]],TabelaIRON[[Linha de Serviço PPU]:[PREÇO UNITÁRIO ]],3,0),"Nao Encontrado")) -> 0.08 | Q16: =IF(ConsolidadoSP[[#This Row],[FC = V1/V2]]="","", ConsolidadoSP[[#This Row],[UA]] * ConsolidadoSP[[#This Row],[$ Unitário]]) -> 0 | R16: FC5 | S16: ARM-MIC
C17: =IFERROR( VLOOKUP(ConsolidadoSP[[#This Row],[MEDIDAS CONTRATO]],MedidasContrato[[MEDIDAS CONTRATO]:[Ø]],2,0),"") | D17: =IFERROR( VLOOKUP(ConsolidadoSP[[#This Row],[MEDIDAS CONTRATO]],MedidasContrato[],3,0),"") | E17: =IFERROR( VLOOKUP(ConsolidadoSP[[#This Row],[MEDIDAS CONTRATO]],MedidasContrato[],4,0),"") | F17: =IFERROR( VLOOKUP(ConsolidadoSP[[#This Row],[MEDIDAS CONTRATO]],MedidasContrato[],5,0),"") | N17: =IF( ConsolidadoSP[[#This Row],[QUAm-1]] = "", "", ConsolidadoSP[[#This Row],[QUAm-1]] +ConsolidadoSP[[#This Row],[QNm]] -ConsolidadoSP[[#This Row],[QBm]] -ConsolidadoSP[[#This Row],[QDm]]) | O17: =IF( ConsolidadoSP[[#This Row],[FC = V1/V2]] = "", "", ConsolidadoSP[[#This Row],[FC = V1/V2]] * ConsolidadoSP[[#This Row],[QUAm]]) | P17: =IF( ConsolidadoSP[[#This Row],[Contrato]] = "", "", IFERROR( VLOOKUP(ConsolidadoSP[[#This Row],[Contrato]],TabelaIRON[[Linha de Serviço PPU]:[PREÇO UNITÁRIO ]],3,0),"Nao Encontrado")) | Q17: =IF(ConsolidadoSP[[#This Row],[FC = V1/V2]]="","", ConsolidadoSP[[#This Row],[UA]] * ConsolidadoSP[[#This Row],[$ Unitário]])
C18: =IFERROR( VLOOKUP(ConsolidadoSP[[#This Row],[MEDIDAS CONTRATO]],MedidasContrato[[MEDIDAS CONTRATO]:[Ø]],2,0),"") | D18: =IFERROR( VLOOKUP(ConsolidadoSP[[#This Row],[MEDIDAS CONTRATO]],MedidasContrato[],3,0),"") | E18: =IFERROR( VLOOKUP(ConsolidadoSP[[#This Row],[MEDIDAS CONTRATO]],MedidasContrato[],4,0),"") | F18: =IFERROR( VLOOKUP(ConsolidadoSP[[#This Row],[MEDIDAS CONTRATO]],MedidasContrato[],5,0),"") | N18: =IF( ConsolidadoSP[[#This Row],[QUAm-1]] = "", "", ConsolidadoSP[[#This Row],[QUAm-1]] +ConsolidadoSP[[#This Row],[QNm]] -ConsolidadoSP[[#This Row],[QBm]] -ConsolidadoSP[[#This Row],[QDm]]) | O18: =IF( ConsolidadoSP[[#This Row],[FC = V1/V2]] = "", "", ConsolidadoSP[[#This Row],[FC = V1/V2]] * ConsolidadoSP[[#This Row],[QUAm]]) | P18: =IF( ConsolidadoSP[[#This Row],[Contrato]] = "", "", IFERROR( VLOOKUP(ConsolidadoSP[[#This Row],[Contrato]],TabelaIRON[[Linha de Serviço PPU]:[PREÇO UNITÁRIO ]],3,0),"Nao Encontrado")) | Q18: =IF(ConsolidadoSP[[#This Row],[FC = V1/V2]]="","", ConsolidadoSP[[#This Row],[UA]] * ConsolidadoSP[[#This Row],[$ Unitário]])
C19: =IFERROR( VLOOKUP(ConsolidadoSP[[#This Row],[MEDIDAS CONTRATO]],MedidasContrato[[MEDIDAS CONTRATO]:[Ø]],2,0),"") | D19: =IFERROR( VLOOKUP(ConsolidadoSP[[#This Row],[MEDIDAS CONTRATO]],MedidasContrato[],3,0),"") | E19: =IFERROR( VLOOKUP(ConsolidadoSP[[#This Row],[MEDIDAS CONTRATO]],MedidasContrato[],4,0),"") | F19: =IFERROR( VLOOKUP(ConsolidadoSP[[#This Row],[MEDIDAS CONTRATO]],MedidasContrato[],5,0),"") | N19: =IF( ConsolidadoSP[[#This Row],[QUAm-1]] = "", "", ConsolidadoSP[[#This Row],[QUAm-1]] +ConsolidadoSP[[#This Row],[QNm]] -ConsolidadoSP[[#This Row],[QBm]] -ConsolidadoSP[[#This Row],[QDm]]) | O19: =IF( ConsolidadoSP[[#This Row],[FC = V1/V2]] = "", "", ConsolidadoSP[[#This Row],[FC = V1/V2]] * ConsolidadoSP[[#This Row],[QUAm]]) | P19: =IF( ConsolidadoSP[[#This Row],[Contrato]] = "", "", IFERROR( VLOOKUP(ConsolidadoSP[[#This Row],[Contrato]],TabelaIRON[[Linha de Serviço PPU]:[PREÇO UNITÁRIO ]],3,0),"Nao Encontrado")) | Q19: =IF(ConsolidadoSP[[#This Row],[FC = V1/V2]]="","", ConsolidadoSP[[#This Row],[UA]] * ConsolidadoSP[[#This Row],[$ Unitário]])
C20: =IFERROR( VLOOKUP(ConsolidadoSP[[#This Row],[MEDIDAS CONTRATO]],MedidasContrato[[MEDIDAS CONTRATO]:[Ø]],2,0),"") | D20: =IFERROR( VLOOKUP(ConsolidadoSP[[#This Row],[MEDIDAS CONTRATO]],MedidasContrato[],3,0),"") | E20: =IFERROR( VLOOKUP(ConsolidadoSP[[#This Row],[MEDIDAS CONTRATO]],MedidasContrato[],4,0),"") | F20: =IFERROR( VLOOKUP(ConsolidadoSP[[#This Row],[MEDIDAS CONTRATO]],MedidasContrato[],5,0),"") | N20: =IF( ConsolidadoSP[[#This Row],[QUAm-1]] = "", "", ConsolidadoSP[[#This Row],[QUAm-1]] +ConsolidadoSP[[#This Row],[QNm]] -ConsolidadoSP[[#This Row],[QBm]] -ConsolidadoSP[[#This Row],[QDm]]) | O20: =IF( ConsolidadoSP[[#This Row],[FC = V1/V2]] = "", "", ConsolidadoSP[[#This Row],[FC = V1/V2]] * ConsolidadoSP[[#This Row],[QUAm]]) | P20: =IF( ConsolidadoSP[[#This Row],[Contrato]] = "", "", IFERROR( VLOOKUP(ConsolidadoSP[[#This Row],[Contrato]],TabelaIRON[[Linha de Serviço PPU]:[PREÇO UNITÁRIO ]],3,0),"Nao Encontrado")) | Q20: =IF(ConsolidadoSP[[#This Row],[FC = V1/V2]]="","", ConsolidadoSP[[#This Row],[UA]] * ConsolidadoSP[[#This Row],[$ Unitário]])
C21: =IFERROR( VLOOKUP(ConsolidadoSP[[#This Row],[MEDIDAS CONTRATO]],MedidasContrato[[MEDIDAS CONTRATO]:[Ø]],2,0),"") | D21: =IFERROR( VLOOKUP(ConsolidadoSP[[#This Row],[MEDIDAS CONTRATO]],MedidasContrato[],3,0),"") | E21: =IFERROR( VLOOKUP(ConsolidadoSP[[#This Row],[MEDIDAS CONTRATO]],MedidasContrato[],4,0),"") | F21: =IFERROR( VLOOKUP(ConsolidadoSP[[#This Row],[MEDIDAS CONTRATO]],MedidasContrato[],5,0),"") | N21: =IF( ConsolidadoSP[[#This Row],[QUAm-1]] = "", "", ConsolidadoSP[[#This Row],[QUAm-1]] +ConsolidadoSP[[#This Row],[QNm]] -ConsolidadoSP[[#This Row],[QBm]] -ConsolidadoSP[[#This Row],[QDm]]) | O21: =IF( ConsolidadoSP[[#This Row],[FC = V1/V2]] = "", "", ConsolidadoSP[[#This Row],[FC = V1/V2]] * ConsolidadoSP[[#This Row],[QUAm]]) | P21: =IF( ConsolidadoSP[[#This Row],[Contrato]] = "", "", IFERROR( VLOOKUP(ConsolidadoSP[[#This Row],[Contrato]],TabelaIRON[[Linha de Serviço PPU]:[PREÇO UNITÁRIO ]],3,0),"Nao Encontrado")) | Q21: =IF(ConsolidadoSP[[#This Row],[FC = V1/V2]]="","", ConsolidadoSP[[#This Row],[UA]] * ConsolidadoSP[[#This Row],[$ Unitário]])
C22: =IFERROR( VLOOKUP(ConsolidadoSP[[#This Row],[MEDIDAS CONTRATO]],MedidasContrato[[MEDIDAS CONTRATO]:[Ø]],2,0),"") | D22: =IFERROR( VLOOKUP(ConsolidadoSP[[#This Row],[MEDIDAS CONTRATO]],MedidasContrato[],3,0),"") | E22: =IFERROR( VLOOKUP(ConsolidadoSP[[#This Row],[MEDIDAS CONTRATO]],MedidasContrato[],4,0),"") | F22: =IFERROR( VLOOKUP(ConsolidadoSP[[#This Row],[MEDIDAS CONTRATO]],MedidasContrato[],5,0),"") | N22: =IF( ConsolidadoSP[[#This Row],[QUAm-1]] = "", "", ConsolidadoSP[[#This Row],[QUAm-1]] +ConsolidadoSP[[#This Row],[QNm]] -ConsolidadoSP[[#This Row],[QBm]] -ConsolidadoSP[[#This Row],[QDm]]) | O22: =IF( ConsolidadoSP[[#This Row],[FC = V1/V2]] = "", "", ConsolidadoSP[[#This Row],[FC = V1/V2]] * ConsolidadoSP[[#This Row],[QUAm]]) | P22: =IF( ConsolidadoSP[[#This Row],[Contrato]] = "", "", IFERROR( VLOOKUP(ConsolidadoSP[[#This Row],[Contrato]],TabelaIRON[[Linha de Serviço PPU]:[PREÇO UNITÁRIO ]],3,0),"Nao Encontrado")) | Q22: =IF(ConsolidadoSP[[#This Row],[FC = V1/V2]]="","", ConsolidadoSP[[#This Row],[UA]] * ConsolidadoSP[[#This Row],[$ Unitário]])
C23: =IFERROR( VLOOKUP(ConsolidadoSP[[#This Row],[MEDIDAS CONTRATO]],MedidasContrato[[MEDIDAS CONTRATO]:[Ø]],2,0),"") | D23: =IFERROR( VLOOKUP(ConsolidadoSP[[#This Row],[MEDIDAS CONTRATO]],MedidasContrato[],3,0),"") | E23: =IFERROR( VLOOKUP(ConsolidadoSP[[#This Row],[MEDIDAS CONTRATO]],MedidasContrato[],4,0),"") | F23: =IFERROR( VLOOKUP(ConsolidadoSP[[#This Row],[MEDIDAS CONTRATO]],MedidasContrato[],5,0),"") | N23: =IF( ConsolidadoSP[[#This Row],[QUAm-1]] = "", "", ConsolidadoSP[[#This Row],[QUAm-1]] +ConsolidadoSP[[#This Row],[QNm]] -ConsolidadoSP[[#This Row],[QBm]] -ConsolidadoSP[[#This Row],[QDm]]) | O23: =IF( ConsolidadoSP[[#This Row],[FC = V1/V2]] = "", "", ConsolidadoSP[[#This Row],[FC = V1/V2]] * ConsolidadoSP[[#This Row],[QUAm]]) | P23: =IF( ConsolidadoSP[[#This Row],[Contrato]] = "", "", IFERROR( VLOOKUP(ConsolidadoSP[[#This Row],[Contrato]],TabelaIRON[[Linha de Serviço PPU]:[PREÇO UNITÁRIO ]],3,0),"Nao Encontrado")) | Q23: =IF(ConsolidadoSP[[#This Row],[FC = V1/V2]]="","", ConsolidadoSP[[#This Row],[UA]] * ConsolidadoSP[[#This Row],[$ Unitário]])
C24: =IFERROR( VLOOKUP(ConsolidadoSP[[#This Row],[MEDIDAS CONTRATO]],MedidasContrato[[MEDIDAS CONTRATO]:[Ø]],2,0),"") | D24: =IFERROR( VLOOKUP(ConsolidadoSP[[#This Row],[MEDIDAS CONTRATO]],MedidasContrato[],3,0),"") | E24: =IFERROR( VLOOKUP(ConsolidadoSP[[#This Row],[MEDIDAS CONTRATO]],MedidasContrato[],4,0),"") | F24: =IFERROR( VLOOKUP(ConsolidadoSP[[#This Row],[MEDIDAS CONTRATO]],MedidasContrato[],5,0),"") | N24: =IF( ConsolidadoSP[[#This Row],[QUAm-1]] = "", "", ConsolidadoSP[[#This Row],[QUAm-1]] +ConsolidadoSP[[#This Row],[QNm]] -ConsolidadoSP[[#This Row],[QBm]] -ConsolidadoSP[[#This Row],[QDm]]) | O24: =IF( ConsolidadoSP[[#This Row],[FC = V1/V2]] = "", "", ConsolidadoSP[[#This Row],[FC = V1/V2]] * ConsolidadoSP[[#This Row],[QUAm]]) | P24: =IF( ConsolidadoSP[[#This Row],[Contrato]] = "", "", IFERROR( VLOOKUP(ConsolidadoSP[[#This Row],[Contrato]],TabelaIRON[[Linha de Serviço PPU]:[PREÇO UNITÁRIO ]],3,0),"Nao Encontrado")) | Q24: =IF(ConsolidadoSP[[#This Row],[FC = V1/V2]]="","", ConsolidadoSP[[#This Row],[UA]] * ConsolidadoSP[[#This Row],[$ Unitário]])
C25: =IFERROR( VLOOKUP(ConsolidadoSP[[#This Row],[MEDIDAS CONTRATO]],MedidasContrato[[MEDIDAS CONTRATO]:[Ø]],2,0),"") | D25: =IFERROR( VLOOKUP(ConsolidadoSP[[#This Row],[MEDIDAS CONTRATO]],MedidasContrato[],3,0),"") | E25: =IFERROR( VLOOKUP(ConsolidadoSP[[#This Row],[MEDIDAS CONTRATO]],MedidasContrato[],4,0),"") | F25: =IFERROR( VLOOKUP(ConsolidadoSP[[#This Row],[MEDIDAS CONTRATO]],MedidasContrato[],5,0),"") | N25: =IF( ConsolidadoSP[[#This Row],[QUAm-1]] = "", "", ConsolidadoSP[[#This Row],[QUAm-1]] +ConsolidadoSP[[#This Row],[QNm]] -ConsolidadoSP[[#This Row],[QBm]] -ConsolidadoSP[[#This Row],[QDm]]) | O25: =IF( ConsolidadoSP[[#This Row],[FC = V1/V2]] = "", "", ConsolidadoSP[[#This Row],[FC = V1/V2]] * ConsolidadoSP[[#This Row],[QUAm]]) | P25: =IF( ConsolidadoSP[[#This Row],[Contrato]] = "", "", IFERROR( VLOOKUP(ConsolidadoSP[[#This Row],[Contrato]],TabelaIRON[[Linha de Serviço PPU]:[PREÇO UNITÁRIO ]],3,0),"Nao Encontrado")) | Q25: =IF(ConsolidadoSP[[#This Row],[FC = V1/V2]]="","", ConsolidadoSP[[#This Row],[UA]] * ConsolidadoSP[[#This Row],[$ Unitário]])
C26: =IFERROR( VLOOKUP(ConsolidadoSP[[#This Row],[MEDIDAS CONTRATO]],MedidasContrato[[MEDIDAS CONTRATO]:[Ø]],2,0),"") | D26: =IFERROR( VLOOKUP(ConsolidadoSP[[#This Row],[MEDIDAS CONTRATO]],MedidasContrato[],3,0),"") | E26: =IFERROR( VLOOKUP(ConsolidadoSP[[#This Row],[MEDIDAS CONTRATO]],MedidasContrato[],4,0),"") | F26: =IFERROR( VLOOKUP(ConsolidadoSP[[#This Row],[MEDIDAS CONTRATO]],MedidasContrato[],5,0),"") | N26: =IF( ConsolidadoSP[[#This Row],[QUAm-1]] = "", "", ConsolidadoSP[[#This Row],[QUAm-1]] +ConsolidadoSP[[#This Row],[QNm]] -ConsolidadoSP[[#This Row],[QBm]] -ConsolidadoSP[[#This Row],[QDm]]) | O26: =IF( ConsolidadoSP[[#This Row],[FC = V1/V2]] = "", "", ConsolidadoSP[[#This Row],[FC = V1/V2]] * ConsolidadoSP[[#This Row],[QUAm]]) | P26: =IF( ConsolidadoSP[[#This Row],[Contrato]] = "", "", IFERROR( VLOOKUP(ConsolidadoSP[[#This Row],[Contrato]],TabelaIRON[[Linha de Serviço PPU]:[PREÇO UNITÁRIO ]],3,0),"Nao Encontrado")) | Q26: =IF(ConsolidadoSP[[#This Row],[FC = V1/V2]]="","", ConsolidadoSP[[#This Row],[UA]] * ConsolidadoSP[[#This Row],[$ Unitário]])
C27: =IFERROR( VLOOKUP(ConsolidadoSP[[#This Row],[MEDIDAS CONTRATO]],MedidasContrato[[MEDIDAS CONTRATO]:[Ø]],2,0),"") | D27: =IFERROR( VLOOKUP(ConsolidadoSP[[#This Row],[MEDIDAS CONTRATO]],MedidasContrato[],3,0),"") | E27: =IFERROR( VLOOKUP(ConsolidadoSP[[#This Row],[MEDIDAS CONTRATO]],MedidasContrato[],4,0),"") | F27: =IFERROR( VLOOKUP(ConsolidadoSP[[#This Row],[MEDIDAS CONTRATO]],MedidasContrato[],5,0),"") | N27: =IF( ConsolidadoSP[[#This Row],[QUAm-1]] = "", "", ConsolidadoSP[[#This Row],[QUAm-1]] +ConsolidadoSP[[#This Row],[QNm]] -ConsolidadoSP[[#This Row],[QBm]] -ConsolidadoSP[[#This Row],[QDm]]) | O27: =IF( ConsolidadoSP[[#This Row],[FC = V1/V2]] = "", "", ConsolidadoSP[[#This Row],[FC = V1/V2]] * ConsolidadoSP[[#This Row],[QUAm]]) | P27: =IF( ConsolidadoSP[[#This Row],[Contrato]] = "", "", IFERROR( VLOOKUP(ConsolidadoSP[[#This Row],[Contrato]],TabelaIRON[[Linha de Serviço PPU]:[PREÇO UNITÁRIO ]],3,0),"Nao Encontrado")) | Q27: =IF(ConsolidadoSP[[#This Row],[FC = V1/V2]]="","", ConsolidadoSP[[#This Row],[UA]] * ConsolidadoSP[[#This Row],[$ Unitário]])
C28: =IFERROR( VLOOKUP(ConsolidadoSP[[#This Row],[MEDIDAS CONTRATO]],MedidasContrato[[MEDIDAS CONTRATO]:[Ø]],2,0),"") | D28: =IFERROR( VLOOKUP(ConsolidadoSP[[#This Row],[MEDIDAS CONTRATO]],MedidasContrato[],3,0),"") | E28: =IFERROR( VLOOKUP(ConsolidadoSP[[#This Row],[MEDIDAS CONTRATO]],MedidasContrato[],4,0),"") | F28: =IFERROR( VLOOKUP(ConsolidadoSP[[#This Row],[MEDIDAS CONTRATO]],MedidasContrato[],5,0),"") | N28: =IF( ConsolidadoSP[[#This Row],[QUAm-1]] = "", "", ConsolidadoSP[[#This Row],[QUAm-1]] +ConsolidadoSP[[#This Row],[QNm]] -ConsolidadoSP[[#This Row],[QBm]] -ConsolidadoSP[[#This Row],[QDm]]) | O28: =IF( ConsolidadoSP[[#This Row],[FC = V1/V2]] = "", "", ConsolidadoSP[[#This Row],[FC = V1/V2]] * ConsolidadoSP[[#This Row],[QUAm]]) | P28: =IF( ConsolidadoSP[[#This Row],[Contrato]] = "", "", IFERROR( VLOOKUP(ConsolidadoSP[[#This Row],[Contrato]],TabelaIRON[[Linha de Serviço PPU]:[PREÇO UNITÁRIO ]],3,0),"Nao Encontrado")) | Q28: =IF(ConsolidadoSP[[#This Row],[FC = V1/V2]]="","", ConsolidadoSP[[#This Row],[UA]] * ConsolidadoSP[[#This Row],[$ Unitário]])
C29: =IFERROR( VLOOKUP(ConsolidadoSP[[#This Row],[MEDIDAS CONTRATO]],MedidasContrato[[MEDIDAS CONTRATO]:[Ø]],2,0),"") | D29: =IFERROR( VLOOKUP(ConsolidadoSP[[#This Row],[MEDIDAS CONTRATO]],MedidasContrato[],3,0),"") | E29: =IFERROR( VLOOKUP(ConsolidadoSP[[#This Row],[MEDIDAS CONTRATO]],MedidasContrato[],4,0),"") | F29: =IFERROR( VLOOKUP(ConsolidadoSP[[#This Row],[MEDIDAS CONTRATO]],MedidasContrato[],5,0),"") | N29: =IF( ConsolidadoSP[[#This Row],[QUAm-1]] = "", "", ConsolidadoSP[[#This Row],[QUAm-1]] +ConsolidadoSP[[#This Row],[QNm]] -ConsolidadoSP[[#This Row],[QBm]] -ConsolidadoSP[[#This Row],[QDm]]) | O29: =IF( ConsolidadoSP[[#This Row],[FC = V1/V2]] = "", "", ConsolidadoSP[[#This Row],[FC = V1/V2]] * ConsolidadoSP[[#This Row],[QUAm]]) | P29: =IF( ConsolidadoSP[[#This Row],[Contrato]] = "", "", IFERROR( VLOOKUP(ConsolidadoSP[[#This Row],[Contrato]],TabelaIRON[[Linha de Serviço PPU]:[PREÇO UNITÁRIO ]],3,0),"Nao Encontrado")) | Q29: =IF(ConsolidadoSP[[#This Row],[FC = V1/V2]]="","", ConsolidadoSP[[#This Row],[UA]] * ConsolidadoSP[[#This Row],[$ Unitário]])

Sheet Tabela
A1: Padrão | C1: Tabela | E1: Linha de serviço PPU | G1: ITEM | H1: DESCRIÇÃO | I1: Linha de Serviço PPU | J1: UNID. | K1: PREÇO UNITÁRIO | L1: Descrição da Linha de Serviço | N1: MEDIDAS CONTRATO | O1: Ø | P1: A | Q1: L | R1: P
A2: Arquivo de aço 1 | C2: FC1 | E2: ARM-CX-DOC | G2: 1.1 | H2: ARM-CX-DOC: Armazenamento de caixas para documentos | I2: ARM-CX-DOC | J2: UA | K2: 0.6 | L2: Armazenamento de caixas para documentos | N2: A 0,5 X L 12,5 X P14,0 | P2: 0.5 | Q2: 12.5 | R2: 14
A3: Arquivo de aço 2 | C3: FC2 | E3: ARM-CX-MID | G3: 1.2 | H3: ARM-CX-MID: Armazenamento de caixas para mídias | I3: ARM-CX-MID | J3: UA | K3: 3.55 | L3: Armazenamento de caixas para mídias | N3: A 0,5 X L 13,0 X P13,0 | P3: 0.5 | Q3: 13 | R3: 13
A4: Arquivo de aço 3 | C4: FC3 | E4: ARM-TB | G4: 1.3 | H4: ARM-TB: Armazenamento de tubos | I4: ARM-TB | J4: UA | K4: 0.74 | L4: Armazenamento de tubos | N4: A 0,5 X L 14,0 X P 12,5 | P4: 0.5 | Q4: 14 | R4: 12.5
A5: Arquivo de aço 4 | C5: FC4 | E5: ARM-MA | G5: 1.4 | H5: ARM-MA: Armazenamento de mapotecas e arquivos de aço | I5: ARM-MA | J5: UA | K5: 56.11 | L5: Armazenamento de mapotecas e arquivos de aço | N5: A 0,5 X L 14,0 X P 13,0 | P5: 0.5 | Q5: 14 | R5: 13
A6: Arquivo de aço 5 | C6: FC5 | E6: ARM-MIC | G6: 1.5 | H6: ARM-MIC: Armazenamento de microformas | I6: ARM-MIC | J6: UA | K6: 0.08 | L6: Armazenamento de microformas | N6: A 0,5 X L 14,0 X P 14,0 | P6: 0.5 | Q6: 14 | R6: 14
A7: Caixa 10 kg (Jumbo) | C7: FC6 | E7: ARM-MID | G7: 1.6 | H7: ARM-MID: Armazenamento de midias | I7: ARM-MID | J7: UA | K7: 0.08 | L7: Armazenamento de midias | N7: A 08,0 X L 41,0 X P 41,0 | P7: 8 | Q7: 41 | R7: 41
A8: Caixa 20 Kg | C8: FC7 | E8: FRE-NRM | G8: 1.7 | H8: FRE-NRM: Frete normal | I8: FRE-NRM | J8: Frete | K8: 125.89 | L8: Frete normal | N8: A 1,0 X L 12,5 X P14,0 | P8: 1 | Q8: 12.5 | R8: 14
A9: Caixa 20 kg - Tipo 1 | C9: FC8 | E9: FRE-EXP | G9: 1.8 | H9: FRE-EXP: Frete expresso | I9: FRE-EXP | J9: Frete | K9: 200 | L9: Frete expresso | N9: A 1,0 X L 14,0 X P 13,0 | P9: 1 | Q9: 14 | R9: 13
A10: Caixa 20 kg - Tipo 2 | C10: FC9 | E10: INS-ITEM | G10: 1.9 | H10: KM-AD: Quilometragem adicional | I10: KM-AD | J10: KM | K10: 0.5 | L10: Quilometragem adicional | N10: A 1,0 X L 14,0 X P 19,0 | P10: 1 | Q10: 14 | R10: 19
A11: Caixa 20 kg (contendo Mídias e Microfilmes) | E11: PES-ITEM | G11: 1.10 | H11: PES-ITEM: Pesquisa de itens avulsos | I11: PES-ITEM | J11: Item Avulso | K11: 1.96 | L11: Pesquisa de itens avulsos | N11: A 10,0 X L 10,0 X P 2,5 | P11: 10 | Q11: 10 | R11: 2.5
A12: Caixa 5 kg | E12: DES-EMB | G12: 1.11 | H12: DES-EMB: Destruição segura de documentos | I12: DES-EMB | J12: Embalagem | K12: 1.35 | L12: Destruição segura de documentos | N12: A 10,0 X L 10,5 X P 4,0 | P12: 10 | Q12: 10.5 | R12: 4
A13: Caixa 5kg | E13: TRANSF | G13: 1.12 | H13: TRANSF: Transferência inicial de acervo documental | I13: TRANSF | J13: Transferência | K13: 594488.34 | L13: Transferência inicial de acervo documental | N13: A 10,0 X L 15,5 X P 0,3 | P13: 10 | Q13: 15.5 | R13: 0.3
A14: Caixa 7 kg | E14: MIGR-UA | G14: 1.13 | H14: MIGR-UA: Migração de acervo documental para digitalização | I14: MIGR-UA | J14: UA | K14: 1.01 | L14: Migração de acervo documental para digitalização | N14: A 10,0 X L 19,0 X P 26,5 | P14: 10 | Q14: 19 | R14: 26.5
A15: Caixa para mídias - Tipo 1 | E15: CAT-EMB | G15: 2.1 | H15: CAT-ITEM: Catalogação de documentos digitalizados | I15: CAT-ITEM | J15: Documento | K15: 0.44 | L15: Catalogação de documentos digitalizados | N15: A 10,0 X L 3,0 X P 10,0 | P15: 10 | Q15: 3 | R15: 10
A16: Caixa para mídias - Tipo 2 | E16: CAT-ITEM | G16: 2.2 | H16: ORG-DOC: Organização de documentos para digitalização | I16: ORG-DOC | J16: UA | K16: 1.44 | L16: Organização de documentos para digitalização | N16: A 10,0 X L 4,5 X P 10,0 | P16: 10 | Q16: 4.5 | R16: 10
A17: Documentação administrativa | E17: ORG-DOC | G17: 2.3 | H17: DIG-MI: Digitalização de microfilmes | I17: DIG-MI | J17: UD | K17: 0.05 | L17: Digitalização de microfilmes | N17: A 10,5 X L 15,0 X P 0,3 | P17: 10.5 | Q17: 15 | R17: 0.3
A18: Documentação bibliográfica | E18: HIG-MI | G18: 2.4 | H18: DIG-MF: Digitalização de microfichas | I18: DIG-MF | J18: UD | K18: 0.06 | L18: Digitalização de microfichas | N18: A 10,5 X L 19,0 X P2,5 | P18: 10.5 | Q18: 19 | R18: 2.5
A19: Documentação contábil e financeira | E19: HIG-MF | G19: 2.5 | H19: DIG-DOC: Digitalização de documentos | I19: DIG-DOC | J19: UD | K19: 0.1 | L19: Digitalização de documentos | N19: A 10,5 X L 41,0 X P 41,0 | P19: 10.5 | Q19: 41 | R19: 41
A20: Documentação contratual | E20: HIG-PER | G20: 2.6 | H20: IND-DOC: Indexação de documentos | I20: IND-DOC | J20: UD | K20: 0.23 | L20: Indexação de documentos | N20: A 100,0 X L 140,0 X P 51,0 | P20: 100 | Q20: 140 | R20: 51
A21: Documentação técnica | E21: DIG-MI | G21: 2.7 | H21: CONV-MID: Conversão de mídias | I21: CONV-MID | J21: Mídia | K21: 68.27 | L21: Conversão de mídias | N21: A 11,0 X L 15,5 X P 0,3 | P21: 11 | Q21: 15.5 | R21: 0.3
A22: Documento - Formato A0 | E22: DIG-MF | G22: 2.8 | H22: GRV-MID: Gravação de mídias | I22: GRV-MID | J22: Mídia | K22: 39 | L22: Gravação de mídias | N22: A 11,0 X L 33,0 X P 37,0 | P22: 11 | Q22: 33 | R22: 37
... A24: Documento - Formato A2 | E24: IND-DOC | G24: 2.10 | H24: COP-VID: Cópia de vídeos | I24: COP-VID | J24: Mídia | K24: 2.44 | L24: Cópia de vídeos | N24: A 11,5 X L 37,0 X P 33,0 | P24: 11.5 | Q24: 37 | R24: 33
A25: Documento - Formato A3 | E25: CONV-MID | N25: A 12,0 X L 34,0 X P 37,0 | P25: 12 | Q25: 34 | R25: 37
A26: Documento - Formato A4 | E26: GRV-MID | N26: A 12,0 X L 34,0 X P 37,0 | P26: 12 | Q26: 34 | R26: 37
A27: Documento - Superior ao Formato A0 | E27: COP-MID | N27: A 12,5 X L 14 X P 0,5 | P27: 12.5 | Q27: 14 | R27: 0.5
A28: Embalagem | E28: COP-VID | N28: A 12,5 X L 14,5 X P0,5 | P28: 12.5 | Q28: 14.5 | R28: 0.5
A29: Fita VHS | E29: N/A | N29: A 130,0 X L 060,0 X P 72,0 | P29: 130 | Q29: 60 | R29: 72
A30: Item avulso | N30: A 130,0 X L 060,0 X P 73,0 | P30: 130 | Q30: 60 | R30: 73
A31: Item documental | N31: A 135,0 X L 51,0 X P 105,0 | P31: 135 | Q31: 51 | R31: 105
A32: Item documental em caixa | N32: A 140,0 X L 067,0 X P 72,0 | P32: 140 | Q32: 67 | R32: 72
A33: Item documental em mapoteca | N33: A 15,0 X L 40,0 X P 35,0 | P33: 15 | Q33: 40 | R33: 35
A34: Item documental em Tubo | N34: A 150,0 X L 090,0 X P 76,0 | P34: 150 | Q34: 90 | R34: 76
A35: Kit de material | N35: A 16,5 X L 11,5 X P 0,3 | P35: 16.5 | Q35: 11.5 | R35: 0.3
A36: Mapoteca | N36: A 17,0 X L 20,5 X P 111,5 | P36: 17 | Q36: 20.5 | R36: 111.5
A37: Microficha | N37: A 170,0 X L 061,0 X P 72,0 | P37: 170 | Q37: 61 | R37: 72
A38: Microfilme | N38: A 180,0 X L 068,0 X P 72,0 | P38: 180 | Q38: 68 | R38: 72
A39: Microfilme 16 mm | N39: A 21,0 X L 31,0 X P 46,0 | P39: 21 | Q39: 31 | R39: 46
A40: Microfilme 35 mm | N40: A 21,0 X L 41,0 X P 55,0 | P40: 21 | Q40: 41 | R40: 55
A41: Microforma em arquivo de aço | N41: A 21,5 X L 41,0 X P 51,0 | P41: 21.5 | Q41: 41 | R41: 51
...

Sheet Digitalização projeto
A1: data_criacao | B1: Medição | C1: Imagens | D1: Identificador SOS | E1: Localização

Sheet Videos submarinos
A1: id | B1: inspecao | C1: etiqueta | D1: status | E1: midia | F1: repositorio | G1: dt_extracao | H1: dt_fim_extracao | I1: dt_sincronismo | J1: dt_fim_sincronismo | K1: hr_fim_sincronismo | L1: estacao | M1: estacao_ip | N1: urgente | O1: arquivos

Sheet Relação de ordens de serviço
B3: OS | C3: Click | D3: Status
B4: 10000 | C4: 52 | D4: No Prazo
B5: 2000 | C5: 45 | D5: Forado prazo
B6: 500 | C6: 10 | D6: No Prazo

Sheet Base
B2: Status Primário | D2: Status Secundário | F2: Solicitante | H2: Coordenador | J2: Status do prazo | L2: Medição | N2: Estados | P2: Tipo de Solicitação
D3: Ordens atendidas no prazo | F3: Gustavo Henrique Ferreira | H3: Renan Valente | J3: No Prazo | L3: 26/01/2021 a 25/02/2021 | N3: RJ | P3: Normal
B4: Ordens em atendimento | D4: Ordens atendidas fora do prazo | F4: Carolina Santos de mendonça | H4: Israel Silva | J4: Fora do Prazo | L4: 26/02/2021 a 25/03/2021 | N4: DF | P4: Urgente
B5: Ordens pendentes | D5: Ordens pendentes no prazo | F5: Viviane Rosa Rangel | H5: Lucas Santos | L5: 26/03/2021 a 25/04/2021 | N5: ES
B6: Ordens atendidas | D6: Ordens pendentes fora do prazo | H6: Erick Brito | L6: 26/04/2021 a 25/05/2021 | N6: SP
H7: Bruna de Oliveira | L7: 26/05/2021 a 25/06/2021 | N7: MS
L8: 26/06/2021 a 25/07/2021
L9: 26/07/2021 a 25/08/2021
L10: 26/08/2021 a 25/09/2021
B11: Status da OS | L11: 26/09/2021 a 25/10/2021
B12: Aguardando atendimento | L12: 26/10/2021 a 25/11/2021
B13: Em atendimento | L13: 26/11/2021 a 25/12/2021
B14: Atendida
