Workbook
Name ARMCXDOC: 'MC BA'!$D$12
Name ARMCXMID: 'MC BA'!$D$15
Name ARMMA: 'MC BA'!$D$21
Name ARMMIC: 'MC BA'!$D$24
Name ARMMID: 'MC BA'!$D$27
Name ARMTB: 'MC BA'!$D$18

Sheet MC BA
B2: P E T R O L E O B R A S I L E I R O S. A. P E T R O B R A S
B3: M E M Ó R I A D E C Á L C U L O D E M E D I Ç Ã O
B4: Razão Social: | D4: PA ARQUIVOS LTDA | I4: CNPJ: | J4: 34.409.656/0001-84 | L4: Item 1 PPU | M4: IAPEFARQ: | N4: ='Mapa Geral'!I41 -> 0.33333333
B5: Contrato SAP: | D5: 4600687006 | I5: Área contrato: | J5: Lote 2 | M5: FDM: | N5: 1
B6: Objeto: | D6: SERVIÇO DE GUARDA E GERENCIAMENTO DE DOCUMENTOS E INFORMAÇÕES DO ACERVO DA PETROBRAS | I6: Instr. contratual: | J6: 5900.0133214.25.2 | L6: Item 2 PPU | M6: IAPEFARQ: | N6: ='Mapa Geral'!K41 -> 0.76
I7: Período: | J7: 26/06/2026 à 25/07/2026 | M7: FDM: | N7: 1
C10: Item | D10: Descrição da atividade | I10: Unidade | J10: QExec | K10: QFinal | L10: Valor unitário | M10: Valor total a pagar | N10: Observações
C11: 1 | D11: Guarda de Documentos e Informações
D12: ARM-CX-DOC | E12: Armazenamento de caixas para documentos
C13: 1.1 | D13: QUAm-1 | E13: QBm | F13: QDm | G13: QNm | H13: QUAm | I13: UA | J13: =SUMIF(ConsolidadoPA[Contrato],D12,ConsolidadoPA[UA]) -> 108333.57 | K13: =J13*$N$5 -> 108333.57 | L13: =IFERROR(VLOOKUP(ARMCXDOC,TabelaPA[[Linha de Serviço PPU]:[PREÇO UNITÁRIO ]],3,FALSE),"N/A") -> 0.9 | M13: =K13*L13 -> 97500.213
D14: =SUMIF(ConsolidadoPA[Contrato],ARMCXDOC,ConsolidadoPA[QUAm-1]) -> 84801 | E14: =SUMIF(ConsolidadoPA[Contrato],D12,ConsolidadoPA[QBm]) -> 0 | F14: =SUMIF(ConsolidadoPA[Contrato],D12,ConsolidadoPA[QDm]) -> 0 | G14: =SUMIF(ConsolidadoPA[Contrato],D12,ConsolidadoPA[QNm]) -> 17366 | H14: =(D14-E14-F14)+G14 -> 102167
D15: ARM-CX-MID | E15: Armazenamento de caixas para mídias
C16: 1.2 | D16: QUAm-1 | E16: QBm | F16: QDm | G16: QNm | H16: QUAm | I16: UA | J16: =SUMIF(ConsolidadoPA[Contrato],D15,ConsolidadoPA[UA]) -> 0 | K16: =J16*$N$5 -> 0 | L16: =IFERROR(VLOOKUP(ARMCXMID,TabelaPA[[Linha de Serviço PPU]:[PREÇO UNITÁRIO ]],3,FALSE),"N/A") -> 0.9 | M16: =K16*L16 -> 0
D17: =SUMIF(ConsolidadoPA[Contrato],D15,ConsolidadoPA[QUAm-1]) -> 0 | E17: =SUMIF(ConsolidadoPA[Contrato],D15,ConsolidadoPA[QBm]) -> 0 | F17: =SUMIF(ConsolidadoPA[Contrato],D15,ConsolidadoPA[QDm]) -> 0 | G17: =SUMIF(ConsolidadoPA[Contrato],D15,ConsolidadoPA[QNm]) -> 0 | H17: =(D17-E17-F17)+G17 -> 0
D18: ARM-TB | E18: Armazenamento de tubos
C19: 1.3 | D19: QUAm-1 | E19: QBm | F19: QDm | G19: QNm | H19: QUAm | I19: UA | J19: =SUMIF(ConsolidadoPA[Contrato],D18,ConsolidadoPA[UA]) -> 6.6206897 | K19: =J19*$N$5 -> 6.6206897 | L19: =IFERROR(VLOOKUP(ARMTB,TabelaPA[[Linha de Serviço PPU]:[PREÇO UNITÁRIO ]],3,FALSE),"N/A") -> 0.9 | M19: =K19*L19 -> 5.9586207
D20: =SUMIF(ConsolidadoPA[Contrato],D18,ConsolidadoPA[QUAm-1]) -> 0 | E20: =SUMIF(ConsolidadoPA[Contrato],D18,ConsolidadoPA[QBm]) -> 0 | F20: =SUMIF(ConsolidadoPA[Contrato],D18,ConsolidadoPA[QDm]) -> 0 | G20: =SUMIF(ConsolidadoPA[Contrato],D18,ConsolidadoPA[QNm]) -> 2 | H20: =(D20-E20-F20)+G20 -> 2
D21: ARM-MA | E21: Armazenamento de mapotecas e arquivos de aço
C22: 1.4 | D22: QUAm-1 | E22: QBm | F22: QDm | G22: QNm | H22: QUAm | I22: UA | J22: =SUMIF(ConsolidadoPA[Contrato],D21,ConsolidadoPA[UA]) -> 0 | K22: =J22*$N$5 -> 0 | L22: =IFERROR(VLOOKUP(ARMMA,TabelaPA[[Linha de Serviço PPU]:[PREÇO UNITÁRIO ]],3,FALSE),"N/A") -> 70 | M22: =K22*L22 -> 0
D23: =SUMIF(ConsolidadoPA[Contrato],D21,ConsolidadoPA[QUAm-1]) -> 0 | E23: =SUMIF(ConsolidadoPA[Contrato],D21,ConsolidadoPA[QBm]) -> 0 | F23: =SUMIF(ConsolidadoPA[Contrato],D21,ConsolidadoPA[QDm]) -> 0 | G23: =SUMIF(ConsolidadoPA[Contrato],D21,ConsolidadoPA[QNm]) -> 0 | H23: =(D23-E23-F23)+G23 -> 0
D24: ARM-MIC | E24: Armazenamento de microformas
C25: 1.5 | D25: QUAm-1 | E25: QBm | F25: QDm | G25: QNm | H25: QUAm | I25: UA | J25: =SUMIF(ConsolidadoPA[Contrato],D24,ConsolidadoPA[UA]) -> 0 | K25: =J25*$N$5 -> 0 | L25: =IFERROR(VLOOKUP(ARMMIC,TabelaPA[[Linha de Serviço PPU]:[PREÇO UNITÁRIO ]],3,FALSE),"N/A") -> 0.1 | M25: =K25*L25 -> 0
D26: =SUMIF(ConsolidadoPA[Contrato],D24,ConsolidadoPA[QUAm-1]) -> 0 | E26: =SUMIF(ConsolidadoPA[Contrato],D24,ConsolidadoPA[QBm]) -> 0 | F26: =SUMIF(ConsolidadoPA[Contrato],D24,ConsolidadoPA[QDm]) -> 0 | G26: =SUMIF(ConsolidadoPA[Contrato],D24,ConsolidadoPA[QNm]) -> 0 | H26: =(D26-E26-F26)+G26 -> 0
D27: ARM-MID | E27: Armazenamento de midias
C28: 1.6 | D28: QUAm-1 | E28: QBm | F28: QDm | G28: QNm | H28: QUAm | I28: UA | J28: =SUMIF(ConsolidadoPA[Contrato],D27,ConsolidadoPA[UA]) -> 0 | K28: =J28*$N$5 -> 0 | L28: =IFERROR(VLOOKUP(ARMMID,TabelaPA[[Linha de Serviço PPU]:[PREÇO UNITÁRIO ]],3,FALSE),"N/A") -> 0.1 | M28: =K28*L28 -> 0
D29: =SUMIF(ConsolidadoPA[Contrato],D27,ConsolidadoPA[QUAm-1]) -> 0 | E29: =SUMIF(ConsolidadoPA[Contrato],D27,ConsolidadoPA[QBm]) -> 0 | F29: =SUMIF(ConsolidadoPA[Contrato],D27,ConsolidadoPA[QDm]) -> 0 | G29: =SUMIF(ConsolidadoPA[Contrato],D27,ConsolidadoPA[QNm]) -> 0 | H29: =(D29-E29-F29)+G29 -> 0
C30: 1.7 | D30: FRE-NRM | E30: Frete normal | I30: Frete | J30: =SUMIF(Table_5[Tipo],"FRE-NRM",Table_5[Cálculo final]) -> 2 | K30: =J30*$N$5 -> 2 | L30: =IFERROR(VLOOKUP(D30,TabelaPA[[Linha de Serviço PPU]:[PREÇO UNITÁRIO ]],3,FALSE),"N/A") -> 50 | M30: =K30*L30 -> 100
C31: 1.8 | D31: FRE-EXP | E31: Frete expresso | I31: Frete | J31: =SUMIF(Table_5[Tipo],"FRE-EXP",Table_5[Cálculo final]) -> 0 | K31: =J31*$N$5 -> 0 | L31: =IFERROR(VLOOKUP(D31,TabelaPA[[Linha de Serviço PPU]:[PREÇO UNITÁRIO ]],3,FALSE),"N/A") -> 100 | M31: =K31*L31 -> 0
C32: 1.9 | D32: KM-AD | E32: Quilometragem adicional | I32: KM | J32: =SUMIF(Table_5[Tipo],"KM-AD",Table_5[KM excedente]) -> 3208 | K32: =J32*$N$5 -> 3208 | L32: =IFERROR(VLOOKUP(D32,TabelaPA[[Linha de Serviço PPU]:[PREÇO UNITÁRIO ]],3,FALSE),"N/A") -> 1 | M32: =K32*L32 -> 3208
C33: 1.10 | D33: PES-ITEM | E33: Pesquisa de itens avulsos | I33: Item Avulso | J33: ='Digitalização Click'!C36 -> 436 | K33: =J33*$N$5 -> 436 | L33: =IFERROR(VLOOKUP(D33,TabelaPA[[Linha de Serviço PPU]:[PREÇO UNITÁRIO ]],3,FALSE),"N/A") -> 3 | M33: =K33*L33 -> 1308
C34: 1.11 | D34: DES-EMB | E34: Destruição segura de documentos | I34: Item Avulso | J34: 0 | K34: =J34*$N$5 -> 0 | L34: =IFERROR(VLOOKUP(D34,TabelaPA[[Linha de Serviço PPU]:[PREÇO UNITÁRIO ]],3,FALSE),"N/A") -> 3 | M34: =K34*L35 -> 0
C35: 1.12 | D35: TRANSF | E35: Transferência inicial de acervo documental | I35: Transferência | J35: 0 | K35: =J35*$N$5 -> 0 | L35: =IFERROR(VLOOKUP(D35,TabelaPA[[Linha de Serviço PPU]:[PREÇO UNITÁRIO ]],3,FALSE),"N/A") -> 100000 | M35: 0
C36: 1.13 | D36: MIGR-UA | E36: Migração de acervo documental para digitalização | I36: UA | J36: 0 | K36: =J36*$N$5 -> 0 | L36: =IFERROR(VLOOKUP(D36,TabelaPA[[Linha de Serviço PPU]:[PREÇO UNITÁRIO ]],3,FALSE),"N/A") -> 7.5 | M36: =K36*L36 -> 0
C37: 2 | D37: Gerenciamento de Documentos e Informações
C38: 2.1 | D38: CAT-ITEM | E38: Catalogação de documentos digitalizados | I38: Documento | J38: 0 | K38: =J38*$N$7 -> 0 | L38: =IFERROR(VLOOKUP(D38,TabelaPA[[Linha de Serviço PPU]:[PREÇO UNITÁRIO ]],3,FALSE),"N/A") -> 0.2 | M38: =K38*L38 -> 0
C39: 2.2 | D39: ORG-DOC | E39: Organização de documentos para digitalização | I39: UA | J39: 0 | K39: =J39*$N$7 -> 0 | L39: =IFERROR(VLOOKUP(D39,TabelaPA[[Linha de Serviço PPU]:[PREÇO UNITÁRIO ]],3,FALSE),"N/A") -> 10 | M39: =K39*L39 -> 0
C40: 2.3 | D40: DIG-MI | E40: Digitalização de microfilmes | I40: UD | J40: 0 | K40: =J40*$N$7 -> 0 | L40: =IFERROR(VLOOKUP(D40,TabelaPA[[Linha de Serviço PPU]:[PREÇO UNITÁRIO ]],3,FALSE),"N/A") -> 0.05 | M40: =K40*L40 -> 0
C41: 2.4 | D41: DIG-MF | E41: Digitalização de microfichas | I41: UD | J41: ='Digitalização Click'!C30 -> 51 | K41: =J41*$N$7 -> 51 | L41: =IFERROR(VLOOKUP(D41,TabelaPA[[Linha de Serviço PPU]:[PREÇO UNITÁRIO ]],3,FALSE),"N/A") -> 0.05 | M41: =K41*L41 -> 2.55
C42: 2.5 | D42: DIG-DOC | E42: Digitalização de documentos | I42: UD | J42: ='Digitalização Click'!C32 -> 34544 | K42: =J42*$N$7 -> 34544 | L42: =IFERROR(VLOOKUP(D42,TabelaPA[[Linha de Serviço PPU]:[PREÇO UNITÁRIO ]],3,FALSE),"N/A") -> 0.11 | M42: =K42*L42 -> 3799.84
C43: 2.6 | D43: IND-DOC | E43: Indexação de documentos | I43: UD | J43: ='Digitalização Click'!C31 -> 436 | K43: =J43*$N$7 -> 436 | L43: =IFERROR(VLOOKUP(D43,TabelaPA[[Linha de Serviço PPU]:[PREÇO UNITÁRIO ]],3,FALSE),"N/A") -> 0.1 | M43: =K43*L43 -> 43.6
...

Sheet Consolidado
A1: Consolidado BA | J1: mês anterior | K1: Saída/mês | L1: Exp./Mês | M1: Novas/mês | N1: QUAm = QUAm-1 + QNm - QBm - QDm
C2: Formula | D2: Formula | E2: Formula | F2: Formula | G2: Formula | H2: Formula | J2: Editar | K2: Editar | L2: Editar | M2: Editar | N2: Formula | O2: Formula | P2: Formula | Q2: Formula
A3: MEDIDAS CONTRATO | B3: Padrão | C3: Ø | D3: A | E3: L | F3: P | G3: cm³ = V1 | H3: cm³ = V2 | I3: FC = V1/V2 | J3: QUAm-1 | K3: QBm | L3: QDm | M3: QNm | N3: QUAm | O3: UA | P3: $ Unitário | Q3: $ Total | R3: Tabela | S3: Contrato
A4: A 26,0 X L 39,5 X P 48,5 | B4: Caixa 20 kg - Tipo 1 | C4: =IF(ConsolidadoPA[[#This Row],[MEDIDAS CONTRATO]]="","", IFERROR( VLOOKUP(ConsolidadoPA[[#This Row],[MEDIDAS CONTRATO]],MedidasContrato[[MEDIDAS CONTRATO]:[Ø]],2,0),"N/A")) -> 0 | D4: =IF( ConsolidadoPA[[#This Row],[MEDIDAS CONTRATO]] = "", "", IFERROR( VLOOKUP(ConsolidadoPA[[#This Row],[MEDIDAS CONTRATO]],MedidasContrato[],3,0),"N/A")) -> 26 | E4: =IF( ConsolidadoPA[[#This Row],[MEDIDAS CONTRATO]] = "", "", IFERROR( VLOOKUP(ConsolidadoPA[[#This Row],[MEDIDAS CONTRATO]],MedidasContrato[],4,0),"N/A")) -> 39.5 | F4: =IF( ConsolidadoPA[[#This Row],[MEDIDAS CONTRATO]] = "", "", IFERROR( VLOOKUP(ConsolidadoPA[[#This Row],[MEDIDAS CONTRATO]],MedidasContrato[],5,0),"N/A")) -> 48.5 | G4: =IFERROR( ConsolidadoPA[[#This Row],[A]]*ConsolidadoPA[[#This Row],[L]]*ConsolidadoPA[[#This Row],[P]], "") -> 49809.5 | H4: 43993 | I4: =IFERROR( ConsolidadoPA[[#This Row],[cm³ = V1]]/ConsolidadoPA[[#This Row],[cm³ = V2]],"") -> 1.1322142 | J4: 4 | M4: 1 | N4: =IF( ConsolidadoPA[[#This Row],[QUAm-1]]="","",Consolidado!$M4+Consolidado!$J4-Consolidado!$L4-Consolidado!$K4) -> 5 | O4: =IF(ConsolidadoPA[[#This Row],[FC = V1/V2]]="","",ConsolidadoPA[[#This Row],[FC = V1/V2]]*ConsolidadoPA[[#This Row],[QUAm]]) -> 5.6610711 | P4: =IF( ConsolidadoPA[[#This Row],[Contrato]] = "", "", IFERROR( VLOOKUP(ConsolidadoPA[[#This Row],[Contrato]],TabelaPA[[Linha de Serviço PPU]:[PREÇO UNITÁRIO ]],3,0),"Nao Encontrado")) -> 0.9 | Q4: =IF(ConsolidadoPA[[#This Row],[$ Unitário]]="","",Consolidado!$P4*Consolidado!$O4) -> 5.094964 | R4: FC1 | S4: ARM-CX-DOC
A5: A 26,5 X L 38,5 X P 46,5 | B5: Caixa 20 kg - Tipo 1 | C5: =IF(ConsolidadoPA[[#This Row],[MEDIDAS CONTRATO]]="","", IFERROR( VLOOKUP(ConsolidadoPA[[#This Row],[MEDIDAS CONTRATO]],MedidasContrato[[MEDIDAS CONTRATO]:[Ø]],2,0),"N/A")) -> 0 | D5: =IF( ConsolidadoPA[[#This Row],[MEDIDAS CONTRATO]] = "", "", IFERROR( VLOOKUP(ConsolidadoPA[[#This Row],[MEDIDAS CONTRATO]],MedidasContrato[],3,0),"N/A")) -> 26.5 | E5: =IF( ConsolidadoPA[[#This Row],[MEDIDAS CONTRATO]] = "", "", IFERROR( VLOOKUP(ConsolidadoPA[[#This Row],[MEDIDAS CONTRATO]],MedidasContrato[],4,0),"N/A")) -> 38.5 | F5: =IF( ConsolidadoPA[[#This Row],[MEDIDAS CONTRATO]] = "", "", IFERROR( VLOOKUP(ConsolidadoPA[[#This Row],[MEDIDAS CONTRATO]],MedidasContrato[],5,0),"N/A")) -> 46.5 | G5: =IFERROR( ConsolidadoPA[[#This Row],[A]]*ConsolidadoPA[[#This Row],[L]]*ConsolidadoPA[[#This Row],[P]], "") -> 47441.625 | H5: 43993 | I5: =IFERROR( ConsolidadoPA[[#This Row],[cm³ = V1]]/ConsolidadoPA[[#This Row],[cm³ = V2]],"") -> 1.0783903 | J5: 8 | M5: 0 | N5: =IF( ConsolidadoPA[[#This Row],[QUAm-1]]="","",Consolidado!$M5+Consolidado!$J5-Consolidado!$L5-Consolidado!$K5) -> 8 | O5: =IF(ConsolidadoPA[[#This Row],[FC = V1/V2]]="","",ConsolidadoPA[[#This Row],[FC = V1/V2]]*ConsolidadoPA[[#This Row],[QUAm]]) -> 8.6271225 | P5: =IF( ConsolidadoPA[[#This Row],[Contrato]] = "", "", IFERROR( VLOOKUP(ConsolidadoPA[[#This Row],[Contrato]],TabelaPA[[Linha de Serviço PPU]:[PREÇO UNITÁRIO ]],3,0),"Nao Encontrado")) -> 0.9 | Q5: =IF(ConsolidadoPA[[#This Row],[$ Unitário]]="","",Consolidado!$P5*Consolidado!$O5) -> 7.7644102 | R5: FC1 | S5: ARM-CX-DOC
A6: A 26,5 X L 40,0 X P 49,0 | B6: Caixa 20 kg - Tipo 1 | C6: =IF(ConsolidadoPA[[#This Row],[MEDIDAS CONTRATO]]="","", IFERROR( VLOOKUP(ConsolidadoPA[[#This Row],[MEDIDAS CONTRATO]],MedidasContrato[[MEDIDAS CONTRATO]:[Ø]],2,0),"N/A")) -> 0 | D6: =IF( ConsolidadoPA[[#This Row],[MEDIDAS CONTRATO]] = "", "", IFERROR( VLOOKUP(ConsolidadoPA[[#This Row],[MEDIDAS CONTRATO]],MedidasContrato[],3,0),"N/A")) -> 26.5 | E6: =IF( ConsolidadoPA[[#This Row],[MEDIDAS CONTRATO]] = "", "", IFERROR( VLOOKUP(ConsolidadoPA[[#This Row],[MEDIDAS CONTRATO]],MedidasContrato[],4,0),"N/A")) -> 40 | F6: =IF( ConsolidadoPA[[#This Row],[MEDIDAS CONTRATO]] = "", "", IFERROR( VLOOKUP(ConsolidadoPA[[#This Row],[MEDIDAS CONTRATO]],MedidasContrato[],5,0),"N/A")) -> 49 | G6: =IFERROR( ConsolidadoPA[[#This Row],[A]]*ConsolidadoPA[[#This Row],[L]]*ConsolidadoPA[[#This Row],[P]], "") -> 51940 | H6: 43993 | I6: =IFERROR( ConsolidadoPA[[#This Row],[cm³ = V1]]/ConsolidadoPA[[#This Row],[cm³ = V2]],"") -> 1.1806424 | J6: 17 | M6: 3 | N6: =IF( ConsolidadoPA[[#This Row],[QUAm-1]]="","",Consolidado!$M6+Consolidado!$J6-Consolidado!$L6-Consolidado!$K6) -> 20 | O6: =IF(ConsolidadoPA[[#This Row],[FC = V1/V2]]="","",ConsolidadoPA[[#This Row],[FC = V1/V2]]*ConsolidadoPA[[#This Row],[QUAm]]) -> 23.612847 | P6: =IF( ConsolidadoPA[[#This Row],[Contrato]] = "", "", IFERROR( VLOOKUP(ConsolidadoPA[[#This Row],[Contrato]],TabelaPA[[Linha de Serviço PPU]:[PREÇO UNITÁRIO ]],3,0),"Nao Encontrado")) -> 0.9 | Q6: =IF(ConsolidadoPA[[#This Row],[$ Unitário]]="","",Consolidado!$P6*Consolidado!$O6) -> 21.251563 | R6: FC1 | S6: ARM-CX-DOC
A7: A 28,0 X L 37,5 X P 47,5 | B7: Caixa 20 kg - Tipo 1 | C7: =IF(ConsolidadoPA[[#This Row],[MEDIDAS CONTRATO]]="","", IFERROR( VLOOKUP(ConsolidadoPA[[#This Row],[MEDIDAS CONTRATO]],MedidasContrato[[MEDIDAS CONTRATO]:[Ø]],2,0),"N/A")) -> 0 | D7: =IF( ConsolidadoPA[[#This Row],[MEDIDAS CONTRATO]] = "", "", IFERROR( VLOOKUP(ConsolidadoPA[[#This Row],[MEDIDAS CONTRATO]],MedidasContrato[],3,0),"N/A")) -> 28 | E7: =IF( ConsolidadoPA[[#This Row],[MEDIDAS CONTRATO]] = "", "", IFERROR( VLOOKUP(ConsolidadoPA[[#This Row],[MEDIDAS CONTRATO]],MedidasContrato[],4,0),"N/A")) -> 37.5 | F7: =IF( ConsolidadoPA[[#This Row],[MEDIDAS CONTRATO]] = "", "", IFERROR( VLOOKUP(ConsolidadoPA[[#This Row],[MEDIDAS CONTRATO]],MedidasContrato[],5,0),"N/A")) -> 47.5 | G7: =IFERROR( ConsolidadoPA[[#This Row],[A]]*ConsolidadoPA[[#This Row],[L]]*ConsolidadoPA[[#This Row],[P]], "") -> 49875 | H7: 43993 | I7: =IFERROR( ConsolidadoPA[[#This Row],[cm³ = V1]]/ConsolidadoPA[[#This Row],[cm³ = V2]],"") -> 1.1337031 | J7: 8084 | M7: 3011 | N7: =IF( ConsolidadoPA[[#This Row],[QUAm-1]]="","",Consolidado!$M7+Consolidado!$J7-Consolidado!$L7-Consolidado!$K7) -> 11095 | O7: =IF(ConsolidadoPA[[#This Row],[FC = V1/V2]]="","",ConsolidadoPA[[#This Row],[FC = V1/V2]]*ConsolidadoPA[[#This Row],[QUAm]]) -> 12578.436 | P7: =IF( ConsolidadoPA[[#This Row],[Contrato]] = "", "", IFERROR( VLOOKUP(ConsolidadoPA[[#This Row],[Contrato]],TabelaPA[[Linha de Serviço PPU]:[PREÇO UNITÁRIO ]],3,0),"Nao Encontrado")) -> 0.9 | Q7: =IF(ConsolidadoPA[[#This Row],[$ Unitário]]="","",Consolidado!$P7*Consolidado!$O7) -> 11320.592 | R7: FC1 | S7: ARM-CX-DOC
A8: A 28,0 X L 39,0 X P 46,0 | B8: Caixa 20 kg - Tipo 1 | C8: =IF(ConsolidadoPA[[#This Row],[MEDIDAS CONTRATO]]="","", IFERROR( VLOOKUP(ConsolidadoPA[[#This Row],[MEDIDAS CONTRATO]],MedidasContrato[[MEDIDAS CONTRATO]:[Ø]],2,0),"N/A")) -> 0 | D8: =IF( ConsolidadoPA[[#This Row],[MEDIDAS CONTRATO]] = "", "", IFERROR( VLOOKUP(ConsolidadoPA[[#This Row],[MEDIDAS CONTRATO]],MedidasContrato[],3,0),"N/A")) -> 28 | E8: =IF( ConsolidadoPA[[#This Row],[MEDIDAS CONTRATO]] = "", "", IFERROR( VLOOKUP(ConsolidadoPA[[#This Row],[MEDIDAS CONTRATO]],MedidasContrato[],4,0),"N/A")) -> 39 | F8: =IF( ConsolidadoPA[[#This Row],[MEDIDAS CONTRATO]] = "", "", IFERROR( VLOOKUP(ConsolidadoPA[[#This Row],[MEDIDAS CONTRATO]],MedidasContrato[],5,0),"N/A")) -> 46 | G8: =IFERROR( ConsolidadoPA[[#This Row],[A]]*ConsolidadoPA[[#This Row],[L]]*ConsolidadoPA[[#This Row],[P]], "") -> 50232 | H8: 43993 | I8: =IFERROR( ConsolidadoPA[[#This Row],[cm³ = V1]]/ConsolidadoPA[[#This Row],[cm³ = V2]],"") -> 1.141818 | J8: 1904 | M8: 645 | N8: =IF( ConsolidadoPA[[#This Row],[QUAm-1]]="","",Consolidado!$M8+Consolidado!$J8-Consolidado!$L8-Consolidado!$K8) -> 2549 | O8: =IF(ConsolidadoPA[[#This Row],[FC = V1/V2]]="","",ConsolidadoPA[[#This Row],[FC = V1/V2]]*ConsolidadoPA[[#This Row],[QUAm]]) -> 2910.4941 | P8: =IF( ConsolidadoPA[[#This Row],[Contrato]] = "", "", IFERROR( VLOOKUP(ConsolidadoPA[[#This Row],[Contrato]],TabelaPA[[Linha de Serviço PPU]:[PREÇO UNITÁRIO ]],3,0),"Nao Encontrado")) -> 0.9 | Q8: =IF(ConsolidadoPA[[#This Row],[$ Unitário]]="","",Consolidado!$P8*Consolidado!$O8) -> 2619.4447 | R8: FC1 | S8: ARM-CX-DOC
A9: A 29,0 X L 37,0 X P 43,0 | B9: Caixa 20 kg - Tipo 1 | C9: =IF(ConsolidadoPA[[#This Row],[MEDIDAS CONTRATO]]="","", IFERROR( VLOOKUP(ConsolidadoPA[[#This Row],[MEDIDAS CONTRATO]],MedidasContrato[[MEDIDAS CONTRATO]:[Ø]],2,0),"N/A")) -> 0 | D9: =IF( ConsolidadoPA[[#This Row],[MEDIDAS CONTRATO]] = "", "", IFERROR( VLOOKUP(ConsolidadoPA[[#This Row],[MEDIDAS CONTRATO]],MedidasContrato[],3,0),"N/A")) -> 29 | E9: =IF( ConsolidadoPA[[#This Row],[MEDIDAS CONTRATO]] = "", "", IFERROR( VLOOKUP(ConsolidadoPA[[#This Row],[MEDIDAS CONTRATO]],MedidasContrato[],4,0),"N/A")) -> 37 | F9: =IF( ConsolidadoPA[[#This Row],[MEDIDAS CONTRATO]] = "", "", IFERROR( VLOOKUP(ConsolidadoPA[[#This Row],[MEDIDAS CONTRATO]],MedidasContrato[],5,0),"N/A")) -> 43 | G9: =IFERROR( ConsolidadoPA[[#This Row],[A]]*ConsolidadoPA[[#This Row],[L]]*ConsolidadoPA[[#This Row],[P]], "") -> 46139 | H9: 43993 | I9: =IFERROR( ConsolidadoPA[[#This Row],[cm³ = V1]]/ConsolidadoPA[[#This Row],[cm³ = V2]],"") -> 1.0487805 | J9: 74783 | M9: 13706 | N9: =IF( ConsolidadoPA[[#This Row],[QUAm-1]]="","",Consolidado!$M9+Consolidado!$J9-Consolidado!$L9-Consolidado!$K9) -> 88489 | O9: =IF(ConsolidadoPA[[#This Row],[FC = V1/V2]]="","",ConsolidadoPA[[#This Row],[FC = V1/V2]]*ConsolidadoPA[[#This Row],[QUAm]]) -> 92805.537 | P9: =IF( ConsolidadoPA[[#This Row],[Contrato]] = "", "", IFERROR( VLOOKUP(ConsolidadoPA[[#This Row],[Contrato]],TabelaPA[[Linha de Serviço PPU]:[PREÇO UNITÁRIO ]],3,0),"Nao Encontrado")) -> 0.9 | Q9: =IF(ConsolidadoPA[[#This Row],[$ Unitário]]="","",Consolidado!$P9*Consolidado!$O9) -> 83524.983 | R9: FC1 | S9: ARM-CX-DOC
A10: A 29,5 X L 39,0 X P 46,0 | B10: Caixa 20 kg - Tipo 1 | C10: =IF(ConsolidadoPA[[#This Row],[MEDIDAS CONTRATO]]="","", IFERROR( VLOOKUP(ConsolidadoPA[[#This Row],[MEDIDAS CONTRATO]],MedidasContrato[[MEDIDAS CONTRATO]:[Ø]],2,0),"N/A")) -> 0 | D10: =IF( ConsolidadoPA[[#This Row],[MEDIDAS CONTRATO]] = "", "", IFERROR( VLOOKUP(ConsolidadoPA[[#This Row],[MEDIDAS CONTRATO]],MedidasContrato[],3,0),"N/A")) -> 29.5 | E10: =IF( ConsolidadoPA[[#This Row],[MEDIDAS CONTRATO]] = "", "", IFERROR( VLOOKUP(ConsolidadoPA[[#This Row],[MEDIDAS CONTRATO]],MedidasContrato[],4,0),"N/A")) -> 39 | F10: =IF( ConsolidadoPA[[#This Row],[MEDIDAS CONTRATO]] = "", "", IFERROR( VLOOKUP(ConsolidadoPA[[#This Row],[MEDIDAS CONTRATO]],MedidasContrato[],5,0),"N/A")) -> 46 | G10: =IFERROR( ConsolidadoPA[[#This Row],[A]]*ConsolidadoPA[[#This Row],[L]]*ConsolidadoPA[[#This Row],[P]], "") -> 52923 | H10: 43993 | I10: =IFERROR( ConsolidadoPA[[#This Row],[cm³ = V1]]/ConsolidadoPA[[#This Row],[cm³ = V2]],"") -> 1.2029868 | J10: 1 | M10: 0 | N10: =IF( ConsolidadoPA[[#This Row],[QUAm-1]]="","",Consolidado!$M10+Consolidado!$J10-Consolidado!$L10-Consolidado!$K10) -> 1 | O10: =IF(ConsolidadoPA[[#This Row],[FC = V1/V2]]="","",ConsolidadoPA[[#This Row],[FC = V1/V2]]*ConsolidadoPA[[#This Row],[QUAm]]) -> 1.2029868 | P10: =IF( ConsolidadoPA[[#This Row],[Contrato]] = "", "", IFERROR( VLOOKUP(ConsolidadoPA[[#This Row],[Contrato]],TabelaPA[[Linha de Serviço PPU]:[PREÇO UNITÁRIO ]],3,0),"Nao Encontrado")) -> 0.9 | Q10: =IF(ConsolidadoPA[[#This Row],[$ Unitário]]="","",Consolidado!$P10*Consolidado!$O10) -> 1.0826882 | R10: FC1 | S10: ARM-CX-DOC
A11: A 12,0 X L 34,0 X P 37,0 | B11: Caixa para mídias - Tipo 1 | C11: =IF(ConsolidadoPA[[#This Row],[MEDIDAS CONTRATO]]="","", IFERROR( VLOOKUP(ConsolidadoPA[[#This Row],[MEDIDAS CONTRATO]],MedidasContrato[[MEDIDAS CONTRATO]:[Ø]],2,0),"N/A")) -> 0 | D11: =IF( ConsolidadoPA[[#This Row],[MEDIDAS CONTRATO]] = "", "", IFERROR( VLOOKUP(ConsolidadoPA[[#This Row],[MEDIDAS CONTRATO]],MedidasContrato[],3,0),"N/A")) -> 12 | E11: =IF( ConsolidadoPA[[#This Row],[MEDIDAS CONTRATO]] = "", "", IFERROR( VLOOKUP(ConsolidadoPA[[#This Row],[MEDIDAS CONTRATO]],MedidasContrato[],4,0),"N/A")) -> 34 | F11: =IF( ConsolidadoPA[[#This Row],[MEDIDAS CONTRATO]] = "", "", IFERROR( VLOOKUP(ConsolidadoPA[[#This Row],[MEDIDAS CONTRATO]],MedidasContrato[],5,0),"N/A")) -> 37 | G11: =IFERROR( ConsolidadoPA[[#This Row],[A]]*ConsolidadoPA[[#This Row],[L]]*ConsolidadoPA[[#This Row],[P]], "") -> 15096 | H11: 15096 | I11: =IFERROR( ConsolidadoPA[[#This Row],[cm³ = V1]]/ConsolidadoPA[[#This Row],[cm³ = V2]],"") -> 1 | J11: 0 | N11: =IF( ConsolidadoPA[[#This Row],[QUAm-1]]="","",Consolidado!$M11+Consolidado!$J11-Consolidado!$L11-Consolidado!$K11) -> 0 | O11: =IF(ConsolidadoPA[[#This Row],[FC = V1/V2]]="","",ConsolidadoPA[[#This Row],[FC = V1/V2]]*ConsolidadoPA[[#This Row],[QUAm]]) -> 0 | P11: =IF( ConsolidadoPA[[#This Row],[Contrato]] = "", "", IFERROR( VLOOKUP(ConsolidadoPA[[#This Row],[Contrato]],TabelaPA[[Linha de Serviço PPU]:[PREÇO UNITÁRIO ]],3,0),"Nao Encontrado")) -> 0.9 | Q11: =IF(ConsolidadoPA[[#This Row],[$ Unitário]]="","",Consolidado!$P11*Consolidado!$O11) -> 0 | R11: FC2 | S11: ARM-CX-MID
A12: A 11,5 X L 37,0 X P 33,0 | B12: Caixa para mídias - Tipo 1 | C12: =IF(ConsolidadoPA[[#This Row],[MEDIDAS CONTRATO]]="","", IFERROR( VLOOKUP(ConsolidadoPA[[#This Row],[MEDIDAS CONTRATO]],MedidasContrato[[MEDIDAS CONTRATO]:[Ø]],2,0),"N/A")) -> 0 | D12: =IF( ConsolidadoPA[[#This Row],[MEDIDAS CONTRATO]] = "", "", IFERROR( VLOOKUP(ConsolidadoPA[[#This Row],[MEDIDAS CONTRATO]],MedidasContrato[],3,0),"N/A")) -> 11.5 | E12: =IF( ConsolidadoPA[[#This Row],[MEDIDAS CONTRATO]] = "", "", IFERROR( VLOOKUP(ConsolidadoPA[[#This Row],[MEDIDAS CONTRATO]],MedidasContrato[],4,0),"N/A")) -> 37 | F12: =IF( ConsolidadoPA[[#This Row],[MEDIDAS CONTRATO]] = "", "", IFERROR( VLOOKUP(ConsolidadoPA[[#This Row],[MEDIDAS CONTRATO]],MedidasContrato[],5,0),"N/A")) -> 33 | G12: =IFERROR( ConsolidadoPA[[#This Row],[A]]*ConsolidadoPA[[#This Row],[L]]*ConsolidadoPA[[#This Row],[P]], "") -> 14041.5 | H12: 15096 | I12: =IFERROR( ConsolidadoPA[[#This Row],[cm³ = V1]]/ConsolidadoPA[[#This Row],[cm³ = V2]],"") -> 0.93014706 | J12: 0 | N12: =IF( ConsolidadoPA[[#This Row],[QUAm-1]]="","",Consolidado!$M12+Consolidado!$J12-Consolidado!$L12-Consolidado!$K12) -> 0 | O12: =IF(ConsolidadoPA[[#This Row],[FC = V1/V2]]="","",ConsolidadoPA[[#This Row],[FC = V1/V2]]*ConsolidadoPA[[#This Row],[QUAm]]) -> 0 | P12: =IF( ConsolidadoPA[[#This Row],[Contrato]] = "", "", IFERROR( VLOOKUP(ConsolidadoPA[[#This Row],[Contrato]],TabelaPA[[Linha de Serviço PPU]:[PREÇO UNITÁRIO ]],3,0),"Nao Encontrado")) -> 0.9 | Q12: =IF(ConsolidadoPA[[#This Row],[$ Unitário]]="","",Consolidado!$P12*Consolidado!$O12) -> 0 | R12: FC2 | S12: ARM-CX-MID
A13: L 10 x P 30 | B13: Tubo de engenharia | C13: =IF(ConsolidadoPA[[#This Row],[MEDIDAS CONTRATO]]="","", IFERROR( VLOOKUP(ConsolidadoPA[[#This Row],[MEDIDAS CONTRATO]],MedidasContrato[[MEDIDAS CONTRATO]:[Ø]],2,0),"N/A")) -> 0 | D13: =IF( ConsolidadoPA[[#This Row],[MEDIDAS CONTRATO]] = "", "", IFERROR( VLOOKUP(ConsolidadoPA[[#This Row],[MEDIDAS CONTRATO]],MedidasContrato[],3,0),"N/A")) -> 104 | E13: =IF( ConsolidadoPA[[#This Row],[MEDIDAS CONTRATO]] = "", "", IFERROR( VLOOKUP(ConsolidadoPA[[#This Row],[MEDIDAS CONTRATO]],MedidasContrato[],4,0),"N/A")) -> 10 | F13: =IF( ConsolidadoPA[[#This Row],[MEDIDAS CONTRATO]] = "", "", IFERROR( VLOOKUP(ConsolidadoPA[[#This Row],[MEDIDAS CONTRATO]],MedidasContrato[],5,0),"N/A")) -> 30 | G13: =IFERROR( ConsolidadoPA[[#This Row],[A]]*ConsolidadoPA[[#This Row],[L]]*ConsolidadoPA[[#This Row],[P]], "") -> 31200 | H13: 9425 | I13: =IFERROR( ConsolidadoPA[[#This Row],[cm³ = V1]]/ConsolidadoPA[[#This Row],[cm³ = V2]],"") -> 3.3103448 | J13: 0 | M13: 2 | N13: =IF( ConsolidadoPA[[#This Row],[QUAm-1]]="","",Consolidado!$M13+Consolidado!$J13-Consolidado!$L13-Consolidado!$K13) -> 2 | O13: =IF(ConsolidadoPA[[#This Row],[FC = V1/V2]]="","",ConsolidadoPA[[#This Row],[FC = V1/V2]]*ConsolidadoPA[[#This Row],[QUAm]]) -> 6.6206897 | P13: =IF( ConsolidadoPA[[#This Row],[Contrato]] = "", "", IFERROR( VLOOKUP(ConsolidadoPA[[#This Row],[Contrato]],TabelaPA[[Linha de Serviço PPU]:[PREÇO UNITÁRIO ]],3,0),"Nao Encontrado")) -> 0.9 | Q13: =IF(ConsolidadoPA[[#This Row],[$ Unitário]]="","",Consolidado!$P13*Consolidado!$O13) -> 5.9586207 | R13: FC3 | S13: ARM-TB
A14: L 0,11 X C 1,20 | B14: Tubo de engenharia | C14: =IF(ConsolidadoPA[[#This Row],[MEDIDAS CONTRATO]]="","", IFERROR( VLOOKUP(ConsolidadoPA[[#This Row],[MEDIDAS CONTRATO]],MedidasContrato[[MEDIDAS CONTRATO]:[Ø]],2,0),"N/A")) -> 0 | D14: =IF( ConsolidadoPA[[#This Row],[MEDIDAS CONTRATO]] = "", "", IFERROR( VLOOKUP(ConsolidadoPA[[#This Row],[MEDIDAS CONTRATO]],MedidasContrato[],3,0),"N/A")) -> 0 | E14: =IF( ConsolidadoPA[[#This Row],[MEDIDAS CONTRATO]] = "", "", IFERROR( VLOOKUP(ConsolidadoPA[[#This Row],[MEDIDAS CONTRATO]],MedidasContrato[],4,0),"N/A")) -> 0.11 | F14: =IF( ConsolidadoPA[[#This Row],[MEDIDAS CONTRATO]] = "", "", IFERROR( VLOOKUP(ConsolidadoPA[[#This Row],[MEDIDAS CONTRATO]],MedidasContrato[],5,0),"N/A")) -> 1.2 | G14: =IFERROR( ConsolidadoPA[[#This Row],[A]]*ConsolidadoPA[[#This Row],[L]]*ConsolidadoPA[[#This Row],[P]], "") -> 0 | H14: 9425 | I14: =IFERROR( ConsolidadoPA[[#This Row],[cm³ = V1]]/ConsolidadoPA[[#This Row],[cm³ = V2]],"") -> 0 | J14: 0 | N14: =IF( ConsolidadoPA[[#This Row],[QUAm-1]]="","",Consolidado!$M14+Consolidado!$J14-Consolidado!$L14-Consolidado!$K14) -> 0 | O14: =IF(ConsolidadoPA[[#This Row],[FC = V1/V2]]="","",ConsolidadoPA[[#This Row],[FC = V1/V2]]*ConsolidadoPA[[#This Row],[QUAm]]) -> 0 | P14: =IF( ConsolidadoPA[[#This Row],[Contrato]] = "", "", IFERROR( VLOOKUP(ConsolidadoPA[[#This Row],[Contrato]],TabelaPA[[Linha de Serviço PPU]:[PREÇO UNITÁRIO ]],3,0),"Nao Encontrado")) -> 0.9 | Q14: =IF(ConsolidadoPA[[#This Row],[$ Unitário]]="","",Consolidado!$P14*Consolidado!$O14) -> 0 | R14: FC3 | S14: ARM-TB
A15: L 0,11 X C 1,23 | B15: Tubo de engenharia | C15: =IF(ConsolidadoPA[[#This Row],[MEDIDAS CONTRATO]]="","", IFERROR( VLOOKUP(ConsolidadoPA[[#This Row],[MEDIDAS CONTRATO]],MedidasContrato[[MEDIDAS CONTRATO]:[Ø]],2,0),"N/A")) -> 0 | D15: =IF( ConsolidadoPA[[#This Row],[MEDIDAS CONTRATO]] = "", "", IFERROR( VLOOKUP(ConsolidadoPA[[#This Row],[MEDIDAS CONTRATO]],MedidasContrato[],3,0),"N/A")) -> 0 | E15: =IF( ConsolidadoPA[[#This Row],[MEDIDAS CONTRATO]] = "", "", IFERROR( VLOOKUP(ConsolidadoPA[[#This Row],[MEDIDAS CONTRATO]],MedidasContrato[],4,0),"N/A")) -> 0.11 | F15: =IF( ConsolidadoPA[[#This Row],[MEDIDAS CONTRATO]] = "", "", IFERROR( VLOOKUP(ConsolidadoPA[[#This Row],[MEDIDAS CONTRATO]],MedidasContrato[],5,0),"N/A")) -> 1.23 | G15: =IFERROR( ConsolidadoPA[[#This Row],[A]]*ConsolidadoPA[[#This Row],[L]]*ConsolidadoPA[[#This Row],[P]], "") -> 0 | H15: 9425 | I15: =IFERROR( ConsolidadoPA[[#This Row],[cm³ = V1]]/ConsolidadoPA[[#This Row],[cm³ = V2]],"") -> 0 | J15: 0 | N15: =IF( ConsolidadoPA[[#This Row],[QUAm-1]]="","",Consolidado!$M15+Consolidado!$J15-Consolidado!$L15-Consolidado!$K15) -> 0 | O15: =IF(ConsolidadoPA[[#This Row],[FC = V1/V2]]="","",ConsolidadoPA[[#This Row],[FC = V1/V2]]*ConsolidadoPA[[#This Row],[QUAm]]) -> 0 | P15: =IF( ConsolidadoPA[[#This Row],[Contrato]] = "", "", IFERROR( VLOOKUP(ConsolidadoPA[[#This Row],[Contrato]],TabelaPA[[Linha de Serviço PPU]:[PREÇO UNITÁRIO ]],3,0),"Nao Encontrado")) -> 0.9 | Q15: =IF(ConsolidadoPA[[#This Row],[$ Unitário]]="","",Consolidado!$P15*Consolidado!$O15) -> 0 | R15: FC3 | S15: ARM-TB
A16: L 0,11 X C 1,30 | B16: Tubo de engenharia | C16: =IF(ConsolidadoPA[[#This Row],[MEDIDAS CONTRATO]]="","", IFERROR( VLOOKUP(ConsolidadoPA[[#This Row],[MEDIDAS CONTRATO]],MedidasContrato[[MEDIDAS CONTRATO]:[Ø]],2,0),"N/A")) -> 0 | D16: =IF( ConsolidadoPA[[#This Row],[MEDIDAS CONTRATO]] = "", "", IFERROR( VLOOKUP(ConsolidadoPA[[#This Row],[MEDIDAS CONTRATO]],MedidasContrato[],3,0),"N/A")) -> 0 | E16: =IF( ConsolidadoPA[[#This Row],[MEDIDAS CONTRATO]] = "", "", IFERROR( VLOOKUP(ConsolidadoPA[[#This Row],[MEDIDAS CONTRATO]],MedidasContrato[],4,0),"N/A")) -> 0.11 | F16: =IF( ConsolidadoPA[[#This Row],[MEDIDAS CONTRATO]] = "", "", IFERROR( VLOOKUP(ConsolidadoPA[[#This Row],[MEDIDAS CONTRATO]],MedidasContrato[],5,0),"N/A")) -> 1.3 | G16: =IFERROR( ConsolidadoPA[[#This Row],[A]]*ConsolidadoPA[[#This Row],[L]]*ConsolidadoPA[[#This Row],[P]], "") -> 0 | H16: 9425 | I16: =IFERROR( ConsolidadoPA[[#This Row],[cm³ = V1]]/ConsolidadoPA[[#This Row],[cm³ = V2]],"") -> 0 | J16: 0 | N16: =IF( ConsolidadoPA[[#This Row],[QUAm-1]]="","",Consolidado!$M16+Consolidado!$J16-Consolidado!$L16-Consolidado!$K16) -> 0 | O16: =IF(ConsolidadoPA[[#This Row],[FC = V1/V2]]="","",ConsolidadoPA[[#This Row],[FC = V1/V2]]*ConsolidadoPA[[#This Row],[QUAm]]) -> 0 | P16: =IF( ConsolidadoPA[[#This Row],[Contrato]] = "", "", IFERROR( VLOOKUP(ConsolidadoPA[[#This Row],[Contrato]],TabelaPA[[Linha de Serviço PPU]:[PREÇO UNITÁRIO ]],3,0),"Nao Encontrado")) -> 0.9 | Q16: =IF(ConsolidadoPA[[#This Row],[$ Unitário]]="","",Consolidado!$P16*Consolidado!$O16) -> 0 | R16: FC3 | S16: ARM-TB
A17: L 0,11 X C 1,26 | B17: Tubo de engenharia | C17: =IF(ConsolidadoPA[[#This Row],[MEDIDAS CONTRATO]]="","", IFERROR( VLOOKUP(ConsolidadoPA[[#This Row],[MEDIDAS CONTRATO]],MedidasContrato[[MEDIDAS CONTRATO]:[Ø]],2,0),"N/A")) -> 0 | D17: =IF( ConsolidadoPA[[#This Row],[MEDIDAS CONTRATO]] = "", "", IFERROR( VLOOKUP(ConsolidadoPA[[#This Row],[MEDIDAS CONTRATO]],MedidasContrato[],3,0),"N/A")) -> 0 | E17: =IF( ConsolidadoPA[[#This Row],[MEDIDAS CONTRATO]] = "", "", IFERROR( VLOOKUP(ConsolidadoPA[[#This Row],[MEDIDAS CONTRATO]],MedidasContrato[],4,0),"N/A")) -> 0.11 | F17: =IF( ConsolidadoPA[[#This Row],[MEDIDAS CONTRATO]] = "", "", IFERROR( VLOOKUP(ConsolidadoPA[[#This Row],[MEDIDAS CONTRATO]],MedidasContrato[],5,0),"N/A")) -> 1.26 | G17: =IFERROR( ConsolidadoPA[[#This Row],[A]]*ConsolidadoPA[[#This Row],[L]]*ConsolidadoPA[[#This Row],[P]], "") -> 0 | H17: 9425 | I17: =IFERROR( ConsolidadoPA[[#This Row],[cm³ = V1]]/ConsolidadoPA[[#This Row],[cm³ = V2]],"") -> 0 | J17: 0 | N17: =IF( ConsolidadoPA[[#This Row],[QUAm-1]]="","",Consolidado!$M17+Consolidado!$J17-Consolidado!$L17-Consolidado!$K17) -> 0 | O17: =IF(ConsolidadoPA[[#This Row],[FC = V1/V2]]="","",ConsolidadoPA[[#This Row],[FC = V1/V2]]*ConsolidadoPA[[#This Row],[QUAm]]) -> 0 | P17: =IF( ConsolidadoPA[[#This Row],[Contrato]] = "", "", IFERROR( VLOOKUP(ConsolidadoPA[[#This Row],[Contrato]],TabelaPA[[Linha de Serviço PPU]:[PREÇO UNITÁRIO ]],3,0),"Nao Encontrado")) -> 0.9 | Q17: =IF(ConsolidadoPA[[#This Row],[$ Unitário]]="","",Consolidado!$P17*Consolidado!$O17) -> 0 | R17: FC3 | S17: ARM-TB
C18: =IF(ConsolidadoPA[[#This Row],[MEDIDAS CONTRATO]]="","", IFERROR( VLOOKUP(ConsolidadoPA[[#This Row],[MEDIDAS CONTRATO]],MedidasContrato[[MEDIDAS CONTRATO]:[Ø]],2,0),"N/A")) | D18: =IF( ConsolidadoPA[[#This Row],[MEDIDAS CONTRATO]] = "", "", IFERROR( VLOOKUP(ConsolidadoPA[[#This Row],[MEDIDAS CONTRATO]],MedidasContrato[],3,0),"N/A")) | E18: =IF( ConsolidadoPA[[#This Row],[MEDIDAS CONTRATO]] = "", "", IFERROR( VLOOKUP(ConsolidadoPA[[#This Row],[MEDIDAS CONTRATO]],MedidasContrato[],4,0),"N/A")) | F18: =IF( ConsolidadoPA[[#This Row],[MEDIDAS CONTRATO]] = "", "", IFERROR( VLOOKUP(ConsolidadoPA[[#This Row],[MEDIDAS CONTRATO]],MedidasContrato[],5,0),"N/A")) | G18: =IFERROR( ConsolidadoPA[[#This Row],[A]]*ConsolidadoPA[[#This Row],[L]]*ConsolidadoPA[[#This Row],[P]], "") | I18: =IFERROR( ConsolidadoPA[[#This Row],[cm³ = V1]]/ConsolidadoPA[[#This Row],[cm³ = V2]],"") | N18: =IF( ConsolidadoPA[[#This Row],[QUAm-1]]="","",Consolidado!$M18+Consolidado!$J18-Consolidado!$L18-Consolidado!$K18) | O18: =IF(ConsolidadoPA[[#This Row],[FC = V1/V2]]="","",ConsolidadoPA[[#This Row],[FC = V1/V2]]*ConsolidadoPA[[#This Row],[QUAm]]) | P18: =IF( ConsolidadoPA[[#This Row],[Contrato]] = "", "", IFERROR( VLOOKUP(ConsolidadoPA[[#This Row],[Contrato]],TabelaPA[[Linha de Serviço PPU]:[PREÇO UNITÁRIO ]],3,0),"Nao Encontrado")) | Q18: =IF(ConsolidadoPA[[#This Row],[$ Unitário]]="","",Consolidado!$P18*Consolidado!$O18)
C19: =IF(ConsolidadoPA[[#This Row],[MEDIDAS CONTRATO]]="","", IFERROR( VLOOKUP(ConsolidadoPA[[#This Row],[MEDIDAS CONTRATO]],MedidasContrato[[MEDIDAS CONTRATO]:[Ø]],2,0),"N/A")) | D19: =IF( ConsolidadoPA[[#This Row],[MEDIDAS CONTRATO]] = "", "", IFERROR( VLOOKUP(ConsolidadoPA[[#This Row],[MEDIDAS CONTRATO]],MedidasContrato[],3,0),"N/A")) | E19: =IF( ConsolidadoPA[[#This Row],[MEDIDAS CONTRATO]] = "", "", IFERROR( VLOOKUP(ConsolidadoPA[[#This Row],[MEDIDAS CONTRATO]],MedidasContrato[],4,0),"N/A")) | F19: =IF( ConsolidadoPA[[#This Row],[MEDIDAS CONTRATO]] = "", "", IFERROR( VLOOKUP(ConsolidadoPA[[#This Row],[MEDIDAS CONTRATO]],MedidasContrato[],5,0),"N/A")) | G19: =IFERROR( ConsolidadoPA[[#This Row],[A]]*ConsolidadoPA[[#This Row],[L]]*ConsolidadoPA[[#This Row],[P]], "") | I19: =IFERROR( ConsolidadoPA[[#This Row],[cm³ = V1]]/ConsolidadoPA[[#This Row],[cm³ = V2]],"") | N19: =IF( ConsolidadoPA[[#This Row],[QUAm-1]]="","",Consolidado!$M19+Consolidado!$J19-Consolidado!$L19-Consolidado!$K19) | O19: =IF(ConsolidadoPA[[#This Row],[FC = V1/V2]]="","",ConsolidadoPA[[#This Row],[FC = V1/V2]]*ConsolidadoPA[[#This Row],[QUAm]]) | P19: =IF( ConsolidadoPA[[#This Row],[Contrato]] = "", "", IFERROR( VLOOKUP(ConsolidadoPA[[#This Row],[Contrato]],TabelaPA[[Linha de Serviço PPU]:[PREÇO UNITÁRIO ]],3,0),"Nao Encontrado")) | Q19: =IF(ConsolidadoPA[[#This Row],[$ Unitário]]="","",Consolidado!$P19*Consolidado!$O19)
C20: =IF(ConsolidadoPA[[#This Row],[MEDIDAS CONTRATO]]="","", IFERROR( VLOOKUP(ConsolidadoPA[[#This Row],[MEDIDAS CONTRATO]],MedidasContrato[[MEDIDAS CONTRATO]:[Ø]],2,0),"N/A")) | D20: =IF( ConsolidadoPA[[#This Row],[MEDIDAS CONTRATO]] = "", "", IFERROR( VLOOKUP(ConsolidadoPA[[#This Row],[MEDIDAS CONTRATO]],MedidasContrato[],3,0),"N/A")) | E20: =IF( ConsolidadoPA[[#This Row],[MEDIDAS CONTRATO]] = "", "", IFERROR( VLOOKUP(ConsolidadoPA[[#This Row],[MEDIDAS CONTRATO]],MedidasContrato[],4,0),"N/A")) | F20: =IF( ConsolidadoPA[[#This Row],[MEDIDAS CONTRATO]] = "", "", IFERROR( VLOOKUP(ConsolidadoPA[[#This Row],[MEDIDAS CONTRATO]],MedidasContrato[],5,0),"N/A")) | G20: =IFERROR( ConsolidadoPA[[#This Row],[A]]*ConsolidadoPA[[#This Row],[L]]*ConsolidadoPA[[#This Row],[P]], "") | I20: =IFERROR( ConsolidadoPA[[#This Row],[cm³ = V1]]/ConsolidadoPA[[#This Row],[cm³ = V2]],"") | N20: =IF( ConsolidadoPA[[#This Row],[QUAm-1]]="","",Consolidado!$M20+Consolidado!$J20-Consolidado!$L20-Consolidado!$K20) | O20: =IF(ConsolidadoPA[[#This Row],[FC = V1/V2]]="","",ConsolidadoPA[[#This Row],[FC = V1/V2]]*ConsolidadoPA[[#This Row],[QUAm]]) | P20: =IF( ConsolidadoPA[[#This Row],[Contrato]] = "", "", IFERROR( VLOOKUP(ConsolidadoPA[[#This Row],[Contrato]],TabelaPA[[Linha de Serviço PPU]:[PREÇO UNITÁRIO ]],3,0),"Nao Encontrado")) | Q20: =IF(ConsolidadoPA[[#This Row],[$ Unitário]]="","",Consolidado!$P20*Consolidado!$O20)
C21: =IF(ConsolidadoPA[[#This Row],[MEDIDAS CONTRATO]]="","", IFERROR( VLOOKUP(ConsolidadoPA[[#This Row],[MEDIDAS CONTRATO]],MedidasContrato[[MEDIDAS CONTRATO]:[Ø]],2,0),"N/A")) | D21: =IF( ConsolidadoPA[[#This Row],[MEDIDAS CONTRATO]] = "", "", IFERROR( VLOOKUP(ConsolidadoPA[[#This Row],[MEDIDAS CONTRATO]],MedidasContrato[],3,0),"N/A")) | E21: =IF( ConsolidadoPA[[#This Row],[MEDIDAS CONTRATO]] = "", "", IFERROR( VLOOKUP(ConsolidadoPA[[#This Row],[MEDIDAS CONTRATO]],MedidasContrato[],4,0),"N/A")) | F21: =IF( ConsolidadoPA[[#This Row],[MEDIDAS CONTRATO]] = "", "", IFERROR( VLOOKUP(ConsolidadoPA[[#This Row],[MEDIDAS CONTRATO]],MedidasContrato[],5,0),"N/A")) | G21: =IFERROR( ConsolidadoPA[[#This Row],[A]]*ConsolidadoPA[[#This Row],[L]]*ConsolidadoPA[[#This Row],[P]], "") | I21: =IFERROR( ConsolidadoPA[[#This Row],[cm³ = V1]]/ConsolidadoPA[[#This Row],[cm³ = V2]],"") | N21: =IF( ConsolidadoPA[[#This Row],[QUAm-1]]="","",Consolidado!$M21+Consolidado!$J21-Consolidado!$L21-Consolidado!$K21) | O21: =IF(ConsolidadoPA[[#This Row],[FC = V1/V2]]="","",ConsolidadoPA[[#This Row],[FC = V1/V2]]*ConsolidadoPA[[#This Row],[QUAm]]) | P21: =IF( ConsolidadoPA[[#This Row],[Contrato]] = "", "", IFERROR( VLOOKUP(ConsolidadoPA[[#This Row],[Contrato]],TabelaPA[[Linha de Serviço PPU]:[PREÇO UNITÁRIO ]],3,0),"Nao Encontrado")) | Q21: =IF(ConsolidadoPA[[#This Row],[$ Unitário]]="","",Consolidado!$P21*Consolidado!$O21)
C22: =IF(ConsolidadoPA[[#This Row],[MEDIDAS CONTRATO]]="","", IFERROR( VLOOKUP(ConsolidadoPA[[#This Row],[MEDIDAS CONTRATO]],MedidasContrato[[MEDIDAS CONTRATO]:[Ø]],2,0),"N/A")) | D22: =IF( ConsolidadoPA[[#This Row],[MEDIDAS CONTRATO]] = "", "", IFERROR( VLOOKUP(ConsolidadoPA[[#This Row],[MEDIDAS CONTRATO]],MedidasContrato[],3,0),"N/A")) | E22: =IF( ConsolidadoPA[[#This Row],[MEDIDAS CONTRATO]] = "", "", IFERROR( VLOOKUP(ConsolidadoPA[[#This Row],[MEDIDAS CONTRATO]],MedidasContrato[],4,0),"N/A")) | F22: =IF( ConsolidadoPA[[#This Row],[MEDIDAS CONTRATO]] = "", "", IFERROR( VLOOKUP(ConsolidadoPA[[#This Row],[MEDIDAS CONTRATO]],MedidasContrato[],5,0),"N/A")) | G22: =IFERROR( ConsolidadoPA[[#This Row],[A]]*ConsolidadoPA[[#This Row],[L]]*ConsolidadoPA[[#This Row],[P]], "") | I22: =IFERROR( ConsolidadoPA[[#This Row],[cm³ = V1]]/ConsolidadoPA[[#This Row],[cm³ = V2]],"") | N22: =IF( ConsolidadoPA[[#This Row],[QUAm-1]]="","",Consolidado!$M22+Consolidado!$J22-Consolidado!$L22-Consolidado!$K22) | O22: =IF(ConsolidadoPA[[#This Row],[FC = V1/V2]]="","",ConsolidadoPA[[#This Row],[FC = V1/V2]]*ConsolidadoPA[[#This Row],[QUAm]]) | P22: =IF( ConsolidadoPA[[#This Row],[Contrato]] = "", "", IFERROR( VLOOKUP(ConsolidadoPA[[#This Row],[Contrato]],TabelaPA[[Linha de Serviço PPU]:[PREÇO UNITÁRIO ]],3,0),"Nao Encontrado")) | Q22: =IF(ConsolidadoPA[[#This Row],[$ Unitário]]="","",Consolidado!$P22*Consolidado!$O22)
C23: =IF(ConsolidadoPA[[#This Row],[MEDIDAS CONTRATO]]="","", IFERROR( VLOOKUP(ConsolidadoPA[[#This Row],[MEDIDAS CONTRATO]],MedidasContrato[[MEDIDAS CONTRATO]:[Ø]],2,0),"N/A")) | D23: =IF( ConsolidadoPA[[#This Row],[MEDIDAS CONTRATO]] = "", "", IFERROR( VLOOKUP(ConsolidadoPA[[#This Row],[MEDIDAS CONTRATO]],MedidasContrato[],3,0),"N/A")) | E23: =IF( ConsolidadoPA[[#This Row],[MEDIDAS CONTRATO]] = "", "", IFERROR( VLOOKUP(ConsolidadoPA[[#This Row],[MEDIDAS CONTRATO]],MedidasContrato[],4,0),"N/A")) | F23: =IF( ConsolidadoPA[[#This Row],[MEDIDAS CONTRATO]] = "", "", IFERROR( VLOOKUP(ConsolidadoPA[[#This Row],[MEDIDAS CONTRATO]],MedidasContrato[],5,0),"N/A")) | G23: =IFERROR( ConsolidadoPA[[#This Row],[A]]*ConsolidadoPA[[#This Row],[L]]*ConsolidadoPA[[#This Row],[P]], "") | I23: =IFERROR( ConsolidadoPA[[#This Row],[cm³ = V1]]/ConsolidadoPA[[#This Row],[cm³ = V2]],"") | N23: =IF( ConsolidadoPA[[#This Row],[QUAm-1]]="","",Consolidado!$M23+Consolidado!$J23-Consolidado!$L23-Consolidado!$K23) | O23: =IF(ConsolidadoPA[[#This Row],[FC = V1/V2]]="","",ConsolidadoPA[[#This Row],[FC = V1/V2]]*ConsolidadoPA[[#This Row],[QUAm]]) | P23: =IF( ConsolidadoPA[[#This Row],[Contrato]] = "", "", IFERROR( VLOOKUP(ConsolidadoPA[[#This Row],[Contrato]],TabelaPA[[Linha de Serviço PPU]:[PREÇO UNITÁRIO ]],3,0),"Nao Encontrado")) | Q23: =IF(ConsolidadoPA[[#This Row],[$ Unitário]]="","",Consolidado!$P23*Consolidado!$O23)
C24: =IF(ConsolidadoPA[[#This Row],[MEDIDAS CONTRATO]]="","", IFERROR( VLOOKUP(ConsolidadoPA[[#This Row],[MEDIDAS CONTRATO]],MedidasContrato[[MEDIDAS CONTRATO]:[Ø]],2,0),"N/A")) | D24: =IF( ConsolidadoPA[[#This Row],[MEDIDAS CONTRATO]] = "", "", IFERROR( VLOOKUP(ConsolidadoPA[[#This Row],[MEDIDAS CONTRATO]],MedidasContrato[],3,0),"N/A")) | E24: =IF( ConsolidadoPA[[#This Row],[MEDIDAS CONTRATO]] = "", "", IFERROR( VLOOKUP(ConsolidadoPA[[#This Row],[MEDIDAS CONTRATO]],MedidasContrato[],4,0),"N/A")) | F24: =IF( ConsolidadoPA[[#This Row],[MEDIDAS CONTRATO]] = "", "", IFERROR( VLOOKUP(ConsolidadoPA[[#This Row],[MEDIDAS CONTRATO]],MedidasContrato[],5,0),"N/A")) | G24: =IFERROR( ConsolidadoPA[[#This Row],[A]]*ConsolidadoPA[[#This Row],[L]]*ConsolidadoPA[[#This Row],[P]], "") | I24: =IFERROR( ConsolidadoPA[[#This Row],[cm³ = V1]]/ConsolidadoPA[[#This Row],[cm³ = V2]],"") | N24: =IF( ConsolidadoPA[[#This Row],[QUAm-1]]="","",Consolidado!$M24+Consolidado!$J24-Consolidado!$L24-Consolidado!$K24) | O24: =IF(ConsolidadoPA[[#This Row],[FC = V1/V2]]="","",ConsolidadoPA[[#This Row],[FC = V1/V2]]*ConsolidadoPA[[#This Row],[QUAm]]) | P24: =IF( ConsolidadoPA[[#This Row],[Contrato]] = "", "", IFERROR( VLOOKUP(ConsolidadoPA[[#This Row],[Contrato]],TabelaPA[[Linha de Serviço PPU]:[PREÇO UNITÁRIO ]],3,0),"Nao Encontrado")) | Q24: =IF(ConsolidadoPA[[#This Row],[$ Unitário]]="","",Consolidado!$P24*Consolidado!$O24)
C25: =IF(ConsolidadoPA[[#This Row],[MEDIDAS CONTRATO]]="","", IFERROR( VLOOKUP(ConsolidadoPA[[#This Row],[MEDIDAS CONTRATO]],MedidasContrato[[MEDIDAS CONTRATO]:[Ø]],2,0),"N/A")) | D25: =IF( ConsolidadoPA[[#This Row],[MEDIDAS CONTRATO]] = "", "", IFERROR( VLOOKUP(ConsolidadoPA[[#This Row],[MEDIDAS CONTRATO]],MedidasContrato[],3,0),"N/A")) | E25: =IF( ConsolidadoPA[[#This Row],[MEDIDAS CONTRATO]] = "", "", IFERROR( VLOOKUP(ConsolidadoPA[[#This Row],[MEDIDAS CONTRATO]],MedidasContrato[],4,0),"N/A")) | F25: =IF( ConsolidadoPA[[#This Row],[MEDIDAS CONTRATO]] = "", "", IFERROR( VLOOKUP(ConsolidadoPA[[#This Row],[MEDIDAS CONTRATO]],MedidasContrato[],5,0),"N/A")) | G25: =IFERROR( ConsolidadoPA[[#This Row],[A]]*ConsolidadoPA[[#This Row],[L]]*ConsolidadoPA[[#This Row],[P]], "") | I25: =IFERROR( ConsolidadoPA[[#This Row],[cm³ = V1]]/ConsolidadoPA[[#This Row],[cm³ = V2]],"") | N25: =IF( ConsolidadoPA[[#This Row],[QUAm-1]]="","",Consolidado!$M25+Consolidado!$J25-Consolidado!$L25-Consolidado!$K25) | O25: =IF(ConsolidadoPA[[#This Row],[FC = V1/V2]]="","",ConsolidadoPA[[#This Row],[FC = V1/V2]]*ConsolidadoPA[[#This Row],[QUAm]]) | P25: =IF( ConsolidadoPA[[#This Row],[Contrato]] = "", "", IFERROR( VLOOKUP(ConsolidadoPA[[#This Row],[Contrato]],TabelaPA[[Linha de Serviço PPU]:[PREÇO UNITÁRIO ]],3,0),"Nao Encontrado")) | Q25: =IF(ConsolidadoPA[[#This Row],[$ Unitário]]="","",Consolidado!$P25*Consolidado!$O25)

Sheet Tabela
A1: Padrão | C1: Tabela | E1: Linha de serviço PPU | G1: ITEM | H1: DESCRIÇÃO | I1: Linha de Serviço PPU | J1: UNID. | K1: PREÇO UNITÁRIO | L1: Descrição da Linha de Serviço | N1: MEDIDAS CONTRATO | O1: Ø | P1: A | Q1: L | R1: P
A2: Arquivo de aço 1 | C2: FC1 | E2: ARM-CX-DOC | G2: 1.1 | H2: ARM-CX-DOC: Armazenamento de caixas para documentos | I2: ARM-CX-DOC | J2: UA | K2: 0.9 | L2: Armazenamento de caixas para documentos | N2: A 0,5 X L 12,5 X P14,0 | P2: 0.5 | Q2: 12.5 | R2: 14
A3: Arquivo de aço 2 | C3: FC2 | E3: ARM-CX-MID | G3: 1.2 | H3: ARM-CX-MID: Armazenamento de caixas para mídias | I3: ARM-CX-MID | J3: UA | K3: 0.9 | L3: Armazenamento de caixas para mídias | N3: A 0,5 X L 13,0 X P13,0 | P3: 0.5 | Q3: 13 | R3: 13
A4: Arquivo de aço 3 | C4: FC3 | E4: ARM-TB | G4: 1.3 | H4: ARM-TB: Armazenamento de tubos | I4: ARM-TB | J4: UA | K4: 0.9 | L4: Armazenamento de tubos | N4: A 0,5 X L 14,0 X P 12,5 | P4: 0.5 | Q4: 14 | R4: 12.5
A5: Arquivo de aço 4 | C5: FC4 | E5: ARM-MA | G5: 1.4 | H5: ARM-MA: Armazenamento de mapotecas e arquivos de aço | I5: ARM-MA | J5: UA | K5: 70 | L5: Armazenamento de mapotecas e arquivos de aço | N5: A 0,5 X L 14,0 X P 13,0 | P5: 0.5 | Q5: 14 | R5: 13
A6: Arquivo de aço 5 | C6: FC5 | E6: ARM-MIC | G6: 1.5 | H6: ARM-MIC: Armazenamento de microformas | I6: ARM-MIC | J6: UA | K6: 0.1 | L6: Armazenamento de microformas | N6: A 0,5 X L 14,0 X P 14,0 | P6: 0.5 | Q6: 14 | R6: 14
A7: Caixa 10 kg (Jumbo) | C7: FC6 | E7: ARM-MID | G7: 1.6 | H7: ARM-MID: Armazenamento de midias | I7: ARM-MID | J7: UA | K7: 0.1 | L7: Armazenamento de midias | N7: A 08,0 X L 41,0 X P 41,0 | P7: 8 | Q7: 41 | R7: 41
A8: Caixa 20 Kg | C8: FC7 | E8: FRE-NRM | G8: 1.7 | H8: FRE-NRM: Frete normal | I8: FRE-NRM | J8: Frete | K8: 50 | L8: Frete normal | N8: A 1,0 X L 12,5 X P14,0 | P8: 1 | Q8: 12.5 | R8: 14
A9: Caixa 20 kg - Tipo 1 | C9: FC8 | E9: FRE-EXP | G9: 1.8 | H9: FRE-EXP: Frete expresso | I9: FRE-EXP | J9: Frete | K9: 100 | L9: Frete expresso | N9: A 1,0 X L 14,0 X P 13,0 | P9: 1 | Q9: 14 | R9: 13
A10: Caixa 20 kg - Tipo 2 | C10: FC9 | E10: INS-ITEM | G10: 1.9 | H10: KM-AD: Quilometragem adicional | I10: KM-AD | J10: KM | K10: 1 | L10: Quilometragem adicional | N10: A 1,0 X L 14,0 X P 19,0 | P10: 1 | Q10: 14 | R10: 19
A11: Caixa 20 kg (contendo Mídias e Microfilmes) | E11: PES-ITEM | G11: 1.10 | H11: PES-ITEM: Pesquisa de itens avulsos | I11: PES-ITEM | J11: Item Avulso | K11: 3 | L11: Pesquisa de itens avulsos | N11: A 10,0 X L 10,0 X P 2,5 | P11: 10 | Q11: 10 | R11: 2.5
A12: Caixa 5 kg | E12: DES-EMB | G12: 1.11 | H12: DES-EMB: Destruição segura de documentos | I12: DES-EMB | J12: Embalagem | K12: 3 | L12: Destruição segura de documentos | N12: A 10,0 X L 10,5 X P 4,0 | P12: 10 | Q12: 10.5 | R12: 4
A13: Caixa 5kg | E13: TRANSF | G13: 1.12 | H13: TRANSF: Transferência inicial de acervo documental | I13: TRANSF | J13: Transferência | K13: 100000 | L13: Transferência inicial de acervo documental | N13: A 10,0 X L 15,5 X P 0,3 | P13: 10 | Q13: 15.5 | R13: 0.3
A14: Caixa 7 kg | E14: MIGR-UA | G14: 1.13 | H14: MIGR-UA: Migração de acervo documental para digitalização | I14: MIGR-UA | J14: UA | K14: 7.5 | L14: Migração de acervo documental para digitalização | N14: A 10,0 X L 19,0 X P 26,5 | P14: 10 | Q14: 19 | R14: 26.5
A15: Caixa para mídias - Tipo 1 | E15: CAT-EMB | G15: 2.1 | H15: CAT-ITEM: Catalogação de documentos digitalizados | I15: CAT-ITEM | J15: Documento | K15: 0.2 | L15: Catalogação de documentos digitalizados | N15: A 10,0 X L 3,0 X P 10,0 | P15: 10 | Q15: 3 | R15: 10
A16: Caixa para mídias - Tipo 2 | E16: CAT-ITEM | G16: 2.2 | H16: ORG-DOC: Organização de documentos para digitalização | I16: ORG-DOC | J16: UA | K16: 10 | L16: Organização de documentos para digitalização | N16: A 10,0 X L 4,5 X P 10,0 | P16: 10 | Q16: 4.5 | R16: 10
A17: Documentação administrativa | E17: ORG-DOC | G17: 2.3 | H17: DIG-MI: Digitalização de microfilmes | I17: DIG-MI | J17: UD | K17: 0.05 | L17: Digitalização de microfilmes | N17: A 10,5 X L 15,0 X P 0,3 | P17: 10.5 | Q17: 15 | R17: 0.3
A18: Documentação bibliográfica | E18: HIG-MI | G18: 2.4 | H18: DIG-MF: Digitalização de microfichas | I18: DIG-MF | J18: UD | K18: 0.05 | L18: Digitalização de microfichas | N18: A 10,5 X L 19,0 X P2,5 | P18: 10.5 | Q18: 19 | R18: 2.5
A19: Documentação contábil e financeira | E19: HIG-MF | G19: 2.5 | H19: DIG-DOC: Digitalização de documentos | I19: DIG-DOC | J19: UD | K19: 0.11 | L19: Digitalização de documentos | N19: A 10,5 X L 41,0 X P 41,0 | P19: 10.5 | Q19: 41 | R19: 41
A20: Documentação contratual | E20: HIG-PER | G20: 2.6 | H20: IND-DOC: Indexação de documentos | I20: IND-DOC | J20: UD | K20: 0.1 | L20: Indexação de documentos | N20: A 100,0 X L 140,0 X P 51,0 | P20: 100 | Q20: 140 | R20: 51
A21: Documentação técnica | E21: DIG-MI | G21: 2.7 | H21: CONV-MID: Conversão de mídias | I21: CONV-MID | J21: Mídia | K21: 40 | L21: Conversão de mídias | N21: A 11,0 X L 15,5 X P 0,3 | P21: 11 | Q21: 15.5 | R21: 0.3
A22: Documento - Formato A0 | E22: DIG-MF | G22: 2.8 | H22: GRV-MID: Gravação de mídias | I22: GRV-MID | J22: Mídia | K22: 40 | L22: Gravação de mídias | N22: A 11,0 X L 33,0 X P 37,0 | P22: 11 | Q22: 33 | R22: 37
A23: Documento - Formato A1 | E23: DIG-DOC | G23: 2.9 | H23: COP-MID: Cópia de mídias | I23: COP-MID | J23: Mídia | K23: 5 | L23: Cópia de mídias | N23: A 11,0 X L 33,0 X P 41,0 | P23: 11 | Q23: 33 | R23: 41
A24: Documento - Formato A2 | E24: IND-DOC | N24: A 11,5 X L 37,0 X P 33,0 | P24: 11.5 | Q24: 37 | R24: 33
A25: Documento - Formato A3 | E25: CONV-MID | N25: A 12,0 X L 34,0 X P 37,0 | P25: 12 | Q25: 34 | R25: 37
A26: Documento - Formato A4 | E26: GRV-MID | N26: A 12,0 X L 34,0 X P 37,0 | P26: 12 | Q26: 34 | R26: 37
A27: Documento - Superior ao Formato A0 | E27: COP-MID | N27: A 12,5 X L 14 X P 0,5 | P27: 12.5 | Q27: 14 | R27: 0.5
A28: Embalagem | E28: COP-VID | N28: A 12,5 X L 14,5 X P0,5 | P28: 12.5 | Q28: 14.5 | R28: 0.5
A29: Fita VHS | E29: N/A | N29: A 130,0 X L 060,0 X P 72,0 | P29: 130 | Q29: 60 | R29: 72
A30: Item avulso | N30: A 130,0 X L 060,0 X P 73,0 | P30: 130 | Q30: 60 | R30: 73
A31: Item documental | N31: A 135,0 X L 51,0 X P 105,0 | P31: 135 | Q31: 51 | R31: 105
A32: Item documental em caixa | N32: A 140,0 X L 067,0 X P 72,0 | P32: 140 | Q32: 67 | R32: 72
A33: Item documental em mapoteca | N33: A 15,0 X L 40,0 X P 35,0 | P33: 15 | Q33: 40 | R33: 35
A34: Item documental em Tubo | N34: A 150,0 X L 090,0 X P 76,0 | P34: 150 | Q34: 90 | R34: 76
A35: Kit de material | N35: A 16,5 X L 11,5 X P 0,3 | P35: 16.5 | Q35: 11.5 | R35: 0.3
A36: Mapoteca | N36: A 17,0 X L 20,5 X P 111,5 | P36: 17 | Q36: 20.5 | R36: 111.5
A37: Microficha | N37: A 170,0 X L 061,0 X P 72,0 | P37: 170 | Q37: 61 | R37: 72
A38: Microfilme | N38: A 180,0 X L 068,0 X P 72,0 | P38: 180 | Q38: 68 | R38: 72
A39: Microfilme 16 mm | N39: A 21,0 X L 31,0 X P 46,0 | P39: 21 | Q39: 31 | R39: 46
A40: Microfilme 35 mm | N40: A 21,0 X L 41,0 X P 55,0 | P40: 21 | Q40: 41 | R40: 55
...

Sheet Mapa Geral
A1: Nº Da Ordem | B1: Medição | C1: Service Now | D1: Quantidade Service Now | E1: Unidade de atendimento | F1: UF para atendimento | G1: Demandante | H1: Telefone | I1: Gerência | J1: Data de emissão | K1: Data máxima de atendimento | L1: Data de atendimento | M1: Data de envio da O.S | N1: Status do Prazo | O1: Linha de serviço | P1: Tipo de Solicitação | Q1: Caixa de 20 Kg | R1: Caixa de Mídia | S1: Tubo de Engenharia | T1: Tubo de perfil de poços | U1: Etiqueta de caixa | V1: Lacre | W1: Observações | X1: Endereço de atendimento | Y1: Grupo | Z1: KM
A2: 0008/2026 | B2: 26/06/2026 a 25/07/2026 | C2: CSC0788409 | D2: 3 | F2: BA | G2: NÃO INFORMADO | I2: SUPRIMENTOS RMF RDR | J2: 46163 | K2: 46164 | L2: 46206 | N2: NÃO | O2: Pesquisa | P2: Normal
A3: 0014/2026 | B3: 26/06/2026 a 25/07/2026 | C3: NÃO INFORMADO | D3: 159 | F3: BA | G3: NÃO INFORMADO | I3: NÃO INFORMADO | J3: 46189 | K3: 46190 | L3: 46206 | N3: SIM | O3: Pesquisa | P3: Normal
A4: 0018/2026 | B4: 26/06/2026 a 25/07/2026 | C4: NÃO INFORMADO | D4: 11 | F4: BA | G4: NÃO INFORMADO | I4: NÃO INFORMADO | J4: 46199 | K4: 46202 | L4: 46199 | N4: SIM | O4: Pesquisa | P4: Normal
A5: 0019/2026 | B5: 26/06/2026 a 25/07/2026 | C5: CSC0811201 | D5: 10 | F5: BA | G5: Jose Paulo de Jesus Santos Departamento | I5: SMS SA SAO DENGE-DPI-DLCM-DTEN | J5: 46199 | K5: 46202 | L5: 46199 | N5: SIM | O5: Pesquisa | P5: Normal
A6: 0020/2026 | B6: 26/06/2026 a 25/07/2026 | C6: CSC0824264 | D6: 1 | F6: BA | G6: NÃO INFORMADO | I6: RH RBO COA CB | J6: 46199 | K6: 46202 | L6: 46202 | N6: SIM | O6: Pesquisa | P6: Normal
A7: 0021/2026 | B7: 26/06/2026 a 25/07/2026 | C7: CSC0829650 | D7: 10 | F7: BA | G7: Jose Paulo de Jesus Santos | I7: SMS SA SAO DENGE-DPI-DLCM-DTEN | J7: 46199 | K7: 46202 | L7: 46202 | N7: SIM | O7: Pesquisa | P7: Normal
A8: 0022/2026 | B8: 26/06/2026 a 25/07/2026 | C8: CSC0831386 | D8: 13 | F8: BA | G8: Jose Paulo de Jesus Santos | I8: SMS SA SAO DENGE-DPI-DLCM-DTEN | J8: 46204 | K8: 46206 | L8: 46204 | N8: SIM | O8: Pesquisa | P8: Normal
A9: 0023/2026 | B9: 26/06/2026 a 25/07/2026 | C9: CSC0783878 | D9: 1 | F9: BA | G9: NÃO INFORMADO | I9: NÃO INFORMADO | J9: 46206 | K9: 46209 | L9: 46206 | N9: SIM | O9: Pesquisa | P9: Normal
A10: 0024/2026 | B10: 26/06/2026 a 25/07/2026 | C10: CSC0819994 | D10: 9 | F10: BA | G10: Jose Paulo de Jesus Santos | I10: SMS SA SAO DENGE-DPI-DLCM-DTEN | J10: 46206 | K10: 46209 | L10: 46209 | N10: SIM | O10: Pesquisa | P10: Normal
A11: 0025/2026 | B11: 26/06/2026 a 25/07/2026 | C11: CSC0820439 | D11: 6 | F11: BA | G11: Jose Paulo de Jesus Santos | I11: SMS SA SAO DENGE-DPI-DLCM-DTEN | J11: 46206 | K11: 46209 | L11: 46223 | N11: NÃO | O11: Pesquisa | P11: Normal
A12: 0026/2026 | B12: 26/06/2026 a 25/07/2026 | C12: CSC0808892 | D12: 1 | F12: BA | G12: Thallya Vitoria Souza | I12: SMS SA SAO STO | J12: 46206 | K12: 46209 | L12: 46220 | N12: NÃO | O12: Pesquisa | P12: Normal
A13: 0027/2026 | B13: 26/06/2026 a 25/07/2026 | C13: CSC0810976 | D13: 10 | F13: BA | G13: Jose Paulo de Jesus Santos | I13: SMS SA SAO DENGE-DPI-DLCM-DTEN | J13: 46206 | K13: 46209 | L13: 46221 | N13: NÃO | O13: Pesquisa | P13: Normal
... A26: 0041/2026 | B26: 26/06/2026 a 25/07/2026 | C26: CSC0849777 | D26: 1 | F26: BA | G26: Thallya Vitoria Souza | I26: SMS SA SAO STO | J26: 46225 | K26: 46226 | L26: 46225 | N26: SIM | O26: Pesquisa | P26: Normal
A27: 0024/2026 | B27: 26/06/2026 a 25/07/2026 | C27: CSC0827133 / CSC0827142 / CSC0827170 | D27: 5 | E27: RNEST | F27: PE | G27: Aline Larissa dos Santos Agostinho | H27: 81 99560-6225 | I27: RNEST/SMS/SSO | J27: 46196 | K27: 46203 | L27: 46211 | M27: 46211 | N27: NÃO | O27: Implantação | P27: Normal | Y27: B | Z27: 746
A28: 0026/2026 | B28: 26/06/2026 a 25/07/2026 | C28: CSC0830441 / CSC0830445 | D28: 11 | E28: RNEST | F28: PE | G28: Aline Larissa dos Santos Agostinho | H28: 81 99560-6225 | I28: RNEST/SMS/SSO | J28: 46203 | K28: 46205 | L28: 46211 | M28: 46211 | N28: NÃO | O28: Implantação | P28: Normal | Y28: B | Z28: 746
A29: 0027/2026 | B29: 26/06/2026 a 25/07/2026 | C29: CSC0846380 | D29: 22 | E29: EDIRN | F29: RN | G29: Nayra Kallyne de Brito Araujo / Malkene | H29: (84) 84 999174758 / 84 98894-2932 | I29: SMS/LMA/GAE&P/AM-RN-CE | J29: 46223 | K29: 46226 | L29: 46226 | M29: 46226 | N29: SIM | O29: Implantação | P29: Normal | Y29: C | Z29: 1058
A30: 0029/2026 | B30: 26/06/2026 a 25/07/2026 | C30: CSC0847315 | D30: 9 | E30: EDIRN | F30: RN | G30: Malkene Wytiza Freire de Medeiros Noronha | H30: (84) 98894-2932 | I30: TAR/PC/REC | J30: 46223 | K30: 46226 | L30: 46226 | M30: 46227 | N30: SIM | O30: Implantação | P30: Normal | Y30: C | Z30: 1058
A31: 0030/2026 | B31: 26/06/2026 a 25/07/2026 | C31: CSC0847436 | D31: 1 | E31: UTE-BAHIA | F31: BA | G31: Adriana Silvana Ferreira / Caetano | H31: (71) 98757-1027 / 71 98749-0368 | I31: G&E/TERM/UTE-TBA | J31: 46223 | K31: 46227 | L31: 46227 | M31: 46227 | N31: NÃO | O31: Implantação | P31: Normal | Y31: A | Z31: 46
A32: 0026/2026 | B32: 26/06/2026 a 25/07/2026 | C32: CSC0846393 | D32: 50 | E32: EDIRN | F32: RN | G32: Malkene Wytiza Freire de Medeiros Noronha | H32: (84) 98894-2932 | I32: TAR/PC/REC | J32: 46220 | K32: 46225 | L32: 46226 | M32: 46226 | N32: NÃO | O32: Materiais | P32: Normal | Q32: 50 | U32: 100 | V32: 50 | X32: AV. EUZÉBIO ROCHA, 1000, CIDADE DA ESPERANÇA, NATAL-RN, CEP: 59070-900. | Y32: C | Z32: 1058
A33: 0027/2027 | B33: 26/06/2026 a 25/07/2026 | C33: CSC0847689 | D33: 80 | E33: C.T. SSEBPASSÉ | F33: BA | G33: Iuri Santana Amadeu | H33: 71992764349 | I33: COMPARTILHADO/SC/SID | J33: 46223 | K33: 46225 | L33: 46225 | N33: SIM | O33: Materiais | P33: Normal | Q33: 80 | W33: Material não recebido pela Petrobras/Cancelado sem aviso | X33: Campo de Taquipe, S/N , São Sebastião Passe | Y33: A | Z33: 44
H38: Grupo 1 | J38: Grupo 2
G39: ANALISES | H39: Qtd | I39: % | J39: Qtd | K39: %
G40: Total de ordens de serviço ATENDIDAS | H40: 6 | I40: 1 | J40: 25 | K40: 1
G41: Total de orden de serviço NO PRAZO | H41: 2 | I41: =H41/H40 -> 0.33333333 | J41: 19 | K41: =J41/J40 -> 0.76
G42: Total de orden de serviço FORA DOPRAZO | H42: =H40-H41 -> 4 | I42: =H42/H40 -> 0.66666667 | J42: =J40-J41 -> 6 | K42: =J42/J41 -> 0.31578947

Sheet Digitalização Click
A1: Nº Da Ordem | B1: Service Now | C1: Unidade de atendimento | D1: Dada abertura da OS | E1: Tipo do Prazo | F1: Excedeu volume | G1: SLA | H1: Data limite de atendimento | I1: Data de início do processo | J1: Data final do processo | K1: Data de entrega das imagens | L1: Prazo | M1: Caixa PA | N1: Caixa Cliente | O1: Qtd de documentos | P1: Qtd de documentos indexados | Q1: Qtd de documentos catalogados | R1: Qtd de Imagens | S1: Quantidade x FC | T1: Tipo documental | U1: Documento | V1: FC | W1: Parcionamento | X1: Qtd parcionamento | Y1: Gerência | Z1: Solicitante
A2: 0008/2026 | B2: CSC0788409 | C2: BA | D2: 46163 | E2: NORMAL | F2: NÃO | G2: D+1 | H2: 46164 | K2: 46206 | L2: NÃO | M2: BA3-3003-I-013 | N2: CX0012000045921SOS CX00120G70394681SOS CX00120G70402395SOS CX00120G70447636SOS CX00120G70447700SOS CX00120G70508196SOS CX00120G70508204SOS CX00120G100548776SOS CX00120G100548778SOS CX00120G100548781SOS CX00120G100548793SOS CX00120G100548802SOS CX00120G100548805SOS | O2: 3 | P2: 3 | Q2: 3 | R2: 486 | S2: =Table_3[[#This Row],[Qtd de Imagens]]*Table_3[[#This Row],[FC]] -> 486 | T2: TECNICA | U2: A4 | V2: 1 | W2: NÃO | X2: 0 | Y2: SUPRIMENTOS RMF RDR | Z2: NÃO INFORMADO
A3: 0014/2026 | B3: NÃO INFORMADO | C3: BA | D3: 46189 | E3: NORMAL | F3: SIM | G3: D+1 | H3: 46190 | K3: 46206 | L3: SIM | M3: EM TRANSFERENCIA | N3: CX00120G100548805SOS CX00120G100548793SOS CX00120G100548781SOS CX00120G100548778SOS CX00120G100548776SOS CX00120G70508204SOS CX00120G70508196SOS CX00120G70402395SOS | O3: 159 | P3: 159 | Q3: 159 | R3: 13909 | S3: =Table_3[[#This Row],[Qtd de Imagens]]*Table_3[[#This Row],[FC]] -> 13909 | T3: TECNICA | U3: A4 | V3: 1 | W3: NÃO | X3: 0 | Y3: NÃO INFORMADO | Z3: NÃO INFORMADO
A4: 0018/2026 | B4: NÃO INFORMADO | C4: BA | D4: 46199 | E4: NORMAL | F4: NÃO | G4: D+1 | H4: 46202 | K4: 46199 | L4: SIM | M4: EM TRANSFERENCIA | N4: CX00120G70413279SOS | O4: 11 | P4: 11 | Q4: 11 | R4: 709 | S4: =Table_3[[#This Row],[Qtd de Imagens]]*Table_3[[#This Row],[FC]] -> 709 | T4: PRONTUARIO MEDICO | U4: A4 | V4: 1 | W4: NÃO | X4: 0 | Y4: NÃO INFORMADO | Z4: NÃO INFORMADO
A5: 0019/2026 | B5: CSC0811201 | C5: BA | D5: 46199 | E5: NORMAL | F5: SIM | G5: D+1 | H5: 46202 | K5: 46199 | L5: SIM | M5: EM TRANSFERENCIA | N5: CX00120G70413266SOS | O5: 10 | P5: 10 | Q5: 10 | R5: 760 | S5: =Table_3[[#This Row],[Qtd de Imagens]]*Table_3[[#This Row],[FC]] -> 760 | T5: PRONTUARIO MEDICO | U5: A4 | V5: 1 | W5: NÃO | X5: 0 | Y5: SMS SA SAO DENGE-DPI-DLCM-DTEN | Z5: Jose Paulo de Jesus Santos Departamento
A6: 0020/2026 | B6: CSC0824264 | C6: BA | D6: 46199 | E6: NORMAL | F6: NÃO | G6: D+1 | H6: 46202 | K6: 46202 | L6: SIM | M6: BA3-3010-F-102 | N6: CX00120G70265450SOS | O6: 1 | P6: 1 | Q6: 1 | R6: 7 | S6: =Table_3[[#This Row],[Qtd de Imagens]]*Table_3[[#This Row],[FC]] -> 7 | T6: RH | U6: A4 | V6: 1 | W6: NÃO | X6: 0 | Y6: RH RBO COA CB | Z6: NÃO INFORMADO
A7: 0021/2026 | B7: CSC0829650 | C7: BA | D7: 46199 | E7: NORMAL | F7: NÃO | G7: D+1 | H7: 46202 | K7: 46202 | L7: SIM | M7: BA3-3014-G-036 | N7: CX00120G100543696SOS | O7: 10 | P7: 10 | Q7: 10 | R7: 692 | S7: =Table_3[[#This Row],[Qtd de Imagens]]*Table_3[[#This Row],[FC]] -> 692 | T7: PRONTUARIO MEDICO | U7: A4 | V7: 1 | W7: NÃO | X7: 0 | Y7: SMS SA SAO DENGE-DPI-DLCM-DTEN | Z7: Jose Paulo de Jesus Santos
A8: 0022/2026 | B8: CSC0831386 | C8: BA | D8: 46204 | E8: NORMAL | F8: NÃO | G8: D+1 | H8: 46206 | K8: 46204 | L8: SIM | M8: EM TRANSFERENCIA | N8: CX00120G70391882SOS | O8: 13 | P8: 13 | Q8: 13 | R8: 1040 | S8: =Table_3[[#This Row],[Qtd de Imagens]]*Table_3[[#This Row],[FC]] -> 1040 | T8: PRONTUARIO MEDICO | U8: A4 | V8: 1 | W8: NÃO | X8: 0 | Y8: SMS SA SAO DENGE-DPI-DLCM-DTEN | Z8: Jose Paulo de Jesus Santos
A9: 0023/2026 | B9: CSC0783878 | C9: BA | D9: 46206 | E9: NORMAL | F9: NÃO | G9: D+1 | H9: 46209 | K9: 46206 | L9: SIM | M9: BA3-3010-A-102 | N9: CX00120G70439250SOS | O9: 1 | P9: 1 | Q9: 1 | R9: 20 | S9: =Table_3[[#This Row],[Qtd de Imagens]]*Table_3[[#This Row],[FC]] -> 20 | T9: ADMINISTRATIVA | U9: A4 | V9: 1 | W9: NÃO | X9: 0 | Y9: NÃO INFORMADO | Z9: NÃO INFORMADO
